Workbook

Sheet Revenue Drivers
C2: ='Income Statement '!C2 -> H1'21 | D2: ='Income Statement '!D2 -> H2'21 | E2: ='Income Statement '!E2 -> FY'21 | F2: ='Income Statement '!F2 -> H1'22 | G2: ='Income Statement '!G2 -> H2'22 | H2: ='Income Statement '!H2 -> FY'22 | I2: ='Income Statement '!I2 -> H1'23 | J2: ='Income Statement '!J2 -> H2'23 | ... AC2: ='Income Statement '!AC2 -> FY'29E
B3: Net Sales
B4: Organic Sales | H4: 2716 | I4: 742 | K4: 969 | L4: =L7+L10 -> -67 | N4: ='North America'!N4+Europe!N4+'Asia Pacific'!N4+LATAM!N4+Africa!N4 -> 1358.32 | O4: ='North America'!O4+Europe!O4+'Asia Pacific'!O4+LATAM!O4+Africa!O4 -> 871.92 | Q4: ='North America'!Q4+Europe!Q4+'Asia Pacific'!Q4+LATAM!Q4+Africa!Q4 -> 1473.7772 | R4: ='North America'!R4+Europe!R4+'Asia Pacific'!R4+LATAM!R4+Africa!R4 -> 946.0332 | T4: ='North America'!T4+Europe!T4+'Asia Pacific'!T4+LATAM!T4+Africa!T4 -> 1621.1549 | U4: ='North America'!U4+Europe!U4+'Asia Pacific'!U4+LATAM!U4+Africa!U4 -> 1026.446 | W4: ='North America'!W4+Europe!W4+'Asia Pacific'!W4+LATAM!W4+Africa!W4 -> 1783.2704 | X4: ='North America'!X4+Europe!X4+'Asia Pacific'!X4+LATAM!X4+Africa!X4 -> 1113.6939 | Z4: ='North America'!Z4+Europe!Z4+'Asia Pacific'!Z4+LATAM!Z4+Africa!Z4 -> 1961.5975 | AA4: ='North America'!AA4+Europe!AA4+'Asia Pacific'!AA4+LATAM!AA4+Africa!AA4 -> 1208.3579 | AC4: ='North America'!AC4+Europe!AC4+'Asia Pacific'!AC4+LATAM!AC4+Africa!AC4 -> 2157.7572
B5: Organic growth (%) | H5: 0.21 | K5: =K4/H22 -> 0.062710329 | L5: =L8+L11 -> -0.0060251799 | N5: =N4/K22 -> 0.079373576 | O5: =O4/L22 -> 0.07954023 | Q5: =Q4/N22 -> 0.079422296 | R5: =R4/O22 -> 0.079576058 | T5: =T4/Q22 -> 0.07947447 | U5: =U4/R22 -> 0.079609108 | W5: =W4/T22 -> 0.07952196 | X5: =X4/U22 -> 0.079639593 | Z5: =Z4/W22 -> 0.079565182 | AA5: =AA4/X22 -> 0.07966771 | AC5: =AC4/Z22 -> 0.079604515
B7: Volume | I7: 142 | L7: -573 | N7: ='North America'!N7+Europe!N7+'Asia Pacific'!N7+LATAM!N7+Africa!N7 -> 0 | O7: ='North America'!O7+Europe!O7+'Asia Pacific'!O7+LATAM!O7+Africa!O7 -> 0 | Q7: ='North America'!Q7+Europe!Q7+'Asia Pacific'!Q7+LATAM!Q7+Africa!Q7 -> 0 | R7: ='North America'!R7+Europe!R7+'Asia Pacific'!R7+LATAM!R7+Africa!R7 -> 0 | T7: ='North America'!T7+Europe!T7+'Asia Pacific'!T7+LATAM!T7+Africa!T7 -> 0 | U7: ='North America'!U7+Europe!U7+'Asia Pacific'!U7+LATAM!U7+Africa!U7 -> 0 | W7: ='North America'!W7+Europe!W7+'Asia Pacific'!W7+LATAM!W7+Africa!W7 -> 0 | X7: ='North America'!X7+Europe!X7+'Asia Pacific'!X7+LATAM!X7+Africa!X7 -> 0 | Z7: ='North America'!Z7+Europe!Z7+'Asia Pacific'!Z7+LATAM!Z7+Africa!Z7 -> 0 | AA7: ='North America'!AA7+Europe!AA7+'Asia Pacific'!AA7+LATAM!AA7+Africa!AA7 -> 0 | AC7: ='North America'!AC7+Europe!AC7+'Asia Pacific'!AC7+LATAM!AC7+Africa!AC7 -> 0
B8: Volume Growth (%) | K8: =K7/H22 -> 0 | L8: =L7/I22 -> -0.051528777
B10: Price | I10: 600 | L10: 506 | N10: ='North America'!N10+Europe!N10+'Asia Pacific'!N10+LATAM!N10+Africa!N10 -> 0 | O10: ='North America'!O10+Europe!O10+'Asia Pacific'!O10+LATAM!O10+Africa!O10 -> 0 | Q10: ='North America'!Q10+Europe!Q10+'Asia Pacific'!Q10+LATAM!Q10+Africa!Q10 -> 0 | R10: ='North America'!R10+Europe!R10+'Asia Pacific'!R10+LATAM!R10+Africa!R10 -> 0 | T10: ='North America'!T10+Europe!T10+'Asia Pacific'!T10+LATAM!T10+Africa!T10 -> 0 | U10: ='North America'!U10+Europe!U10+'Asia Pacific'!U10+LATAM!U10+Africa!U10 -> 0 | W10: ='North America'!W10+Europe!W10+'Asia Pacific'!W10+LATAM!W10+Africa!W10 -> 0 | X10: ='North America'!X10+Europe!X10+'Asia Pacific'!X10+LATAM!X10+Africa!X10 -> 0 | Z10: ='North America'!Z10+Europe!Z10+'Asia Pacific'!Z10+LATAM!Z10+Africa!Z10 -> 0 | AA10: ='North America'!AA10+Europe!AA10+'Asia Pacific'!AA10+LATAM!AA10+Africa!AA10 -> 0 | AC10: ='North America'!AC10+Europe!AC10+'Asia Pacific'!AC10+LATAM!AC10+Africa!AC10 -> 0
B11: Price (%) | K11: =K10/H22 -> 0 | L11: =L10/I22 -> 0.045503597
B13: FX | H13: -223 | I13: 669 | K13: 817 | L13: -167 | N13: ='North America'!N13+Europe!N13+'Asia Pacific'!N13+LATAM!N13+Africa!N13 -> 0 | O13: ='North America'!O13+Europe!O13+'Asia Pacific'!O13+LATAM!O13+Africa!O13 -> 0 | Q13: ='North America'!Q13+Europe!Q13+'Asia Pacific'!Q13+LATAM!Q13+Africa!Q13 -> 0 | R13: ='North America'!R13+Europe!R13+'Asia Pacific'!R13+LATAM!R13+Africa!R13 -> 0 | T13: ='North America'!T13+Europe!T13+'Asia Pacific'!T13+LATAM!T13+Africa!T13 -> 0 | U13: ='North America'!U13+Europe!U13+'Asia Pacific'!U13+LATAM!U13+Africa!U13 -> 0 | W13: ='North America'!W13+Europe!W13+'Asia Pacific'!W13+LATAM!W13+Africa!W13 -> 0 | X13: ='North America'!X13+Europe!X13+'Asia Pacific'!X13+LATAM!X13+Africa!X13 -> 0 | Z13: ='North America'!Z13+Europe!Z13+'Asia Pacific'!Z13+LATAM!Z13+Africa!Z13 -> 0 | AA13: ='North America'!AA13+Europe!AA13+'Asia Pacific'!AA13+LATAM!AA13+Africa!AA13 -> 0 | AC13: ='North America'!AC13+Europe!AC13+'Asia Pacific'!AC13+LATAM!AC13+Africa!AC13 -> 0
B14: FX Growth (%) | K14: =K13/H22 -> 0.052873414 | L14: =L13/I22 -> -0.015017986
B16: Scope | H16: 75 | I16: -33 | K16: 182 | L16: -51 | N16: ='North America'!N16+Europe!N16+'Asia Pacific'!N16+LATAM!N16+Africa!N16 -> 84.895 | O16: ='North America'!O16+Europe!O16+'Asia Pacific'!O16+LATAM!O16+Africa!O16 -> 54.495 | Q16: ='North America'!Q16+Europe!Q16+'Asia Pacific'!Q16+LATAM!Q16+Africa!Q16 -> 368.4443 | R16: ='North America'!R16+Europe!R16+'Asia Pacific'!R16+LATAM!R16+Africa!R16 -> 59.127075 | T16: ='North America'!T16+Europe!T16+'Asia Pacific'!T16+LATAM!T16+Africa!T16 -> 405.28873 | U16: ='North America'!U16+Europe!U16+'Asia Pacific'!U16+LATAM!U16+Africa!U16 -> 64.152876 | W16: ='North America'!W16+Europe!W16+'Asia Pacific'!W16+LATAM!W16+Africa!W16 -> 445.8176 | X16: ='North America'!X16+Europe!X16+'Asia Pacific'!X16+LATAM!X16+Africa!X16 -> 69.605871 | Z16: ='North America'!Z16+Europe!Z16+'Asia Pacific'!Z16+LATAM!Z16+Africa!Z16 -> 490.39936 | AA16: ='North America'!AA16+Europe!AA16+'Asia Pacific'!AA16+LATAM!AA16+Africa!AA16 -> 75.52237 | AC16: ='North America'!AC16+Europe!AC16+'Asia Pacific'!AC16+LATAM!AC16+Africa!AC16 -> 539.4393
B17: Scope growth (%) | K17: =K16/H22 -> 0.011778411 | L17: =L16/I22 -> -0.0045863309 | N17: =N16/K22 -> 0.0049608485 | O17: =O16/L22 -> 0.0049712644 | Q17: =Q16/N22 -> 0.019855574 | R17: =R16/O22 -> 0.0049735036 | T17: =T16/Q22 -> 0.019868617 | U17: =U16/R22 -> 0.0049755692 | W17: =W16/T22 -> 0.01988049 | X17: =X16/U22 -> 0.0049774745 | Z17: =Z16/W22 -> 0.019891295 | AA17: =AA16/X22 -> 0.0049792319 | AC17: =AC16/Z22 -> 0.019901129
B19: Hyperinflation | H19: 189 | I19: 85 | K19: 175 | L19: 127 | N19: ='North America'!N19+Europe!N19+'Asia Pacific'!N19+LATAM!N19+Africa!N19 -> 0 | O19: ='North America'!O19+Europe!O19+'Asia Pacific'!O19+LATAM!O19+Africa!O19 -> 0 | Q19: ='North America'!Q19+Europe!Q19+'Asia Pacific'!Q19+LATAM!Q19+Africa!Q19 -> 0 | R19: ='North America'!R19+Europe!R19+'Asia Pacific'!R19+LATAM!R19+Africa!R19 -> 0 | T19: ='North America'!T19+Europe!T19+'Asia Pacific'!T19+LATAM!T19+Africa!T19 -> 0 | U19: ='North America'!U19+Europe!U19+'Asia Pacific'!U19+LATAM!U19+Africa!U19 -> 0 | W19: ='North America'!W19+Europe!W19+'Asia Pacific'!W19+LATAM!W19+Africa!W19 -> 0 | X19: ='North America'!X19+Europe!X19+'Asia Pacific'!X19+LATAM!X19+Africa!X19 -> 0 | Z19: ='North America'!Z19+Europe!Z19+'Asia Pacific'!Z19+LATAM!Z19+Africa!Z19 -> 0 | AA19: ='North America'!AA19+Europe!AA19+'Asia Pacific'!AA19+LATAM!AA19+Africa!AA19 -> 0 | AC19: ='North America'!AC19+Europe!AC19+'Asia Pacific'!AC19+LATAM!AC19+Africa!AC19 -> 0
B20: Hyprinflation (%)
H21: -38 | I21: =11120-9420 -> 1700 | K21: =-(15452-14970) -> -482
B22: Total | E22: 12733 | F22: 7957 | H22: =E22+H4+H13+H16+H19+H21 -> 15452 | I22: =F22+I4+I13+I16+I19+I21 -> 11120 | K22: =H22+K4+K13+K16+K19+K21 -> 17113 | L22: =I22+L4+L13+L16+L19+L21 -> 10962 | N22: =K22+N4+N13+N16+N19+N21 -> 18556.215 | O22: =L22+O4+O13+O16+O19+O21 -> 11888.415 | Q22: =N22+Q4+Q13+Q16+Q19+Q21 -> 20398.436 | R22: =O22+R4+R13+R16+R19+R21 -> 12893.575 | T22: =Q22+T4+T13+T16+T19+T21 -> 22424.88 | U22: =R22+U4+U13+U16+U19+U21 -> 13984.174 | W22: =T22+W4+W13+W16+W19+W21 -> 24653.968 | X22: =U22+X4+X13+X16+X19+X21 -> 15167.474 | Z22: =W22+Z4+Z13+Z16+Z19+Z21 -> 27105.965 | AA22: =X22+AA4+AA13+AA16+AA19+AA21 -> 16451.354 | AC22: =Z22+AC4+AC13+AC16+AC19+AC21 -> 29803.161
K23: =K22/H22-1 -> 0.10749418 | L23: =L22/I22-1 -> -0.014208633 | N23: =N22/K22-1 -> 0.084334424 | O23: =O22/L22-1 -> 0.084511494 | Q23: =Q22/N22-1 -> 0.09927787 | R23: =R22/O22-1 -> 0.084549561 | T23: =T22/Q22-1 -> 0.099343087 | U23: =U22/R22-1 -> 0.084584677 | W23: =W22/T22-1 -> 0.099402449 | X23: =X22/U22-1 -> 0.084617067 | Z23: =Z22/W22-1 -> 0.099456477 | AA23: =AA22/X22-1 -> 0.084646942 | AC23: =AC22/Z22-1 -> 0.099505644

Sheet North America
C2: ='Income Statement '!C2 -> H1'21 | D2: ='Income Statement '!D2 -> H2'21 | E2: ='Income Statement '!E2 -> FY'21 | F2: ='Income Statement '!F2 -> H1'22 | G2: ='Income Statement '!G2 -> H2'22 | H2: ='Income Statement '!H2 -> FY'22 | I2: ='Income Statement '!I2 -> H1'23 | J2: ='Income Statement '!J2 -> H2'23 | ... AC2: ='Income Statement '!AC2 -> FY'29E
B3: Net Sales
B4: Organic Sales | H4: 754 | I4: 88 | K4: 11 | L4: -64 | N4: =N5*K22 -> 536.96 | O4: =O5*L22 -> 326.72 | Q4: =Q5*N22 -> 582.6016 | R4: =R5*O22 -> 354.4912 | T4: =T5*Q22 -> 640.86176 | U4: =U5*R22 -> 384.62295 | W4: =W5*T22 -> 704.94794 | X4: =X5*U22 -> 417.3159 | Z4: =Z5*W22 -> 775.44273 | AA4: =AA5*X22 -> 452.78775 | AC4: =AC5*Z22 -> 852.987
B5: Organic growth (%) | I5: 0.03 | K5: =K4/H22 -> 0.0018184824 | L5: =L4/I22 -> -0.015425404 | N5: =N8+N11 -> 0.08 | O5: =O8+O11 -> 0.08 | Q5: =Q8+Q11 -> 0.08 | R5: =R8+R11 -> 0.08 | T5: =T8+T11 -> 0.08 | U5: =U8+U11 -> 0.08 | W5: =W8+W11 -> 0.08 | X5: =X8+X11 -> 0.08 | Z5: =Z8+Z11 -> 0.08 | AA5: =AA8+AA11 -> 0.08 | AC5: =AC8+AC11 -> 0.08
B7: Volume | L7: -124.47
B8: Volume Growth (%) | L8: =L7/I22 -> -0.03 | N8: 0.04 | O8: 0.04 | Q8: 0.04 | R8: 0.04 | T8: 0.04 | U8: 0.04 | W8: 0.04 | X8: 0.04 | Z8: 0.04 | AA8: 0.04 | AC8: 0.04
B10: Price | L10: =L11*I22 -> 41.49
B11: Price (%) | L11: 0.01 | N11: 0.04 | O11: 0.04 | Q11: 0.04 | R11: 0.04 | T11: 0.04 | U11: 0.04 | W11: 0.04 | X11: 0.04 | Z11: 0.04 | AA11: 0.04 | AC11: 0.04
B13: FX | H13: 97 | I13: 452 | K13: 678 | L13: -3 | N13: =N14*K22 -> 0 | O13: =O14*L22 -> 0 | Q13: =Q14*N22 -> 0 | R13: =R14*O22 -> 0 | T13: =T14*Q22 -> 0 | U13: =U14*R22 -> 0 | W13: =W14*T22 -> 0 | X13: =X14*U22 -> 0 | Z13: =Z14*W22 -> 0 | AA13: =AA14*X22 -> 0 | AC13: =AC14*Z22 -> 0
B14: FX Growth (%) | K14: =K13/H22 -> 0.11208464 | L14: =L13/I22 -> -0.0007230658 | N14: 0 | O14: 0 | Q14: 0 | R14: 0 | T14: 0 | U14: 0 | W14: 0 | X14: 0 | Z14: 0 | AA14: 0 | AC14: 0
B16: Scope | H16: 34 | I16: 13 | K16: 20 | L16: 2 | N16: =N17*K22 -> 33.56 | O16: =O17*L22 -> 20.42 | Q16: =Q17*N22 -> 145.6504 | R16: =R17*O22 -> 22.1557 | T16: =T17*Q22 -> 160.21544 | U16: =U17*R22 -> 24.038934 | W16: =W17*T22 -> 176.23698 | X16: =X17*U22 -> 26.082244 | Z16: =Z17*W22 -> 193.86068 | AA16: =AA17*X22 -> 28.299235 | AC16: =AC17*Z22 -> 213.24675
B17: Scope growth (%) | K17: =K16/H22 -> 0.0033063316 | L17: =L16/I22 -> 0.00048204387 | N17: 0.005 | O17: 0.005 | Q17: 0.02 | R17: 0.005 | T17: 0.02 | U17: 0.005 | W17: 0.02 | X17: 0.005 | Z17: 0.02 | AA17: 0.005 | AC17: 0.02
B19: Hyperinflation | K19: 0 | L19: 0
B20: Hyperinflation (%)
H21: -46 | I21: =4149-3517 -> 632 | K21: -46
B22: Total | E22: 5210 | F22: 2964 | H22: =E22+H4+H13+H16+H19+H21 -> 6049 | I22: =F22+I4+I13+I16+I19+I21 -> 4149 | K22: =H22+K4+K13+K16+K19+K21 -> 6712 | L22: =I22+L4+L13+L16+L19+L21 -> 4084 | N22: =N4+N13+N16+K22 -> 7282.52 | O22: =O4+O13+O16+L22 -> 4431.14 | Q22: =Q4+Q13+Q16+N22 -> 8010.772 | R22: =R4+R13+R16+O22 -> 4807.7869 | T22: =T4+T13+T16+Q22 -> 8811.8492 | U22: =U4+U13+U16+R22 -> 5216.4488 | W22: =W4+W13+W16+T22 -> 9693.0341 | X22: =X4+X13+X16+U22 -> 5659.8469 | Z22: =Z4+Z13+Z16+W22 -> 10662.338 | AA22: =AA4+AA13+AA16+X22 -> 6140.9339 | AC22: =AC4+AC13+AC16+Z22 -> 11728.571
K23: =K22/H22-1 -> 0.10960489 | L23: =L22/I22-1 -> -0.015666426 | N23: =N22/K22-1 -> 0.085 | O23: =O22/L22-1 -> 0.085 | Q23: =Q22/N22-1 -> 0.1 | R23: =R22/O22-1 -> 0.085 | T23: =T22/Q22-1 -> 0.1 | U23: =U22/R22-1 -> 0.085 | W23: =W22/T22-1 -> 0.1 | X23: =X22/U22-1 -> 0.085 | Z23: =Z22/W22-1 -> 0.1 | AA23: =AA22/X22-1 -> 0.085 | AC23: =AC22/Z22-1 -> 0.1

Sheet Europe
C2: ='Income Statement '!C2 -> H1'21 | D2: ='Income Statement '!D2 -> H2'21 | E2: ='Income Statement '!E2 -> FY'21 | F2: ='Income Statement '!F2 -> H1'22 | G2: ='Income Statement '!G2 -> H2'22 | H2: ='Income Statement '!H2 -> FY'22 | I2: ='Income Statement '!I2 -> H1'23 | J2: ='Income Statement '!J2 -> H2'23 | ... AC2: ='Income Statement '!AC2 -> FY'29E
B3: Net Sales
B4: Organic Sales | H4: 766 | I4: 164 | K4: 347 | L4: 78 | N4: =N5*K22 -> 285.52 | O4: =O5*L22 -> 205.2 | Q4: =Q5*N22 -> 309.7892 | R4: =R5*O22 -> 222.642 | T4: =T5*Q22 -> 340.76812 | U4: =U5*R22 -> 241.56657 | W4: =W5*T22 -> 374.84493 | X4: =X5*U22 -> 262.09973 | Z4: =Z5*W22 -> 412.32943 | AA4: =AA5*X22 -> 284.37821 | AC4: =AC5*Z22 -> 453.56237
B5: Organic growth (%) | I5: 0.1 | K5: =K4/H22 -> 0.10803238 | L5: =L4/I22 -> 0.033347584 | N5: =N8+N11 -> 0.08 | O5: =O8+O11 -> 0.08 | Q5: =Q8+Q11 -> 0.08 | R5: =R8+R11 -> 0.08 | T5: =T8+T11 -> 0.08 | U5: =U8+U11 -> 0.08 | W5: =W8+W11 -> 0.08 | X5: =X8+X11 -> 0.08 | Z5: =Z8+Z11 -> 0.08 | AA5: =AA8+AA11 -> 0.08 | AC5: =AC8+AC11 -> 0.08
B7: Volume
B8: Volume Growth (%) | L8: -0.04 | N8: 0.04 | O8: 0.04 | Q8: 0.04 | R8: 0.04 | T8: 0.04 | U8: 0.04 | W8: 0.04 | X8: 0.04 | Z8: 0.04 | AA8: 0.04 | AC8: 0.04
B10: Price
B11: Price (%) | L11: 0.07 | N11: 0.04 | O11: 0.04 | Q11: 0.04 | R11: 0.04 | T11: 0.04 | U11: 0.04 | W11: 0.04 | X11: 0.04 | Z11: 0.04 | AA11: 0.04 | AC11: 0.04
B13: FX | H13: -304 | I13: -13 | K13: -41 | L13: 5 | N13: =N14*K22 -> 0 | O13: =O14*L22 -> 0 | Q13: =Q14*N22 -> 0 | R13: =R14*O22 -> 0 | T13: =T14*Q22 -> 0 | U13: =U14*R22 -> 0 | W13: =W14*T22 -> 0 | X13: =X14*U22 -> 0 | Z13: =Z14*W22 -> 0 | AA13: =AA14*X22 -> 0 | AC13: =AC14*Z22 -> 0
B14: FX Growth (%) | K14: =K13/H22 -> -0.012764633 | L14: =L13/I22 -> 0.0021376657 | N14: 0 | O14: 0 | Q14: 0 | R14: 0 | T14: 0 | U14: 0 | W14: 0 | X14: 0 | Z14: 0 | AA14: 0 | AC14: 0
B16: Scope | H16: 23 | I16: -9 | K16: 20 | L16: 20 | N16: =N17*K22 -> 17.845 | O16: =O17*L22 -> 12.825 | Q16: =Q17*N22 -> 77.4473 | R16: =R17*O22 -> 13.915125 | T16: =T17*Q22 -> 85.19203 | U16: =U17*R22 -> 15.097911 | W16: =W17*T22 -> 93.711233 | X16: =X17*U22 -> 16.381233 | Z16: =Z17*W22 -> 103.08236 | AA16: =AA17*X22 -> 17.773638 | AC16: =AC17*Z22 -> 113.39059
B17: Scope growth (%) | K17: =K16/H22 -> 0.0062266501 | L17: =L16/I22 -> 0.0085506627 | N17: 0.005 | O17: 0.005 | Q17: 0.02 | R17: 0.005 | T17: 0.02 | U17: 0.005 | W17: 0.02 | X17: 0.005 | Z17: 0.02 | AA17: 0.005 | AC17: 0.02
B19: Hyperinflation | H19: 189 | I19: 85 | K19: 175 | L19: 123
B20: Hyperinflation (%)
I21: 360 | K21: -144
B22: Total | E22: 2538 | F22: 1752 | H22: 3212 | I22: =F22+I4+I13+I16+I19+I21 -> 2339 | K22: =H22+K4+K13+K16+K19+K21 -> 3569 | L22: =I22+L4+L13+L16+L19+L21 -> 2565 | N22: =N4+N13+N16+K22 -> 3872.365 | O22: =O4+O13+O16+L22 -> 2783.025 | Q22: =Q4+Q13+Q16+N22 -> 4259.6015 | R22: =R4+R13+R16+O22 -> 3019.5821 | T22: =T4+T13+T16+Q22 -> 4685.5616 | U22: =U4+U13+U16+R22 -> 3276.2466 | W22: =W4+W13+W16+T22 -> 5154.1178 | X22: =X4+X13+X16+U22 -> 3554.7276 | Z22: =Z4+Z13+Z16+W22 -> 5669.5296 | AA22: =AA4+AA13+AA16+X22 -> 3856.8794 | AC22: =AC4+AC13+AC16+Z22 -> 6236.4826
K23: =K22/H22-1 -> 0.1111457 | L23: =L22/I22-1 -> 0.096622488 | N23: =N22/K22-1 -> 0.085 | O23: =O22/L22-1 -> 0.085 | Q23: =Q22/N22-1 -> 0.1 | R23: =R22/O22-1 -> 0.085 | T23: =T22/Q22-1 -> 0.1 | U23: =U22/R22-1 -> 0.085 | W23: =W22/T22-1 -> 0.1 | X23: =X22/U22-1 -> 0.085 | Z23: =Z22/W22-1 -> 0.1 | AA23: =AA22/X22-1 -> 0.085 | AC23: =AC22/Z22-1 -> 0.1

Sheet Asia Pacific
C2: ='Income Statement '!C2 -> H1'21 | D2: ='Income Statement '!D2 -> H2'21 | E2: ='Income Statement '!E2 -> FY'21 | F2: ='Income Statement '!F2 -> H1'22 | G2: ='Income Statement '!G2 -> H2'22 | H2: ='Income Statement '!H2 -> FY'22 | I2: ='Income Statement '!I2 -> H1'23 | J2: ='Income Statement '!J2 -> H2'23 | ... AC2: ='Income Statement '!AC2 -> FY'29E
B3: Net Sales
B4: Organic Sales | H4: 402 | I4: 250 | K4: 353 | L4: 125 | N4: =N5*K22 -> 256 | O4: =O5*L22 -> 176.48 | Q4: =Q5*N22 -> 277.76 | R4: =R5*O22 -> 191.4808 | T4: =T5*Q22 -> 305.536 | U4: =U5*R22 -> 207.75667 | W4: =W5*T22 -> 336.0896 | X4: =X5*U22 -> 225.41598 | Z4: =Z5*W22 -> 369.69856 | AA4: =AA5*X22 -> 244.57634 | AC4: =AC5*Z22 -> 406.66842
B5: Organic growth (%) | K5: =K4/H22 -> 0.12887915 | L5: =L4/I22 -> 0.057630244 | N5: =N8+N11 -> 0.08 | O5: =O8+O11 -> 0.08 | Q5: =Q8+Q11 -> 0.08 | R5: =R8+R11 -> 0.08 | T5: =T8+T11 -> 0.08 | U5: =U8+U11 -> 0.08 | W5: =W8+W11 -> 0.08 | X5: =X8+X11 -> 0.08 | Z5: =Z8+Z11 -> 0.08 | AA5: =AA8+AA11 -> 0.08 | AC5: =AC8+AC11 -> 0.08
B7: Volume
B8: Volume Growth (%) | L8: -0.02 | N8: 0.04 | O8: 0.04 | Q8: 0.04 | R8: 0.04 | T8: 0.04 | U8: 0.04 | W8: 0.04 | X8: 0.04 | Z8: 0.04 | AA8: 0.04 | AC8: 0.04
B10: Price
B11: Price (%) | L11: 0.08 | N11: 0.04 | O11: 0.04 | Q11: 0.04 | R11: 0.04 | T11: 0.04 | U11: 0.04 | W11: 0.04 | X11: 0.04 | Z11: 0.04 | AA11: 0.04 | AC11: 0.04
B13: FX | H13: -4 | I13: 89 | K13: 73 | L13: -23 | N13: =N14*K22 -> 0 | O13: =O14*L22 -> 0 | Q13: =Q14*N22 -> 0 | R13: =R14*O22 -> 0 | T13: =T14*Q22 -> 0 | U13: =U14*R22 -> 0 | W13: =W14*T22 -> 0 | X13: =X14*U22 -> 0 | Z13: =Z14*W22 -> 0 | AA13: =AA14*X22 -> 0 | AC13: =AC14*Z22 -> 0
B14: FX Growth (%) | K14: =K13/H22 -> 0.026652063 | L14: =L13/I22 -> -0.010603965 | N14: 0 | O14: 0 | Q14: 0 | R14: 0 | T14: 0 | U14: 0 | W14: 0 | X14: 0 | Z14: 0 | AA14: 0 | AC14: 0
B16: Scope | I16: -33 | K16: 35 | L16: -65 | N16: =N17*K22 -> 16 | O16: =O17*L22 -> 11.03 | Q16: =Q17*N22 -> 69.44 | R16: =R17*O22 -> 11.96755 | T16: =T17*Q22 -> 76.384 | U16: =U17*R22 -> 12.984792 | W16: =W17*T22 -> 84.0224 | X16: =X17*U22 -> 14.088499 | Z16: =Z17*W22 -> 92.42464 | AA16: =AA17*X22 -> 15.286021 | AC16: =AC17*Z22 -> 101.6671
B17: Scope growth (%) | K17: =K16/H22 -> 0.012778386 | L17: =L16/I22 -> -0.029967727 | N17: 0.005 | O17: 0.005 | Q17: 0.02 | R17: 0.005 | T17: 0.02 | U17: 0.005 | W17: 0.02 | X17: 0.005 | Z17: 0.02 | AA17: 0.005 | AC17: 0.02
B19: Hyperinflation
B20: Hyperinflation (%)
H21: =2739-2884 -> -145 | I21: =2169-1837 -> 332
B22: Total | E22: 2486 | F22: 1531 | H22: 2739 | I22: =F22+I4+I13+I16+I19+I21 -> 2169 | K22: =H22+K4+K13+K16+K19+K21 -> 3200 | L22: =I22+L4+L13+L16+L19+L21 -> 2206 | N22: =N4+N13+N16+K22 -> 3472 | O22: =O4+O13+O16+L22 -> 2393.51 | Q22: =Q4+Q13+Q16+N22 -> 3819.2 | R22: =R4+R13+R16+O22 -> 2596.9584 | T22: =T4+T13+T16+Q22 -> 4201.12 | U22: =U4+U13+U16+R22 -> 2817.6998 | W22: =W4+W13+W16+T22 -> 4621.232 | X22: =X4+X13+X16+U22 -> 3057.2043 | Z22: =Z4+Z13+Z16+W22 -> 5083.3552 | AA22: =AA4+AA13+AA16+X22 -> 3317.0667 | AC22: =AC4+AC13+AC16+Z22 -> 5591.6907
K23: =K22/H22-1 -> 0.1683096 | L23: =L22/I22-1 -> 0.017058552 | N23: =N22/K22-1 -> 0.085 | O23: =O22/L22-1 -> 0.085 | Q23: =Q22/N22-1 -> 0.1 | R23: =R22/O22-1 -> 0.085 | T23: =T22/Q22-1 -> 0.1 | U23: =U22/R22-1 -> 0.085 | W23: =W22/T22-1 -> 0.1 | X23: =X22/U22-1 -> 0.085 | Z23: =Z22/W22-1 -> 0.1 | AA23: =AA22/X22-1 -> 0.085 | AC23: =AC22/Z22-1 -> 0.1

Sheet LATAM
C2: ='Income Statement '!C2 -> H1'21 | D2: ='Income Statement '!D2 -> H2'21 | E2: ='Income Statement '!E2 -> FY'21 | F2: ='Income Statement '!F2 -> H1'22 | G2: ='Income Statement '!G2 -> H2'22 | H2: ='Income Statement '!H2 -> FY'22 | I2: ='Income Statement '!I2 -> H1'23 | J2: ='Income Statement '!J2 -> H2'23 | ... AC2: ='Income Statement '!AC2 -> FY'29E
B3: Net Sales
B4: Organic Sales | H4: 308 | I4: 167 | K4: 142 | L4: -310 | N4: =N5*K22 -> 143.92 | O4: =O5*L22 -> 85.52 | Q4: =Q5*N22 -> 156.1532 | R4: =R5*O22 -> 92.7892 | T4: =T5*Q22 -> 171.76852 | U4: =U5*R22 -> 100.67628 | W4: =W5*T22 -> 188.94537 | X4: =X5*U22 -> 109.23377 | Z4: =Z5*W22 -> 207.83991 | AA4: =AA5*X22 -> 118.51864 | AC4: =AC5*Z22 -> 228.6239
B5: Organic growth (%) | K5: =K4/H22 -> 0.094102054 | L5: =L4/I22 -> -0.23864511 | N5: =N8+N11 -> 0.08 | O5: =O8+O11 -> 0.08 | Q5: =Q8+Q11 -> 0.08 | R5: =R8+R11 -> 0.08 | T5: =T8+T11 -> 0.08 | U5: =U8+U11 -> 0.08 | W5: =W8+W11 -> 0.08 | X5: =X8+X11 -> 0.08 | Z5: =Z8+Z11 -> 0.08 | AA5: =AA8+AA11 -> 0.08 | AC5: =AC8+AC11 -> 0.08
B7: Volume
B8: Volume Growth (%) | L8: -0.19 | N8: 0.04 | O8: 0.04 | Q8: 0.04 | R8: 0.04 | T8: 0.04 | U8: 0.04 | W8: 0.04 | X8: 0.04 | Z8: 0.04 | AA8: 0.04 | AC8: 0.04
B10: Price
B11: Price (%) | L11: -0.04 | N11: 0.04 | O11: 0.04 | Q11: 0.04 | R11: 0.04 | T11: 0.04 | U11: 0.04 | W11: 0.04 | X11: 0.04 | Z11: 0.04 | AA11: 0.04 | AC11: 0.04
B13: FX | H13: -35 | I13: 111 | K13: 145 | L13: 80 | N13: =N14*K22 -> 0 | O13: =O14*L22 -> 0 | Q13: =Q14*N22 -> 0 | R13: =R14*O22 -> 0 | T13: =T14*Q22 -> 0 | U13: =U14*R22 -> 0 | W13: =W14*T22 -> 0 | X13: =X14*U22 -> 0 | Z13: =Z14*W22 -> 0 | AA13: =AA14*X22 -> 0 | AC13: =AC14*Z22 -> 0
B14: FX Growth (%) | K14: =K13/H22 -> 0.096090126 | L14: =L13/I22 -> 0.061585835 | N14: 0 | O14: 0 | Q14: 0 | R14: 0 | T14: 0 | U14: 0 | W14: 0 | X14: 0 | Z14: 0 | AA14: 0 | AC14: 0
B16: Scope | H16: 15 | I16: 3 | K16: 3 | L16: 0 | N16: =N17*K22 -> 8.995 | O16: =O17*L22 -> 5.345 | Q16: =Q17*N22 -> 39.0383 | R16: =R17*O22 -> 5.799325 | T16: =T17*Q22 -> 42.94213 | U16: =U17*R22 -> 6.2922676 | W16: =W17*T22 -> 47.236343 | X16: =X17*U22 -> 6.8271104 | Z16: =Z17*W22 -> 51.959977 | AA16: =AA17*X22 -> 7.4074148 | AC16: =AC17*Z22 -> 57.155975
B17: Scope growth (%) | K17: =K16/H22 -> 0.0019880716 | L17: =L16/I22 -> 0 | N17: 0.005 | O17: 0.005 | Q17: 0.02 | R17: 0.005 | T17: 0.02 | U17: 0.005 | W17: 0.02 | X17: 0.005 | Z17: 0.02 | AA17: 0.005 | AC17: 0.02
B19: Hyperinflation
B20: Hyperinflation (%)
H21: =1682-1509 -> 173 | I21: =1299-1100 -> 199
B22: Total | E22: 1394 | F22: 819 | H22: 1509 | I22: =F22+I4+I13+I16+I19+I21 -> 1299 | K22: =H22+K4+K13+K16+K19+K21 -> 1799 | L22: =I22+L4+L13+L16+L19+L21 -> 1069 | N22: =N4+N13+N16+K22 -> 1951.915 | O22: =O4+O13+O16+L22 -> 1159.865 | Q22: =Q4+Q13+Q16+N22 -> 2147.1065 | R22: =R4+R13+R16+O22 -> 1258.4535 | T22: =T4+T13+T16+Q22 -> 2361.8171 | U22: =U4+U13+U16+R22 -> 1365.4221 | W22: =W4+W13+W16+T22 -> 2597.9989 | X22: =X4+X13+X16+U22 -> 1481.483 | Z22: =Z4+Z13+Z16+W22 -> 2857.7988 | AA22: =AA4+AA13+AA16+X22 -> 1607.409 | AC22: =AC4+AC13+AC16+Z22 -> 3143.5786
K23: =K22/H22-1 -> 0.19218025 | L23: =L22/I22-1 -> -0.17705928 | N23: =N22/K22-1 -> 0.085 | O23: =O22/L22-1 -> 0.085 | Q23: =Q22/N22-1 -> 0.1 | R23: =R22/O22-1 -> 0.085 | T23: =T22/Q22-1 -> 0.1 | U23: =U22/R22-1 -> 0.085 | W23: =W22/T22-1 -> 0.1 | X23: =X22/U22-1 -> 0.085 | Z23: =Z22/W22-1 -> 0.1 | AA23: =AA22/X22-1 -> 0.085 | AC23: =AC22/Z22-1 -> 0.1

Sheet Africa
C2: ='Income Statement '!C2 -> H1'21 | D2: ='Income Statement '!D2 -> H2'21 | E2: ='Income Statement '!E2 -> FY'21 | F2: ='Income Statement '!F2 -> H1'22 | G2: ='Income Statement '!G2 -> H2'22 | H2: ='Income Statement '!H2 -> FY'22 | I2: ='Income Statement '!I2 -> H1'23 | J2: ='Income Statement '!J2 -> H2'23 | ... AC2: ='Income Statement '!AC2 -> FY'29E
B3: Net Sales
B4: Organic Sales | H4: 451 | I4: 52 | K4: 83 | L4: 95 | N4: =N5*K22 -> 135.92 | O4: =O5*L22 -> 78 | Q4: =Q5*N22 -> 147.4732 | R4: =R5*O22 -> 84.63 | T4: =T5*Q22 -> 162.22052 | U4: =U5*R22 -> 91.82355 | W4: =W5*T22 -> 178.44257 | X4: =X5*U22 -> 99.628552 | Z4: =Z5*W22 -> 196.28683 | AA4: =AA5*X22 -> 108.09698 | AC4: =AC5*Z22 -> 215.91551
B5: Organic growth (%) | L5: =L4/I22 -> 0.085354897 | N5: =N8+N11 -> 0.08 | O5: =O8+O11 -> 0.08 | Q5: =Q8+Q11 -> 0.08 | R5: =R8+R11 -> 0.08 | T5: =T8+T11 -> 0.08 | U5: =U8+U11 -> 0.08 | W5: =W8+W11 -> 0.08 | X5: =X8+X11 -> 0.08 | Z5: =Z8+Z11 -> 0.08 | AA5: =AA8+AA11 -> 0.08 | AC5: =AC8+AC11 -> 0.08
B7: Volume
B8: Volume Growth (%) | L8: -0.06 | N8: 0.04 | O8: 0.04 | Q8: 0.04 | R8: 0.04 | T8: 0.04 | U8: 0.04 | W8: 0.04 | X8: 0.04 | Z8: 0.04 | AA8: 0.04 | AC8: 0.04
B10: Price
B11: Price (%) | L11: 0.16 | N11: 0.04 | O11: 0.04 | Q11: 0.04 | R11: 0.04 | T11: 0.04 | U11: 0.04 | W11: 0.04 | X11: 0.04 | Z11: 0.04 | AA11: 0.04 | AC11: 0.04
B13: FX | H13: 24 | I13: 30 | K13: -39 | L13: -229 | N13: =N14*K22 -> 0 | O13: =O14*L22 -> 0 | Q13: =Q14*N22 -> 0 | R13: =R14*O22 -> 0 | T13: =T14*Q22 -> 0 | U13: =U14*R22 -> 0 | W13: =W14*T22 -> 0 | X13: =X14*U22 -> 0 | Z13: =Z14*W22 -> 0 | AA13: =AA14*X22 -> 0 | AC13: =AC14*Z22 -> 0
B14: FX Growth (%) | L14: =L13/I22 -> -0.20575022 | N14: 0 | O14: 0 | Q14: 0 | R14: 0 | T14: 0 | U14: 0 | W14: 0 | X14: 0 | Z14: 0 | AA14: 0 | AC14: 0
B16: Scope | H16: 3 | I16: -73 | K16: 104 | L16: -8 | N16: =N17*K22 -> 8.495 | O16: =O17*L22 -> 4.875 | Q16: =Q17*N22 -> 36.8683 | R16: =R17*O22 -> 5.289375 | T16: =T17*Q22 -> 40.55513 | U16: =U17*R22 -> 5.7389719 | W16: =W17*T22 -> 44.610643 | X16: =X17*U22 -> 6.2267845 | Z16: =Z17*W22 -> 49.071707 | AA16: =AA17*X22 -> 6.7560612 | AC16: =AC17*Z22 -> 53.978878
B17: Scope growth (%) | L17: =L16/I22 -> -0.0071877808 | N17: 0.005 | O17: 0.005 | Q17: 0.02 | R17: 0.005 | T17: 0.02 | U17: 0.005 | W17: 0.02 | X17: 0.005 | Z17: 0.02 | AA17: 0.005 | AC17: 0.02
B19: Hyperinflation | L19: 4
B20: Hyperinflation (%)
H21: 26 | I21: =1113-943 -> 170
B22: Total | E22: 1047 | F22: 868 | H22: 1551 | I22: 1113 | K22: =H22+K4+K13+K16+K19 -> 1699 | L22: =I22+L4+L13+L16+L19 -> 975 | N22: =N4+N13+N16+K22 -> 1843.415 | O22: =O4+O13+O16+L22 -> 1057.875 | Q22: =Q4+Q13+Q16+N22 -> 2027.7565 | R22: =R4+R13+R16+O22 -> 1147.7944 | T22: =T4+T13+T16+Q22 -> 2230.5322 | U22: =U4+U13+U16+R22 -> 1245.3569 | W22: =W4+W13+W16+T22 -> 2453.5854 | X22: =X4+X13+X16+U22 -> 1351.2122 | Z22: =Z4+Z13+Z16+W22 -> 2698.9439 | AA22: =AA4+AA13+AA16+X22 -> 1466.0653 | AC22: =AC4+AC13+AC16+Z22 -> 2968.8383
K23: =K22/H22-1 -> 0.095422308 | L23: =L22/I22-1 -> -0.12398922 | N23: =N22/K22-1 -> 0.085 | O23: =O22/L22-1 -> 0.085 | Q23: =Q22/N22-1 -> 0.1 | R23: =R22/O22-1 -> 0.085 | T23: =T22/Q22-1 -> 0.1 | U23: =U22/R22-1 -> 0.085 | W23: =W22/T22-1 -> 0.1 | X23: =X22/U22-1 -> 0.085 | Z23: =Z22/W22-1 -> 0.1 | AA23: =AA22/X22-1 -> 0.085 | AC23: =AC22/Z22-1 -> 0.1

Sheet Corporate
C2: ='Income Statement '!C2 -> H1'21 | D2: ='Income Statement '!D2 -> H2'21 | E2: ='Income Statement '!E2 -> FY'21 | F2: ='Income Statement '!F2 -> H1'22 | G2: ='Income Statement '!G2 -> H2'22 | H2: ='Income Statement '!H2 -> FY'22 | I2: ='Income Statement '!I2 -> H1'23 | J2: ='Income Statement '!J2 -> H2'23 | ... AC2: ='Income Statement '!AC2 -> FY'29E
B3: Net Sales
B4: Organic Sales | K4: 33 | L4: 9
B5: Organic growth (%) | L5: 0.17
B7: FX | K7: 1 | L7: -229
B8: FX Growth (%)
B10: Scope | L10: -8
B11: Scope growth (%)
B13: Hyperinflation | L13: 4
B14: Hyperinflation (%)
B16: Total | H16: 54 | I16: 1113 | K16: =H16+K4+K7+K10+K13 -> 88 | L16: =I16+L4+L7+L10+L13 -> 889

Sheet Income Statement 
C2: H1'21 | D2: H2'21 | E2: FY'21 | F2: H1'22 | G2: H2'22 | H2: FY'22 | I2: H1'23 | J2: H2'23 | K2: FY'23 | L2: H1'24 | M2: H2'24E | N2: FY'24E | O2: H1'25E | P2: H2'25E | Q2: FY'25E | R2: H1'26E | S2: H2'26E | T2: FY'26E | U2: H1'27E | V2: H2'27E | W2: FY'27E | X2: H1'28E | Y2: H2'28E | Z2: FY'28E | AA2: H1'29E | AB2: H2'29E | AC2: FY'29E
B3: Sales | C3: 10436 | D3: =E3-C3 -> 8717 | E3: 19153 | F3: 11753 | G3: =H3-F3 -> 10695 | H3: 22448 | I3: 15611 | J3: =K3-I3 -> 7904 | K3: 23515 | L3: 15181
B4: Excise Duties | C4: 3562 | D4: =E4-C4 -> 2858 | E4: 6420 | F4: 3796 | G4: =H4-F4 -> 3200 | H4: 6996 | I4: 4491 | J4: =K4-I4 -> 1911 | K4: 6402 | L4: 4219
B5: Net Sales | C5: =C3-C4 -> 6874 | D5: =D3-D4 -> 5859 | E5: =E3-E4 -> 12733 | F5: =F3-F4 -> 7957 | G5: =G3-G4 -> 7495 | H5: =H3-H4 -> 15452 | I5: =I3-I4 -> 11120 | J5: =J3-J4 -> 5993 | ... L5: =L3-L4 -> 10962 | M5: =N5-L5 -> 7594.215 | N5: ='Revenue Drivers'!N22 -> 18556.215 | O5: ='Revenue Drivers'!O22 -> 11888.415 | P5: =Q5-O5 -> 8510.0215 | Q5: ='Revenue Drivers'!Q22 -> 20398.436 | R5: ='Revenue Drivers'!R22 -> 12893.575 | S5: =T5-R5 -> 9531.3049 | T5: ='Revenue Drivers'!T22 -> 22424.88 | U5: ='Revenue Drivers'!U22 -> 13984.174 | V5: =W5-U5 -> 10669.794 | W5: ='Revenue Drivers'!W22 -> 24653.968 | X5: ='Revenue Drivers'!X22 -> 15167.474 | Y5: =Z5-X5 -> 11938.491 | Z5: ='Revenue Drivers'!Z22 -> 27105.965 | AA5: ='Revenue Drivers'!AA22 -> 16451.354 | AB5: =AC5-AA5 -> 13351.807 | AC5: ='Revenue Drivers'!AC22 -> 29803.161
B6: Cost of Sales | C6: 2661 | D6: =E6-C6 -> 2377 | E6: 5038 | F6: 2955 | G6: =H6-F6 -> 3018 | H6: 5973 | I6: 4279 | J6: =K6-I6 -> 2620 | K6: 6899 | L6: 4241 | M6: =M5-M7 -> 3181.486 | N6: =L6+M6 -> 7422.486 | O6: =O5-O7 -> 4160.9452 | P6: =P5-P7 -> 2978.5075 | Q6: =O6+P6 -> 7139.4528 | R6: =R5-R7 -> 4512.7513 | S6: =S5-S7 -> 3335.9567 | T6: =R6+S6 -> 7848.7081 | U6: =U5-U7 -> 4894.461 | V6: =V5-V7 -> 3734.4279 | W6: =U6+V6 -> 8628.8889 | X6: =X5-X7 -> 5308.6159 | Y6: =Y5-Y7 -> 4178.4719 | Z6: =X6+Y6 -> 9487.0877 | AA6: =AA5-AA7 -> 5757.974 | AB6: =AB5-AB7 -> 4673.1325 | AC6: =AA6+AB6 -> 10431.107
B7: Gross Profit | C7: =C5-C6 -> 4213 | D7: =D5-D6 -> 3482 | E7: =E5-E6 -> 7695 | F7: =F5-F6 -> 5002 | G7: =G5-G6 -> 4477 | H7: =H5-H6 -> 9479 | I7: =I5-I6 -> 6841 | J7: =J5-J6 -> 3373 | ... L7: =L5-L6 -> 6721 | M7: =N7-L7 -> 4412.729 | N7: =N5*N8 -> 11133.729 | O7: =O5*O8 -> 7727.4698 | P7: =Q7-O7 -> 5531.514 | Q7: =Q5*Q8 -> 13258.984 | R7: =R5*R8 -> 8380.8239 | S7: =T7-R7 -> 6195.3482 | T7: =T5*T8 -> 14576.172 | U7: =U5*U8 -> 9089.7132 | V7: =W7-U7 -> 6935.3661 | W7: =W5*W8 -> 16025.079 | X7: =X5*X8 -> 9858.8581 | Y7: =Z7-X7 -> 7760.0192 | Z7: =Z5*Z8 -> 17618.877 | AA7: =AA5*AA8 -> 10693.38 | AB7: =AC7-AA7 -> 8678.6747 | AC7: =AC5*AC8 -> 19372.055
B8: Gross Profit Margin (%) | C8: =C7/C5 -> 0.61288915 | D8: =D7/D5 -> 0.59429937 | E8: =E7/E5 -> 0.60433519 | F8: =F7/F5 -> 0.62862888 | G8: =G7/G5 -> 0.59733155 | H8: =H7/H5 -> 0.6134481 | I8: =I7/I5 -> 0.61519784 | J8: =J7/J5 -> 0.56282329 | ... M8: =M7/M5 -> 0.58106453 | N8: 0.6 | O8: 0.65 | P8: =P7/P5 -> 0.65 | Q8: 0.65 | R8: 0.65 | S8: =S7/S5 -> 0.65 | T8: 0.65 | U8: 0.65 | V8: =V7/V5 -> 0.65 | W8: 0.65 | X8: 0.65 | Y8: =Y7/Y5 -> 0.65 | Z8: 0.65 | AA8: 0.65 | AB8: =AB7/AB5 -> 0.65 | AC8: 0.65
B9: Marketing | C9: 1085 | D9: =E9-C9 -> 1078 | E9: 2163 | F9: 1351 | G9: =H9-F9 -> 1370 | H9: 2721 | I9: 1861 | J9: =K9-I9 -> 1190 | K9: 3051 | L9: 1952 | M9: =N9-L9 -> 831.43225 | N9: =N10*N5 -> 2783.4322 | O9: =O10*O5 -> 1783.2622 | P9: =Q9-O9 -> 1276.5032 | Q9: =Q10*Q5 -> 3059.7655 | R9: =R10*R5 -> 1934.0363 | S9: =T9-R9 -> 1429.6957 | T9: =T10*T5 -> 3363.732 | U9: =U10*U5 -> 2097.6261 | V9: =W9-U9 -> 1600.4691 | W9: =W10*W5 -> 3698.0952 | X9: =X10*X5 -> 2275.1211 | Y9: =Z9-X9 -> 1790.7737 | Z9: =Z10*Z5 -> 4065.8947 | AA9: =AA10*AA5 -> 2467.7031 | AB9: =AC9-AA9 -> 2002.7711 | AC9: =AC10*AC5 -> 4470.4742
B10: % of sales | C10: =C9/C5 -> 0.15784114 | D10: =D9/D5 -> 0.18399044 | E10: =E9/E5 -> 0.16987356 | F10: =F9/F5 -> 0.16978761 | G10: =G9/G5 -> 0.18278853 | H10: =H9/H5 -> 0.17609371 | I10: =I9/I5 -> 0.16735612 | J10: =J9/J5 -> 0.19856499 | ... M10: =M9/M5 -> 0.10948232 | N10: 0.15 | O10: 0.15 | P10: =P9/P5 -> 0.15 | Q10: 0.15 | R10: 0.15 | S10: =S9/S5 -> 0.15 | T10: 0.15 | U10: 0.15 | V10: =V9/V5 -> 0.15 | W10: 0.15 | X10: 0.15 | Y10: =Y9/Y5 -> 0.15 | Z10: 0.15 | AA10: 0.15 | AB10: =AB9/AB5 -> 0.15 | AC10: 0.15
B11: Other Operating Item | C11: 889 | D11: =E11-C11 -> 1195 | E11: =2531-E13 -> 2084 | F11: 908 | G11: =H11-F11 -> 795 | H11: =2531-H13 -> 1703 | I11: 1249 | J11: =K11-I11 -> 216 | K11: =2531-K13 -> 1465 | L11: 1452 | M11: =N11-L11 -> 106.72206 | N11: =N12*N7 -> 1558.7221 | O11: =O12*O7 -> 850.02167 | P11: =Q11-O11 -> 873.64621 | Q11: =Q12*Q7 -> 1723.6679 | R11: =R12*R7 -> 921.89063 | S11: =T11-R11 -> 973.01174 | T11: =T12*T7 -> 1894.9024 | U11: =U12*U7 -> 999.86845 | V11: =W11-U11 -> 1083.3919 | W11: =W12*W7 -> 2083.2603 | X11: =X12*X7 -> 1084.4744 | Y11: =Z11-X11 -> 1205.9797 | Z11: =Z12*Z7 -> 2290.454 | AA11: =AA12*AA7 -> 1176.2718 | AB11: =AC11-AA11 -> 1342.0953 | AC11: =AC12*AC7 -> 2518.3671
B12: % of sales | C12: =C11/C5 -> 0.1293279 | D12: =D11/D5 -> 0.20395972 | E12: =E11/E5 -> 0.16366921 | F12: =F11/F5 -> 0.11411336 | G12: =G11/G5 -> 0.10607071 | H12: =H11/H5 -> 0.11021227 | I12: =I11/I5 -> 0.11232014 | J12: =J11/J5 -> 0.036042049 | ... L12: =L11/L5 -> 0.13245758 | M12: =M11/M7 -> 0.024185047 | N12: 0.14 | O12: 0.11 | P12: =P11/P7 -> 0.1579398 | Q12: 0.13 | R12: 0.11 | S12: =S11/S7 -> 0.15705522 | T12: 0.13 | U12: 0.11 | V12: =V11/V7 -> 0.15621264 | W12: 0.13 | X12: 0.11 | Y12: =Y11/Y7 -> 0.15540937 | Z12: 0.13 | AA12: 0.11 | AB12: =AB11/AB7 -> 0.15464289 | AC12: 0.13
B13: D&A | C13: 486 | D13: =E13-C13 -> -39 | E13: 447 | F13: 452 | G13: =H13-F13 -> 376 | H13: 828 | I13: 332 | J13: =K13-I13 -> 734 | K13: 1066 | L13: 411 | M13: =N13-L13 -> 418.812 | N13: ='Balance Sheet'!N62 -> 829.812 | O13: ='Balance Sheet'!O62 -> 417.97975 | P13: =Q13-O13 -> 428.79717 | Q13: ='Balance Sheet'!Q62 -> 846.77692 | R13: ='Balance Sheet'!R62 -> 429.9311 | S13: =T13-R13 -> 442.85595 | T13: ='Balance Sheet'!T62 -> 872.78705 | U13: ='Balance Sheet'!U62 -> 446.03341 | V13: =W13-U13 -> 461.08493 | W13: ='Balance Sheet'!W62 -> 907.11835 | X13: ='Balance Sheet'!X62 -> 466.41005 | Y13: =Z13-X13 -> 483.62082 | Z13: ='Balance Sheet'!Z62 -> 950.03088 | AA13: ='Balance Sheet'!AA62 -> 491.2259 | AB13: =AC13-AA13 -> 510.64139 | AC13: ='Balance Sheet'!AC62 -> 1001.8673
B14: Operating Profit | C14: =C7-C9-C11 -> 2239 | D14: =D7-D9-D11 -> 1209 | E14: =E7-E9-E11 -> 3448 | F14: =F7-F9-F11 -> 2743 | G14: =G7-G9-G11 -> 2312 | H14: =H7-H9-H11 -> 5055 | I14: =I7-I9-I11 -> 3731 | J14: =J7-J9-J11 -> 1967 | ... AC14: =AC7-AC9-AC11 -> 12383.214
B15: EBIT Margin (%) | C15: =C14/C5 -> 0.3257201 | D15: =D14/D5 -> 0.20634921 | E15: =E14/E5 -> 0.27079243 | F15: =F14/F5 -> 0.34472791 | G15: =G14/G5 -> 0.30847231 | H15: =H14/H5 -> 0.32714212 | I15: =I14/I5 -> 0.33552158 | J15: =J14/J5 -> 0.32821625 | ... AC15: =AC14/AC5 -> 0.4155
B16: Non-operating items | C16: 5 | D16: =E16-C16 -> 9 | E16: 14 | F16: -31 | G16: =H16-F16 -> 14 | H16: -17 | I16: 19 | J16: =K16-I16 -> 309 | K16: 328 | L16: -60 | N16: =L16+M16 -> -60
B17: Finance Income | C17: 127 | D17: =E17-C17 -> 151 | E17: 278 | F17: 130 | G17: =H17-F17 -> 367 | H17: 497 | I17: 303 | J17: =K17-I17 -> 37 | K17: 340 | L17: 287 | N17: =L17+M17 -> 287
B18: Finance Charges | C18: -327 | D18: =E18-C18 -> -324 | E18: -651 | F18: -310 | G18: =H18-F18 -> -609 | H18: -919 | I18: -648 | J18: =K18-I18 -> -286 | K18: -934 | L18: -718 | M18: =N18-L18 -> -799.04 | N18: =-'Balance Sheet'!N82 -> -1517.04 | O18: =-'Balance Sheet'!O82 -> -819.04 | P18: =Q18-O18 -> -839.04 | Q18: =-'Balance Sheet'!Q82 -> -1658.08 | R18: =-'Balance Sheet'!R82 -> -859.04 | S18: =T18-R18 -> -879.04 | T18: =-'Balance Sheet'!T82 -> -1738.08 | U18: =-'Balance Sheet'!U82 -> -899.04 | V18: =W18-U18 -> -919.04 | W18: =-'Balance Sheet'!W82 -> -1818.08 | X18: =-'Balance Sheet'!X82 -> -939.04 | Y18: =Z18-X18 -> -959.04 | Z18: =-'Balance Sheet'!Z82 -> -1898.08 | AA18: =-'Balance Sheet'!AA82 -> -979.04 | AB18: =AC18-AA18 -> -999.04 | AC18: =-'Balance Sheet'!AC82 -> -1978.08
B19: Share of after tax results of associates and JVs | C19: 154 | D19: =E19-C19 -> 180 | E19: 334 | F19: 190 | G19: =H19-F19 -> 227 | H19: 417 | I19: 202 | J19: =K19-I19 -> 168 | K19: 370 | L19: 253 | N19: =L19+M19 -> 253
B20: Profit Before Taxes | C20: =C14+C16+C17+C18+C19 -> 2198 | D20: =D14+D16+D17+D18+D19 -> 1225 | E20: =E14+E16+E17+E18+E19 -> 3423 | F20: =F14+F16+F17+F18+F19 -> 2722 | G20: =G14+G16+G17+G18+G19 -> 2311 | H20: =H14+H16+H17+H18+H19 -> 5033 | I20: =I14+I16+I17+I18+I19 -> 3607 | J20: =J14+J16+J17+J18+J19 -> 2195 | ... AC20: =AC14+AC16+AC17+AC18+AC19 -> 10405.134
B21: Taxation | C21: 537 | D21: =E21-C21 -> 370 | E21: 907 | F21: 634 | G21: =H21-F21 -> 415 | H21: 1049 | I21: 766 | J21: =K21-I21 -> 204 | K21: 970 | L21: 737 | M21: =N21-L21 -> 413.90694 | N21: =N20*N22 -> 1150.9069 | O21: =O20*O22 -> 855.02917 | P21: =Q21-O21 -> 508.46491 | Q21: =Q20*Q22 -> 1363.4941 | R21: =R20*R22 -> 933.1714 | S21: =T21-R21 -> 582.72014 | T21: =T20*T22 -> 1515.8915 | U21: =U20*U22 -> 1018.6357 | V21: =W21-U21 -> 666.49303 | W21: =W20*W22 -> 1685.1288 | X21: =X20*X22 -> 1112.0445 | Y21: =Z21-X21 -> 760.84517 | Z21: =Z20*Z22 -> 1872.8897 | AA21: =AA20*AA22 -> 1214.0731 | AB21: =AC21-AA21 -> 866.95366 | AC21: =AC20*AC22 -> 2081.0267
B22: Tax Rate (%) | C22: =C21/C20 -> 0.24431301 | D22: =D21/D20 -> 0.30204082 | E22: =E21/E20 -> 0.26497225 | F22: =F21/F20 -> 0.23291697 | G22: =G21/G20 -> 0.17957594 | H22: =H21/H20 -> 0.2084244 | I22: =I21/I20 -> 0.21236485 | J22: =J21/J20 -> 0.092938497 | ... M22: =M21/M20 -> 0.15470064 | N22: 0.2 | O22: 0.2 | P22: =P21/P20 -> 0.2 | Q22: 0.2 | R22: 0.2 | S22: =S21/S20 -> 0.2 | T22: 0.2 | U22: 0.2 | V22: =V21/V20 -> 0.2 | W22: 0.2 | X22: 0.2 | Y22: =Y21/Y20 -> 0.2 | Z22: 0.2 | AA22: 0.2 | AB22: =AB21/AB20 -> 0.2 | AC22: 0.2
B23: Profit | C23: =C20-C21 -> 1661 | D23: =D20-D21 -> 855 | E23: =E20-E21 -> 2516 | F23: =F20-F21 -> 2088 | G23: =G20-G21 -> 1896 | H23: =H20-H21 -> 3984 | I23: =I20-I21 -> 2841 | J23: =J20-J21 -> 1991 | ... AC23: =AC20-AC21 -> 8324.1069
B25: Non-controlling interests | C25: 81 | D25: =E25-C25 -> 58 | E25: 139 | F25: 123 | G25: =H25-F25 -> -34 | H25: 89 | I25: 132 | J25: =K25-I25 -> -100 | K25: 32 | L25: 132 | M25: =L25 -> 132 | N25: =L25+M25 -> 264
B26: Share of parent | C26: =C23-C25 -> 1580 | D26: =D23-D25 -> 797 | E26: =E23-E25 -> 2377 | F26: =F23-F25 -> 1965 | G26: =G23-G25 -> 1930 | H26: =H23-H25 -> 3895 | I26: =I23-I25 -> 2709 | J26: =J23-J25 -> 2091 | ... AC26: =AC23-AC25 -> 8324.1069
B28: Weighted number of shares
B29: Basic Shares | C29: 2336 | D29: =D26/D33*100 -> 2338.985 | E29: 2337 | F29: 2331 | G29: =G26/G33*100 -> 2304.9124 | H29: 2318 | I29: 2274 | J29: =J26/J33*100 -> 2251.1745 | K29: 2264 | L29: 2242 | M29: =L29 -> 2242 | N29: =M29 -> 2242 | O29: =N29 -> 2242 | P29: =O29 -> 2242 | Q29: =P29 -> 2242 | R29: =Q29 -> 2242 | S29: =R29 -> 2242 | T29: =S29 -> 2242 | ... AC29: =AB29 -> 2242
B30: Dilutive effect | C30: 7 | D30: =D31-D29 -> 9.9900119 | E30: 8 | F30: 8 | G30: =G31-G29 -> 6.0048726 | H30: 7 | I30: 7 | J30: =J31-J29 -> 6.9996032 | K30: 7 | L30: 5
B31: Diluted Shares | C31: =C29+C30 -> 2343 | D31: =D26/D34*100 -> 2348.975 | E31: =E29+E30 -> 2345 | F31: =F29+F30 -> 2339 | G31: =G26/G34*100 -> 2310.9173 | H31: =H29+H30 -> 2325 | I31: =I29+I30 -> 2281 | J31: =J26/J34*100 -> 2258.1741 | K31: =K29+K30 -> 2271 | L31: =L29+L30 -> 2247 | M31: =L31 -> 2247 | N31: =M31 -> 2247 | O31: =N31 -> 2247 | P31: =O31 -> 2247 | Q31: =P31 -> 2247 | R31: =Q31 -> 2247 | S31: =R31 -> 2247 | T31: =S31 -> 2247 | ... AC31: =AB31 -> 2247
B33: Basic EPS | C33: =C26/C29*100 -> 67.636986 | D33: =E33-C33 -> 34.07461 | E33: =E26/E29*100 -> 101.7116 | F33: =F26/F29*100 -> 84.298584 | G33: =H33-F33 -> 83.734203 | H33: =H26/H29*100 -> 168.03279 | I33: =I26/I29*100 -> 119.12929 | J33: =K33-I33 -> 92.884847 | K33: =K26/K29*100 -> 212.01413 | L33: =L26/L29*100 -> 98.572703 | M33: =M26/M29*100 -> 94.987857 | N33: =N26/N29*100 -> 193.56056 | O33: =O26/O29*100 -> 152.54758 | P33: =P26/P29*100 -> 90.716308 | Q33: =Q26/Q29*100 -> 243.26388 | R33: =R26/R29*100 -> 166.4891 | ... AC33: =AC26/AC29*100 -> 371.28041
B34: Diluted EPS | C34: =C26/C31*100 -> 67.434913 | D34: =E34-C34 -> 33.929693 | E34: =E26/E31*100 -> 101.36461 | F34: =F26/F31*100 -> 84.010261 | G34: =H34-F34 -> 83.516621 | H34: =H26/H31*100 -> 167.52688 | I34: =I26/I31*100 -> 118.7637 | J34: =K34-I34 -> 92.596934 | K34: =K26/K31*100 -> 211.36063 | L34: =L26/L31*100 -> 98.35336 | M34: =M26/M31*100 -> 94.776491 | N34: =N26/N31*100 -> 193.12985 | O34: =O26/O31*100 -> 152.20813 | P34: =P26/P31*100 -> 90.514447 | Q34: =Q26/Q31*100 -> 242.72258 | R34: =R26/R31*100 -> 166.11863 | ... AC34: =AC26/AC31*100 -> 370.45424
B37: Adjustments

Sheet Cash Flow
C2: ='Balance Sheet'!C2 -> H1'21 | D2: ='Balance Sheet'!D2 -> H2'21 | E2: ='Balance Sheet'!E2 -> FY'21 | F2: ='Balance Sheet'!F2 -> H1'22 | G2: ='Balance Sheet'!G2 -> H2'22 | H2: ='Balance Sheet'!H2 -> FY'22 | I2: ='Balance Sheet'!I2 -> H1'23 | J2: ='Balance Sheet'!J2 -> H2'23 | ... AC2: ='Balance Sheet'!AC2 -> FY'29E
B3: Cash flows from operating activities
B4: Profit from the period | C4: 1661 | D4: =E4-C4 -> 1138 | E4: 2799 | F4: 2088 | G4: =H4-F4 -> 1250 | H4: 3338 | I4: 2841 | J4: =K4-I4 -> 925 | K4: 3766 | L4: 2342 | M4: ='Income Statement '!M23 -> 2261.6278 | N4: ='Income Statement '!N23 -> 4603.6278 | O4: ='Income Statement '!O23 -> 3420.1167 | P4: ='Income Statement '!P23 -> 2033.8596 | Q4: ='Income Statement '!Q23 -> 5453.9763 | R4: ='Income Statement '!R23 -> 3732.6856 | S4: ='Income Statement '!S23 -> 2330.8806 | T4: ='Income Statement '!T23 -> 6063.5662 | ... AC4: ='Income Statement '!AC23 -> 8324.1069
B5: Taxation | C5: 537 | D5: =E5-C5 -> 370 | E5: 907 | F5: 634 | G5: =H5-F5 -> 415 | H5: 1049 | I5: 766 | J5: =K5-I5 -> 204 | K5: 970 | L5: 737 | M5: ='Income Statement '!M21 -> 413.90694 | N5: ='Income Statement '!N21 -> 1150.9069 | O5: ='Income Statement '!O21 -> 855.02917 | P5: ='Income Statement '!P21 -> 508.46491 | Q5: ='Income Statement '!Q21 -> 1363.4941 | R5: ='Income Statement '!R21 -> 933.1714 | S5: ='Income Statement '!S21 -> 582.72014 | T5: ='Income Statement '!T21 -> 1515.8915 | ... AC5: ='Income Statement '!AC21 -> 2081.0267
B6: Share of after tax results of associates and JVs | C6: -154 | D6: =E6-C6 -> -180 | E6: -334 | F6: -190 | G6: =H6-F6 -> -227 | H6: -417 | I6: -202 | J6: =K6-I6 -> -168 | K6: -370 | L6: -253 | M6: =-'Income Statement '!M19 -> 0 | N6: =-'Income Statement '!N19 -> -253 | O6: =-'Income Statement '!O19 -> 0 | P6: =-'Income Statement '!P19 -> 0 | Q6: =-'Income Statement '!Q19 -> 0 | R6: =-'Income Statement '!R19 -> 0 | S6: =-'Income Statement '!S19 -> 0 | T6: =-'Income Statement '!T19 -> 0 | ... AC6: =-'Income Statement '!AC19 -> 0
B7: Net finance charges | C7: 200 | D7: =E7-C7 -> 173 | E7: 373 | F7: 180 | G7: =H7-F7 -> 242 | H7: 422 | I7: 345 | J7: =K7-I7 -> 249 | K7: 594 | L7: 431 | M7: =-'Income Statement '!M18 -> 799.04 | N7: =-'Income Statement '!N18-'Income Statement '!N17 -> 1230.04 | O7: =-'Income Statement '!O18 -> 819.04 | P7: =-'Income Statement '!P18 -> 839.04 | Q7: =-'Income Statement '!Q18 -> 1658.08 | R7: =-'Income Statement '!R18 -> 859.04 | S7: =-'Income Statement '!S18 -> 879.04 | T7: =-'Income Statement '!T18 -> 1738.08 | U7: =-'Income Statement '!U18 -> 899.04 | V7: =-'Income Statement '!V18 -> 919.04 | ... AC7: =-'Income Statement '!AC18 -> 1978.08
B8: Non-operating items | C8: -5 | D8: =E8-C8 -> -9 | E8: -14 | F8: 31 | G8: =H8-F8 -> -14 | H8: 17 | I8: -19 | J8: =K8-I8 -> -309 | K8: -328 | L8: 60 | M8: =-'Income Statement '!M16 -> 0 | N8: =-'Income Statement '!N16 -> 60 | O8: =-'Income Statement '!O16 -> 0 | P8: =-'Income Statement '!P16 -> 0 | Q8: =-'Income Statement '!Q16 -> 0 | R8: =-'Income Statement '!R16 -> 0 | S8: =-'Income Statement '!S16 -> 0 | T8: =-'Income Statement '!T16 -> 0 | ... AC8: =-'Income Statement '!AC16 -> 0
B9: Operating Profit | C9: =SUM(C4:C8) -> 2239 | D9: =SUM(D4:D8) -> 1492 | E9: =SUM(E4:E8) -> 3731 | F9: =SUM(F4:F8) -> 2743 | G9: =SUM(G4:G8) -> 1666 | H9: =SUM(H4:H8) -> 4409 | I9: =SUM(I4:I8) -> 3731 | J9: =SUM(J4:J8) -> 901 | ... AC9: =SUM(AC4:AC8) -> 12383.214
B10: Increase in inventories | C10: -112 | D10: =E10-C10 -> -331 | E10: -443 | F10: -187 | G10: =H10-F10 -> -553 | H10: -740 | I10: -552 | J10: =K10-I10 -> -123 | K10: -675 | L10: -82 | M10: ='Balance Sheet'!L16-'Balance Sheet'!M16 -> -300.0082 | N10: =L10+M10 -> -382.0082 | O10: ='Balance Sheet'!N16-'Balance Sheet'!O16 -> -1259.8418 | P10: ='Balance Sheet'!O16-'Balance Sheet'!P16 -> 1619.7777 | Q10: =O10+P10 -> 359.9359 | R10: ='Balance Sheet'!Q16-'Balance Sheet'!R16 -> -2583.63 | S10: ='Balance Sheet'!R16-'Balance Sheet'!S16 -> 1612.0475 | T10: =R10+S10 -> -971.58257 | U10: ='Balance Sheet'!T16-'Balance Sheet'!U16 -> -2657.8272 | V10: ='Balance Sheet'!U16-'Balance Sheet'!V16 -> 1589.0864 | W10: =U10+V10 -> -1068.7408 | X10: ='Balance Sheet'!W16-'Balance Sheet'!X16 -> -2684.0193 | Y10: ='Balance Sheet'!X16-'Balance Sheet'!Y16 -> 1543.9126 | Z10: =X10+Y10 -> -1140.1067 | AA10: ='Balance Sheet'!Z16-'Balance Sheet'!AA16 -> -2814.7688 | AB10: ='Balance Sheet'!AA16-'Balance Sheet'!AB16 -> 1486.0842 | AC10: =AA10+AB10 -> -1328.6846
B11: Increase in trade and other receivables | C11: -1078 | D11: =E11-C11 -> 632 | E11: -446 | F11: -976 | G11: =H11-F11 -> 598 | H11: -378 | I11: -1191 | J11: =K11-I11 -> 1312 | K11: 121 | L11: -1106 | M11: ='Balance Sheet'!L17-'Balance Sheet'!M17 -> 703.54202 | N11: =L11+M11 -> -402.45798 | O11: ='Balance Sheet'!N17-'Balance Sheet'!O17 -> -1074.334 | P11: ='Balance Sheet'!O17-'Balance Sheet'!P17 -> 703.44632 | Q11: =O11+P11 -> -370.8877 | R11: ='Balance Sheet'!Q17-'Balance Sheet'!R17 -> -1122.0336 | S11: ='Balance Sheet'!R17-'Balance Sheet'!S17 -> 700.08918 | T11: =R11+S11 -> -421.94443 | U11: ='Balance Sheet'!T17-'Balance Sheet'!U17 -> -1154.2564 | V11: ='Balance Sheet'!U17-'Balance Sheet'!V17 -> 690.11752 | W11: =U11+V11 -> -464.13887 | X11: ='Balance Sheet'!W17-'Balance Sheet'!X17 -> -1165.6312 | Y11: ='Balance Sheet'!X17-'Balance Sheet'!Y17 -> 670.4992 | Z11: =X11+Y11 -> -495.13205 | AA11: ='Balance Sheet'!Z17-'Balance Sheet'!AA17 -> -1222.4139 | AB11: ='Balance Sheet'!AA17-'Balance Sheet'!AB17 -> 645.38514 | AC11: =AA11+AB11 -> -577.02875
B12: Increase in trade and other payables | C12: 1161 | D12: =E12-C12 -> 59 | E12: 1220 | F12: 653 | G12: =H12-F12 -> 286 | H12: 939 | I12: 131 | J12: =K12-I12 -> -752 | K12: -621 | L12: 469 | M12: ='Balance Sheet'!M30-'Balance Sheet'!L30 -> -910.86726 | N12: =L12+M12 -> -441.86726 | O12: ='Balance Sheet'!O30-'Balance Sheet'!N30 -> 800.77276 | P12: ='Balance Sheet'!P30-'Balance Sheet'!O30 -> -1020.46 | Q12: =O12+P12 -> -219.6872 | R12: ='Balance Sheet'!R30-'Balance Sheet'!Q30 -> 1627.6869 | S12: ='Balance Sheet'!S30-'Balance Sheet'!R30 -> -1015.5899 | T12: =R12+S12 -> 612.09702 | U12: ='Balance Sheet'!U30-'Balance Sheet'!T30 -> 1674.4311 | V12: ='Balance Sheet'!V30-'Balance Sheet'!U30 -> -1001.1244 | W12: =U12+V12 -> 673.30672 | X12: ='Balance Sheet'!X30-'Balance Sheet'!W30 -> 1690.9322 | Y12: ='Balance Sheet'!Y30-'Balance Sheet'!X30 -> -972.66495 | Z12: =X12+Y12 -> 718.26721 | AA12: ='Balance Sheet'!AA30-'Balance Sheet'!Z30 -> 1773.3044 | AB12: ='Balance Sheet'!AB30-'Balance Sheet'!AA30 -> -936.23305 | AC12: =AA12+AB12 -> 837.07132
B13: Net change in working capital | C13: =C10+C11+C12 -> -29 | D13: =D10+D11+D12 -> 360 | E13: =E10+E11+E12 -> 331 | F13: =F10+F11+F12 -> -510 | G13: =G10+G11+G12 -> 331 | H13: =H10+H11+H12 -> -179 | I13: =I10+I11+I12 -> -1612 | J13: =J10+J11+J12 -> 437 | ... AC13: =AC10+AC11+AC12 -> -1068.6421
B14: D&A | C14: 219 | D14: =E14-C14 -> 228 | E14: 447 | F14: 224 | G14: =H14-F14 -> 604 | H14: 828 | I14: 332 | J14: =K14-I14 -> 734 | K14: 1066 | L14: 411 | M14: ='Income Statement '!M13 -> 418.812 | N14: =L14+M14 -> 829.812 | O14: ='Income Statement '!O13 -> 417.97975 | P14: ='Income Statement '!P13 -> 428.79717 | Q14: =O14+P14 -> 846.77692 | R14: ='Income Statement '!R13 -> 429.9311 | S14: ='Income Statement '!S13 -> 442.85595 | T14: =R14+S14 -> 872.78705 | U14: ='Income Statement '!U13 -> 446.03341 | V14: ='Income Statement '!V13 -> 461.08493 | W14: =U14+V14 -> 907.11835 | X14: ='Income Statement '!X13 -> 466.41005 | Y14: ='Income Statement '!Y13 -> 483.62082 | Z14: =X14+Y14 -> 950.03088 | AA14: ='Income Statement '!AA13 -> 491.2259 | AB14: ='Income Statement '!AB13 -> 510.64139 | AC14: =AA14+AB14 -> 1001.8673
B15: Dividends Received | C15: 82 | D15: =E15-C15 -> 208 | E15: 290 | F15: 1 | G15: =H15-F15 -> 189 | H15: 190 | I15: 5 | J15: =K15-I15 -> 214 | K15: 219 | L15: 5 | N15: =L15+M15 -> 5 | Q15: =O15+P15 -> 0 | T15: =R15+S15 -> 0 | W15: =U15+V15 -> 0 | Z15: =X15+Y15 -> 0 | AC15: =AA15+AB15 -> 0
B16: Post employment payments | C16: -14 | D16: =E16-C16 -> -16 | E16: -30 | F16: -23 | G16: =H16-F16 -> -66 | H16: -89 | I16: -27 | J16: =K16-I16 -> 2 | K16: -25 | L16: -24 | N16: =L16+M16 -> -24 | Q16: =O16+P16 -> 0 | T16: =R16+S16 -> 0 | W16: =U16+V16 -> 0 | Z16: =X16+Y16 -> 0 | AC16: =AA16+AB16 -> 0
B17: Other items | C17: -1 | D17: =E17-C17 -> 89 | E17: 88 | F17: 34 | G17: =H17-F17 -> 19 | H17: 53 | I17: 9 | J17: =K17-I17 -> 53 | K17: 62 | L17: 59 | N17: =L17+M17 -> 59 | Q17: =O17+P17 -> 0 | T17: =R17+S17 -> 0 | W17: =U17+V17 -> 0 | Z17: =X17+Y17 -> 0 | AC17: =AA17+AB17 -> 0
B18: Cash generated from operations | C18: =SUM(C14:C17) -> 286 | D18: =SUM(D14:D17) -> 509 | E18: =SUM(E14:E17) -> 795 | F18: =SUM(F14:F17) -> 236 | G18: =SUM(G14:G17) -> 746 | H18: =SUM(H14:H17) -> 982 | I18: =SUM(I14:I17) -> 319 | J18: =SUM(J14:J17) -> 1003 | ... AC18: =SUM(AC14:AC17) -> 1001.8673
B19: Interest Received | C19: 84 | D19: =E19-C19 -> 5 | E19: 89 | F19: 41 | G19: =H19-F19 -> 69 | H19: 110 | I19: 78 | J19: =K19-I19 -> 53 | K19: 131 | L19: 91 | N19: =L19+M19 -> 91
B20: Interest Paid | C20: -266 | D20: =E20-C20 -> -174 | E20: -440 | F20: -185 | G20: =H20-F20 -> -253 | H20: -438 | I20: -293 | J20: =K20-I20 -> -392 | K20: -685 | L20: -443 | M20: =-M7 -> -799.04 | N20: =L20+M20 -> -1242.04 | O20: =-O7 -> -819.04 | P20: =-P7 -> -839.04 | Q20: =O20+P20 -> -1658.08 | R20: =-R7 -> -859.04 | S20: =-S7 -> -879.04 | T20: =R20+S20 -> -1738.08 | U20: =-U7 -> -899.04 | V20: =-V7 -> -919.04 | W20: =U20+V20 -> -1818.08 | X20: =-X7 -> -939.04 | Y20: =-Y7 -> -959.04 | Z20: =X20+Y20 -> -1898.08 | AA20: =-AA7 -> -979.04 | AB20: =-AB7 -> -999.04 | AC20: =AA20+AB20 -> -1978.08 | AG20: 3654 | AH20: 3935 | AI20: 1472 | AJ20: 1552 | AK20: 3024 | AL20: 4319.1063
B21: Taxation Paid | C21: -316 | D21: =E21-C21 -> -536 | E21: -852 | F21: -378 | G21: =H21-F21 -> -571 | H21: -949 | I21: -751 | J21: =K21-I21 -> -450 | K21: -1201 | L21: -551 | M21: =-M5 -> -413.90694 | N21: =L21+M21 -> -964.90694 | O21: =-O5 -> -855.02917 | P21: =-P5 -> -508.46491 | Q21: =O21+P21 -> -1363.4941 | R21: =-R5 -> -933.1714 | S21: =-S5 -> -582.72014 | T21: =R21+S21 -> -1515.8915 | U21: =-U5 -> -1018.6357 | V21: =-V5 -> -666.49303 | W21: =U21+V21 -> -1685.1288 | X21: =-X5 -> -1112.0445 | Y21: =-Y5 -> -760.84517 | Z21: =X21+Y21 -> -1872.8897 | AA21: =-AA5 -> -1214.0731 | AB21: =-AB5 -> -866.95366 | AC21: =AA21+AB21 -> -2081.0267
B22: Net Cash Flow from Operating Activities | C22: =C9+C13+C18+C19+C20+C21 -> 1998 | D22: =D9+D13+D18+D19+D20+D21 -> 1656 | E22: =E9+E13+E18+E19+E20+E21 -> 3654 | F22: =F9+F13+F18+F19+F20+F21 -> 1947 | G22: =G9+G13+G18+G19+G20+G21 -> 1988 | H22: =H9+H13+H18+H19+H20+H21 -> 3935 | I22: =I9+I13+I18+I19+I20+I21 -> 1472 | J22: =J9+J13+J18+J19+J20+J21 -> 1552 | ... AC22: =AC9+AC13+AC18+AC19+AC20+AC21 -> 8257.3321
B24: Cash Flows from investing activities
B25: Disposal of PP&E | C25: 8 | D25: =E25-C25 -> 5 | E25: 13 | F25: 7 | G25: =H25-F25 -> 10 | H25: 17 | I25: 8 | J25: =K25-I25 -> 5 | K25: 13 | L25: 7 | N25: =L25+M25 -> 7
B26: Capex | C26: -250 | D26: =E26-C26 -> -376 | E26: -626 | F26: -382 | G26: =H26-F26 -> -715 | H26: -1097 | I26: -514 | J26: =K26-I26 -> -666 | K26: -1180 | L26: -582 | M26: =-'Balance Sheet'!M59 -> -402.4934 | N26: =L26+M26 -> -984.49339 | O26: =-'Balance Sheet'!O59 -> -630.086 | P26: =-'Balance Sheet'!P59 -> -451.03114 | Q26: =O26+P26 -> -1081.1171 | R26: =-'Balance Sheet'!R59 -> -683.35949 | S26: =-'Balance Sheet'!S59 -> -505.15916 | T26: =R26+S26 -> -1188.5186 | U26: =-'Balance Sheet'!U59 -> -741.16123 | V26: =-'Balance Sheet'!V59 -> -565.49908 | W26: =U26+V26 -> -1306.6603 | X26: =-'Balance Sheet'!X59 -> -803.87612 | Y26: =-'Balance Sheet'!Y59 -> -632.74002 | Z26: =X26+Y26 -> -1436.6161 | AA26: =-'Balance Sheet'!AA59 -> -871.92178 | AB26: =-'Balance Sheet'!AB59 -> -707.64578 | AC26: =AA26+AB26 -> -1579.5676
B27: Movements in loans and other investments | C27: -3 | D27: =E27-C27 -> -1 | E27: -4 | F27: 3 | G27: =H27-F27 -> -75 | H27: -72 | I27: -2 | J27: =K27-I27 -> -55 | K27: -57 | L27: -109 | N27: =L27+M27 -> -109
B28: Sale of businesses and brands | C28: 5 | D28: =E28-C28 -> 9 | E28: 14 | F28: 2 | G28: =H28-F28 -> 80 | H28: 82 | I28: 111 | J28: =K28-I28 -> 351 | K28: 462 | L28: 18 | N28: =L28+M28 -> 18
B29: Acquisition of subsidiaries | C29: -364 | D29: =E29-C29 -> -86 | E29: -450 | F29: -110 | G29: =H29-F29 -> -96 | H29: -206 | I29: -129 | J29: =K29-I29 -> -213 | K29: -342 | L29: -3 | N29: =L29+M29 -> -3
B30: Investment in associates and JVs | C30: 0 | D30: =E30-C30 -> -38 | E30: -38 | F30: -24 | G30: =H30-F30 -> -41 | H30: -65 | I30: -38 | J30: =K30-I30 -> -55 | K30: -93 | L30: -51 | N30: =L30+M30 -> -51
B31: Net Cashflow from investing activities | C31: =SUM(C25:C30) -> -604 | D31: =SUM(D25:D30) -> -487 | E31: =SUM(E25:E30) -> -1091 | F31: =SUM(F25:F30) -> -504 | G31: =SUM(G25:G30) -> -837 | H31: =SUM(H25:H30) -> -1341 | I31: =SUM(I25:I30) -> -564 | J31: =SUM(J25:J30) -> -633 | ... AC31: =SUM(AC25:AC30) -> -1579.5676
B33: Cash Flows from financing activities
B34: Share buyback | C34: 0 | D34: =E34-C34 -> -109 | E34: -109 | F34: -538 | G34: =H34-F34 -> -1746 | H34: -2284 | I34: -655 | J34: =K34-I34 -> -726 | K34: -1381 | L34: -480 | N34: =L34+M34 -> -480
B35: Net sale of own shares for share schemes | C35: 9 | D35: =E35-C35 -> 40 | E35: 49 | F35: 42 | G35: =H35-F35 -> -24 | H35: 18 | I35: 12 | J35: =K35-I35 -> 17 | K35: 29 | L35: 5 | N35: =L35+M35 -> 5
B36: Purchase of treasury shares in respect of subsidiaries | C36: 0 | D36: =E36-C36 -> 0 | E36: 0 | F36: -13 | G36: =H36-F36 -> -2 | H36: -15 | J36: =K36-I36 -> 0 | K36: 0 | N36: =L36+M36 -> 0
B37: Dividends paid to non-controlling interests | C37: -53 | D37: =E37-C37 -> -24 | E37: -77 | F37: -51 | G37: =H37-F37 -> -30 | H37: -81 | I37: -94 | J37: =K37-I37 -> -3 | K37: -97 | L37: -71 | N37: =L37+M37 -> -71
B38: Proceeds from bonds | C38: 1031 | D38: =E38-C38 -> 0 | E38: 1031 | F38: 0 | G38: =H38-F38 -> 2263 | H38: 2263 | I38: 1989 | J38: =K38-I38 -> 240 | K38: 2229 | L38: 1690 | N38: =L38+M38 -> 1690
B39: Repayment of bonds | C39: -1247 | D39: =E39-C39 -> 0 | E39: -1247 | F39: -769 | G39: =H39-F39 -> -752 | H39: -1521 | I39: -300 | J39: =K39-I39 -> -1040 | K39: -1340 | L39: -1132 | N39: =L39+M39 -> -1132
B40: Purchase of non-controlling interests | C40: -34 | D40: =E40-C40 -> -8 | E40: -42 | F40: 0 | G40: =H40-F40 -> 0 | H40: 0 | J40: =K40-I40 -> -146 | K40: -146 | M40: 132 | N40: =L40+M40 -> 132
B41: Cash inflow from other borrowings | C41: 0 | D41: =E41-C41 -> 34 | E41: 34 | F41: 136 | G41: =H41-F41 -> 367 | H41: 503 | I41: 173 | J41: =K41-I41 -> 260 | K41: 433 | L41: 470 | M41: ='Balance Sheet'!M37-'Balance Sheet'!L37 -> 500 | N41: =L41+M41 -> 970 | O41: ='Balance Sheet'!O37-'Balance Sheet'!N37 -> 500 | P41: ='Balance Sheet'!P37-'Balance Sheet'!O37 -> 500 | Q41: =O41+P41 -> 1000 | R41: ='Balance Sheet'!R37-'Balance Sheet'!Q37 -> 500 | S41: ='Balance Sheet'!S37-'Balance Sheet'!R37 -> 500 | T41: =R41+S41 -> 1000 | U41: ='Balance Sheet'!U37-'Balance Sheet'!T37 -> 500 | V41: ='Balance Sheet'!V37-'Balance Sheet'!U37 -> 500 | W41: =U41+V41 -> 1000 | X41: ='Balance Sheet'!X37-'Balance Sheet'!W37 -> 500 | Y41: ='Balance Sheet'!Y37-'Balance Sheet'!X37 -> 500 | Z41: =X41+Y41 -> 1000 | AA41: ='Balance Sheet'!AA37-'Balance Sheet'!Z37 -> 500 | AB41: ='Balance Sheet'!AB37-'Balance Sheet'!AA37 -> 500 | AC41: =AA41+AB41 -> 1000
B42: Cash outflow from other borrowings | C42: -345 | D42: =E42-C42 -> -442 | E42: -787 | F42: -98 | G42: =H42-F42 -> -326 | H42: -424 | I42: -206 | J42: =K42-I42 -> -168 | K42: -374 | L42: -801 | N42: =L42+M42 -> -801
B43: Equity Dividend Paid | C43: -992 | D43: =E43-C43 -> -654 | E43: -1646 | F43: -1040 | G43: =H43-F43 -> -678 | H43: -1718 | I43: -1194 | J43: =K43-I43 -> -567 | K43: -1761 | L43: -1348 | N43: =L43+M43 -> -1348
...

Sheet Balance Sheet
C2: ='Income Statement '!C2 -> H1'21 | D2: ='Income Statement '!D2 -> H2'21 | E2: ='Income Statement '!E2 -> FY'21 | F2: ='Income Statement '!F2 -> H1'22 | G2: ='Income Statement '!G2 -> H2'22 | H2: ='Income Statement '!H2 -> FY'22 | I2: ='Income Statement '!I2 -> H1'23 | J2: ='Income Statement '!J2 -> H2'23 | ... AC2: ='Income Statement '!AC2 -> FY'29E
B3: Non-current Assets
B4: Intangible Assets | C4: 10877 | D4: =E4 -> 10764 | E4: 10764 | F4: 10921 | G4: =H4 -> 11902 | H4: 11902 | I4: 14556 | J4: =K4 -> 11512 | K4: 11512 | L4: 14496 | M4: =L4 -> 14496 | N4: =M4 -> 14496 | O4: =N4 -> 14496 | P4: =O4 -> 14496 | Q4: =P4 -> 14496 | R4: =Q4 -> 14496 | S4: =R4 -> 14496 | T4: =S4 -> 14496 | ... AC4: =AB4 -> 14496
B5: PP&E | C5: 4757 | D5: =E5 -> 4849 | E5: 4849 | F5: 5091 | G5: =H5 -> 5848 | H5: 5848 | I5: 7168 | J5: =K5 -> 6142 | K5: 6142 | L5: 8212 | M5: =M65 -> 8195.6814 | N5: =N65 -> 8195.6814 | O5: =O65 -> 8407.7876 | P5: =P65 -> 8430.0216 | Q5: =Q65 -> 8430.0216 | R5: =R65 -> 8683.45 | S5: =S65 -> 8745.7532 | T5: =T65 -> 8745.7532 | ... AC5: =AC65 -> 10209.581
B6: Biological Assets | C6: 63 | D6: =E6 -> 66 | E6: 66 | F6: 75 | G6: =H6 -> 94 | H6: 94 | I6: 143 | J6: =K6 -> 156 | K6: 156 | L6: 194 | M6: =L6 -> 194 | N6: =M6 -> 194 | O6: =N6 -> 194 | P6: =O6 -> 194 | Q6: =P6 -> 194 | R6: =Q6 -> 194 | S6: =R6 -> 194 | T6: =S6 -> 194 | ... AC6: =AB6 -> 194
B7: Investments in associates and JVs | C7: 3578 | D7: =E7 -> 3308 | E7: 3308 | F7: 3473 | G7: =H7 -> 3652 | H7: 3652 | I7: 4710 | J7: =K7 -> 3829 | K7: 3829 | L7: 5229 | M7: =L7 -> 5229 | N7: =M7 -> 5229 | O7: =N7 -> 5229 | P7: =O7 -> 5229 | Q7: =P7 -> 5229 | R7: =Q7 -> 5229 | S7: =R7 -> 5229 | T7: =S7 -> 5229 | ... AC7: =AB7 -> 5229
B8: Other investments | C8: 36 | D8: =E8 -> 40 | E8: 40 | F8: 50 | G8: =H8 -> 37 | H8: 37 | I8: 50 | J8: =K8 -> 57 | K8: 57 | L8: 96 | M8: =L8 -> 96 | N8: =M8 -> 96 | O8: =N8 -> 96 | P8: =O8 -> 96 | Q8: =P8 -> 96 | R8: =Q8 -> 96 | S8: =R8 -> 96 | T8: =S8 -> 96 | ... AC8: =AB8 -> 96
B9: Other receivables | C9: 41 | D9: =E9 -> 36 | E9: 36 | F9: 28 | G9: =H9 -> 37 | H9: 37 | I9: 33 | J9: =K9 -> 31 | K9: 31 | L9: 32 | M9: =L9 -> 32 | N9: =M9 -> 32 | O9: =N9 -> 32 | P9: =O9 -> 32 | Q9: =P9 -> 32 | R9: =Q9 -> 32 | S9: =R9 -> 32 | T9: =S9 -> 32 | ... AC9: =AB9 -> 32
B10: Other financial assets | C10: 410 | D10: =E10 -> 327 | E10: 327 | F10: 319 | G10: =H10 -> 345 | H10: 345 | I10: 479 | J10: =K10 -> 394 | K10: 394 | L10: 430 | M10: =L10 -> 430 | N10: =M10 -> 430 | O10: =N10 -> 430 | P10: =O10 -> 430 | Q10: =P10 -> 430 | R10: =Q10 -> 430 | S10: =R10 -> 430 | T10: =S10 -> 430 | ... AC10: =AB10 -> 430
B11: Deferred tax assets | C11: 114 | D11: =E11 -> 100 | E11: 100 | F11: 83 | G11: =H11 -> 114 | H11: 114 | I11: 127 | J11: =K11 -> 141 | K11: 141 | L11: 171 | M11: =L11 -> 171 | N11: =M11 -> 171 | O11: =N11 -> 171 | P11: =O11 -> 171 | Q11: =P11 -> 171 | R11: =Q11 -> 171 | S11: =R11 -> 171 | T11: =S11 -> 171 | ... AC11: =AB11 -> 171
B12: Post Employment Benefit Assets | C12: 1083 | D12: =E12 -> 1018 | E12: 1018 | F12: 1544 | G12: =H12 -> 1553 | H12: 1553 | I12: 1272 | J12: =K12 -> 960 | K12: 960 | L12: 1118 | M12: =L12 -> 1118 | N12: =M12 -> 1118 | O12: =N12 -> 1118 | P12: =O12 -> 1118 | Q12: =P12 -> 1118 | R12: =Q12 -> 1118 | S12: =R12 -> 1118 | T12: =S12 -> 1118 | ... AC12: =AB12 -> 1118
B13: Total Non-Current Assets | C13: =SUM(C4:C12) -> 20959 | D13: =SUM(D4:D12) -> 20508 | E13: =SUM(E4:E12) -> 20508 | F13: =SUM(F4:F12) -> 21584 | G13: =SUM(G4:G12) -> 23582 | H13: =SUM(H4:H12) -> 23582 | I13: =SUM(I4:I12) -> 28538 | J13: =SUM(J4:J12) -> 23222 | ... AC13: =SUM(AC4:AC12) -> 31975.581
B15: Current Assets
B16: Inventories | C16: 5750 | D16: =E16 -> 6045 | E16: 6045 | F16: 6235 | G16: =H16 -> 7094 | H16: 7094 | I16: 9062 | J16: =K16 -> 7661 | K16: 7661 | L16: 9840 | M16: =M70 -> 10140.008 | N16: =N70 -> 10140.008 | O16: =O70 -> 11399.85 | P16: =P70 -> 9780.0723 | Q16: =Q70 -> 9780.0723 | R16: =R70 -> 12363.702 | S16: =S70 -> 10751.655 | T16: =T70 -> 10751.655 | ... AC16: =AC70 -> 14289.187
B17: Trade and other receivables | C17: 3075 | D17: =E17 -> 2385 | E17: 2385 | F17: 3328 | G17: =H17 -> 2933 | H17: 2933 | I17: 4648 | J17: =K17 -> 2720 | K17: 2720 | L17: 4580 | M17: =M71 -> 3876.458 | N17: =N71 -> 3876.458 | O17: =O71 -> 4950.792 | P17: =P71 -> 4247.3457 | Q17: =Q71 -> 4247.3457 | R17: =R71 -> 5369.3793 | S17: =S71 -> 4669.2901 | T17: =T71 -> 4669.2901 | ... AC17: =AC71 -> 6205.5898
