Workbook

Sheet Profit and Loss Statement 
A1: In millions of € | B1: H1'19 | C1: H2'19 | D1: FY'19 | E1: H1'20 | F1: H2'20 | G1: H1'21 | H1: H2'21 | I1: H1'22 | J1: H2'22 | K1: H1'23 | L1: H2'23 | M1: H1'24 | N1: H2'24 | O1: H1'25 | P1: H2'25 | Q1: H1'26 | R1: H2'26 | S1: H1'27 | T1: H2'27 | U1: H1'28 | V1: H2'28 | W1: H1'29 | X1: H2'29 | Y1: H1'30 | Z1: H2'30 | AE1: FY'20 | AF1: FY'21 | AG1: FY'22 | AH1: FY'23 | AI1: FY'24 | AJ1: FY'25 | AK1: FY'26 | AL1: FY'27 | AM1: FY'28 | AN1: FY'29 | AO1: FY'30
A3: Revenue | B3: 13597 | C3: =D3-B3 -> 14924 | D3: 28521 | E3: 11156 | F3: =AE3-E3 -> 12614 | G3: 11970 | H3: =AF3-G3 -> 14613 | I3: 16401 | J3: =AG3-I3 -> 18275 | K3: 17436 | L3: =AH3-K3 -> 18939 | M3: 17823 | P3: =AK3-O3 -> 0 | R3: =AM3-Q3 -> 0 | T3: =AO3-S3 -> 0 | V3: =AQ3-U3 -> 0 | X3: =AS3-W3 -> 0 | Z3: =AU3-Y3 -> 0 | AE3: 23770 | AF3: 26583 | AG3: 34676 | AH3: 36375 | AI3: 35955
A4: Excise tax expense | B4: -2154 | C4: =D4-B4 -> -2398 | D4: -4552 | E4: -1913 | F4: =AE4-E4 -> -2142 | G4: -1960 | H4: =AF4-G4 -> -2682 | I4: -2916 | J4: =AG4-I4 -> -3041 | K4: -2912 | L4: =AH4-K4 -> -3101 | M4: -2999 | P4: =AK4-O4 -> 0 | R4: =AM4-Q4 -> 0 | T4: =AO4-S4 -> 0 | V4: =AQ4-U4 -> 0 | X4: =AS4-W4 -> 0 | Z4: =AU4-Y4 -> 0 | AE4: -4055 | AF4: -4642 | AG4: -5957 | AH4: -6013 | AI4: -6134
A5: Net Revenue | B5: =B3+B4 -> 11443 | C5: =C3+C4 -> 12526 | D5: =D3+D4 -> 23969 | E5: =E3+E4 -> 9243 | F5: =F3+F4 -> 10472 | G5: =G3+G4 -> 10010 | H5: =H3+H4 -> 11931 | I5: =I3+I4 -> 13485 | ... M5: =M3+M4 -> 14824 | N5: =AI5-M5 -> 14997 | O5: =O42 -> 15432.843 | P5: =AJ5-O5 -> 19885.332 | Q5: =Q42 -> 16386.674 | R5: =AK5-Q5 -> 22330.016 | S5: =S42 -> 17678.547 | T5: =AL5-S5 -> 25098.108 | U5: =U42 -> 19330.782 | V5: =AM5-U5 -> 28255.609 | W5: =W42 -> 21384.123 | X5: =AN5-W5 -> 31881.428 | Y5: =Y42 -> 23897.321 | Z5: =AO5-Y5 -> 36070.143 | AF5: =AF3+AF4 -> 21941 | AG5: =AG3+AG4 -> 28719 | AH5: =AH3+AH4 -> 30362 | AI5: =AI3+AI4 -> 29821 | AJ5: =AJ42 -> 35318.175 | AK5: =AK42 -> 38716.689 | AL5: =AL42 -> 42776.655 | AM5: =AM42 -> 47586.391 | AN5: =AN42 -> 53265.551 | AO5: =AO42 -> 59967.464
K6: =K5/I5-1 -> 0.077048572 | L6: =L5/J5-1 -> 0.039648155 | M6: =M5/K5-1 -> 0.020655467 | N6: =N5/L5-1 -> -0.053100139 | O6: =O5/M5-1 -> 0.041071431 | P6: =P5/N5-1 -> 0.32595402 | Q6: =Q5/O5-1 -> 0.061805247 | R6: =R5/P5-1 -> 0.12293902 | ... Z6: =Z5/X5-1 -> 0.13138418
A7: Other Income | B7: 78 | C7: =D7-B7 -> 17 | D7: 95 | E7: 5 | F7: =AE7-E7 -> 51 | G7: 194 | H7: =AF7-G7 -> 1327 | I7: 31 | J7: =AG7-I7 -> 116 | K7: 145 | L7: =AH7-K7 -> 248 | M7: 26 | N7: =N5*N8 -> 14.997 | O7: =O8*O5 -> 308.65686 | P7: =AJ7-O7 -> -213.90973 | Q7: =Q8*Q5 -> 327.73347 | R7: =AK7-Q7 -> -223.86924 | S7: =S8*S5 -> 353.57094 | T7: =AL7-S7 -> -238.81515 | U7: =U8*U5 -> 386.61564 | V7: =AM7-U7 -> -258.9569 | W7: =W8*W5 -> 427.68246 | X7: =AN7-W7 -> -284.78839 | Y7: =Y8*Y5 -> 477.94641 | Z7: =AO7-Y7 -> -317.0733 | AE7: 56 | AF7: 1521 | AG7: 147 | AH7: 393 | AI7: 80 | AJ7: =AJ5*AJ8 -> 94.747125 | AK7: =AK5*AK8 -> 103.86423 | AL7: =AL5*AL8 -> 114.75579 | AM7: =AM5*AM8 -> 127.65874 | AN7: =AN5*AN8 -> 142.89407 | AO7: =AO5*AO8 -> 160.87311
I8: =I7/I5 -> 0.0022988506 | J8: =J7/J5 -> 0.0076145464 | K8: =K7/K5 -> 0.0099834756 | L8: =L7/L5 -> 0.015658543 | M8: =M7/M5 -> 0.0017539126 | N8: 0.001 | O8: 0.02 | P8: =P7/P5 -> -0.010757162 | Q8: =O8 -> 0.02 | R8: =R7/R5 -> -0.010025485 | S8: =Q8 -> 0.02 | T8: =T7/T5 -> -0.009515265 | U8: =S8 -> 0.02 | V8: =V7/V5 -> -0.009164796 | W8: =U8 -> 0.02 | X8: =X7/X5 -> -0.0089327363 | Y8: =W8 -> 0.02 | Z8: =Z7/Z5 -> -0.008790464 | AF8: =AF7/AF5 -> 0.069322273 | AG8: =AG7/AG5 -> 0.0051185626 | AH8: =AH7/AH5 -> 0.012943811 | AI8: =AI7/AI5 -> 0.0026826733 | AJ8: =AI8 -> 0.0026826733 | AK8: =AJ8 -> 0.0026826733 | AL8: =AK8 -> 0.0026826733 | AM8: =AL8 -> 0.0026826733 | AN8: =AM8 -> 0.0026826733 | AO8: =AN8 -> 0.0026826733
A9: Raw Materials, consumables and services | B9: -7064 | C9: =D9-B9 -> -7528 | D9: -14592 | E9: -5967 | F9: =AE9-E9 -> -6483 | G9: -5972 | H9: =AF9-G9 -> -7563 | I9: -8580 | J9: =AG9-I9 -> -10038 | K9: -9704 | L9: =AH9-K9 -> -10373 | M9: -9674 | N9: =-N10*N5 -> -10047.99 | O9: =-O10*O5 -> -10071.325 | P9: =AJ9-O9 -> -12801.815 | Q9: =-Q10*Q5 -> -10693.786 | R9: =AK9-Q9 -> -14380.337 | S9: =-S10*S5 -> -11536.85 | T9: =AL9-S9 -> -16166.632 | U9: =-U10*U5 -> -12615.083 | V9: =AM9-U9 -> -18203.333 | W9: =-W10*W5 -> -13955.073 | X9: =AN9-W9 -> -20541.342 | Y9: =-Y10*Y5 -> -15595.162 | Z9: =AO9-Y9 -> -23241.619 | AE9: -12450 | AF9: -13535 | AG9: -18618 | AH9: -20077 | AI9: -19313 | AJ9: =-AJ10*AJ5 -> -22873.14 | AK9: =-AK10*AK5 -> -25074.123 | AL9: =-AL10*AL5 -> -27703.482 | AM9: =-AM10*AM5 -> -30818.416 | AN9: =-AN10*AN5 -> -34496.415 | AO9: =-AO10*AO5 -> -38836.78
B10: =-B9/B5 -> 0.61732063 | C10: =-C9/C5 -> 0.60098994 | D10: =-D9/D5 -> 0.60878635 | E10: =-E9/E5 -> 0.64556962 | F10: =-F9/F5 -> 0.61907945 | G10: =-G9/G5 -> 0.5966034 | H10: =-H9/H5 -> 0.6338949 | I10: =-I9/I5 -> 0.63626251 | ... M10: =-M9/M5 -> 0.65259039 | N10: 0.67 | O10: =M10 -> 0.65259039 | P10: =-P9/P5 -> 0.64378181 | Q10: =O10 -> 0.65259039 | R10: =-R9/R5 -> 0.64399136 | S10: =Q10 -> 0.65259039 | T10: =-T9/T5 -> 0.64413748 | U10: =S10 -> 0.65259039 | V10: =-V9/V5 -> 0.64423785 | W10: =U10 -> 0.65259039 | X10: =-X9/X5 -> 0.64430431 | Y10: =W10 -> 0.65259039 | Z10: =-Z9/Z5 -> 0.64434506 | AE10: =-AE9/AE5 -> #DIV/0! | AF10: =-AF9/AF5 -> 0.61688164 | AG10: =-AG9/AG5 -> 0.64828163 | AH10: =-AH9/AH5 -> 0.6612542 | AI10: =-AI9/AI5 -> 0.64763086 | AJ10: =AI10 -> 0.64763086 | AK10: =AJ10 -> 0.64763086 | AL10: =AK10 -> 0.64763086 | AM10: =AL10 -> 0.64763086 | AN10: =AM10 -> 0.64763086 | AO10: =AN10 -> 0.64763086
A11: Personnel Expenses | B11: -1898 | C11: =D11-B11 -> -1982 | D11: -3880 | E11: -1716 | F11: =AE11-E11 -> -1953 | G11: -1645 | H11: =AF11-G11 -> -1840 | I11: -1934 | J11: =AG11-I11 -> -2145 | K11: -2110 | L11: =AH11-K11 -> -2243 | M11: -2267 | N11: =-N12*N5 -> -2399.52 | O11: =-O12*O5 -> -2360.1089 | P11: =AJ11-O11 -> -2929.1493 | Q11: =-Q12*Q5 -> -2505.976 | R11: =AK11-Q11 -> -3292.2445 | S11: =-S12*S5 -> -2703.5393 | T11: =AL11-S11 -> -3702.7027 | U11: =-U12*U5 -> -2956.2117 | V11: =AM11-U11 -> -4170.3375 | W11: =-W12*W5 -> -3270.2244 | X11: =AN11-W11 -> -4706.8371 | Y11: =-Y12*Y5 -> -3654.5619 | Z11: =AO11-Y11 -> -5326.1796 | AE11: -3669 | AF11: -3485 | AG11: -4079 | AH11: -4353 | AI11: -4466 | AJ11: =-AJ12*AJ5 -> -5289.2583 | AK11: =-AK12*AK5 -> -5798.2205 | AL11: =-AL12*AL5 -> -6406.242 | AM11: =-AM12*AM5 -> -7126.5492 | AN11: =-AN12*AN5 -> -7977.0615 | AO11: =-AO12*AO5 -> -8980.7415
B12: =-B11/B5 -> 0.16586559 | C12: =-C11/C5 -> 0.15823088 | D12: =-D11/D5 -> 0.16187576 | E12: =-E11/E5 -> 0.18565401 | F12: =-F11/F5 -> 0.18649733 | G12: =-G11/G5 -> 0.16433566 | H12: =-H11/H5 -> 0.1542201 | I12: =-I11/I5 -> 0.14341861 | ... M12: =-M11/M5 -> 0.15292768 | N12: 0.16 | O12: =M12 -> 0.15292768 | P12: =-P11/P5 -> 0.14730201 | Q12: =O12 -> 0.15292768 | R12: =-R11/R5 -> 0.14743583 | S12: =Q12 -> 0.15292768 | T12: =-T11/T5 -> 0.14752916 | U12: =S12 -> 0.15292768 | V12: =-V11/V5 -> 0.14759326 | W12: =U12 -> 0.15292768 | X12: =-X11/X5 -> 0.1476357 | Y12: =W12 -> 0.15292768 | Z12: =-Z11/Z5 -> 0.14766173 | AE12: =-AE11/AE5 -> #DIV/0! | AF12: =-AF11/AF5 -> 0.15883506 | AG12: =-AG11/AG5 -> 0.14203141 | AH12: =-AH11/AH5 -> 0.14337 | AI12: =-AI11/AI5 -> 0.14976024 | AJ12: =AI12 -> 0.14976024 | AK12: =AJ12 -> 0.14976024 | AL12: =AK12 -> 0.14976024 | AM12: =AL12 -> 0.14976024 | AN12: =AM12 -> 0.14976024 | AO12: =AN12 -> 0.14976024
A13: D&A | B13: -911 | C13: =D13-B13 -> -1048 | D13: -1959 | E13: -1480 | F13: =AE13-E13 -> -1394 | G13: -870 | H13: =AF13-G13 -> -1089 | I13: -932 | J13: =AG13-I13 -> -954 | K13: -1244 | L13: =AH13-K13 -> -1852 | M13: -1367 | N13: =AI13-M13 -> -1238 | O13: =-('Balance Sheet'!O58+'Balance Sheet'!O68) -> -1692.54 | P13: =AJ13-O13 -> -1425.72 | Q13: =-('Balance Sheet'!Q58+'Balance Sheet'!Q68) -> -1766.7082 | R13: =AK13-Q13 -> -1514.0154 | S13: =-('Balance Sheet'!S58+'Balance Sheet'!S68) -> -1848.0132 | T13: =AL13-S13 -> -1610.8072 | U13: =-('Balance Sheet'!U58+'Balance Sheet'!U68) -> -1937.8442 | V13: =AM13-U13 -> -1717.7488 | W13: =-('Balance Sheet'!W58+'Balance Sheet'!W68) -> -2037.7756 | X13: =AN13-W13 -> -1836.7148 | Y13: =-('Balance Sheet'!Y58+'Balance Sheet'!Y68) -> -2149.6333 | Z13: =AO13-Y13 -> -1969.8787 | AE13: -2874 | AF13: -1959 | AG13: -1886 | AH13: -3096 | AI13: -2605 | AJ13: =-'Balance Sheet'!AJ58-'Balance Sheet'!AJ68 -> -3118.26 | AK13: =-'Balance Sheet'!AK58-'Balance Sheet'!AK68 -> -3280.7236 | AL13: =-'Balance Sheet'!AL58-'Balance Sheet'!AL68 -> -3458.8204 | AM13: =-'Balance Sheet'!AM58-'Balance Sheet'!AM68 -> -3655.593 | AN13: =-'Balance Sheet'!AN58-'Balance Sheet'!AN68 -> -3874.4904 | AO13: =-'Balance Sheet'!AO58-'Balance Sheet'!AO68 -> -4119.5119
A14: EBIT | B14: =B5+B7+B9+B11+B13 -> 1648 | C14: =C5+C7+C9+C11+C13 -> 1985 | D14: =D5+D7+D9+D11+D13 -> 3633 | E14: =E5+E7+E9+E11+E13 -> 85 | F14: =F5+F7+F9+F11+F13 -> 693 | G14: =G5+G7+G9+G11+G13 -> 1717 | H14: =H5+H7+H9+H11+H13 -> 2766 | I14: =I5+I7+I9+I11+I13 -> 2070 | ... Z14: =Z5+Z7+Z9+Z11+Z13 -> 5215.3931 | AE14: =AE5+AE7+AE9+AE11+AE13 -> -18937 | AF14: =AF5+AF7+AF9+AF11+AF13 -> 4483 | AG14: =AG5+AG7+AG9+AG11+AG13 -> 4283 | AH14: =AH5+AH7+AH9+AH11+AH13 -> 3229 | AI14: =AI5+AI7+AI9+AI11+AI13 -> 3517 | AJ14: =AJ5+AJ7+AJ9+AJ11+AJ13 -> 4132.2638 | AK14: =AK5+AK7+AK9+AK11+AK13 -> 4667.4864 | AL14: =AL5+AL7+AL9+AL11+AL13 -> 5322.8665 | ... AO14: =AO5+AO7+AO9+AO11+AO13 -> 8191.3031
A15: EBITDA | B15: =B14-B13 -> 2559 | C15: =C14-C13 -> 3033 | D15: =D14-D13 -> 5592 | E15: =E14-E13 -> 1565 | F15: =F14-F13 -> 2087 | G15: =G14-G13 -> 2587 | H15: =H14-H13 -> 3855 | I15: =I14-I13 -> 3002 | ... Z15: =Z14-Z13 -> 7185.2718 | AE15: =AE14-AE13 -> -16063 | AF15: =AF14-AF13 -> 6442 | AG15: =AG14-AG13 -> 6169 | AH15: =AH14-AH13 -> 6325 | AI15: =AI14-AI13 -> 6122 | AJ15: =AJ14-AJ13 -> 7250.5238 | AK15: =AK14-AK13 -> 7948.21 | AL15: =AL14-AL13 -> 8781.6869 | ... AO15: =AO14-AO13 -> 12310.815
A16: Interest Income | B16: 28 | C16: =D16-B16 -> 47 | D16: 75 | E16: 32 | F16: =AE16-E16 -> 18 | G16: 24 | H16: =AF16-G16 -> 25 | I16: 29 | J16: =AG16-I16 -> 45 | K16: 46 | L16: =AH16-K16 -> 44 | M16: 47 | N16: =AI16-M16 -> 63 | P16: =AK16-O16 -> 0 | R16: =AM16-Q16 -> 0 | T16: =AO16-S16 -> 0 | V16: =AQ16-U16 -> 0 | X16: =AS16-W16 -> 0 | Z16: =AU16-Y16 -> 0 | AE16: 50 | AF16: 49 | AG16: 74 | AH16: 90 | AI16: 110
A17: Interest Expenses | B17: -255 | C17: =D17-B17 -> -274 | D17: -529 | E17: -239 | F17: =AE17-E17 -> -258 | G17: -226 | H17: =AF17-G17 -> -236 | I17: -214 | J17: =AG17-I17 -> -244 | K17: -295 | L17: =AH17-K17 -> -345 | M17: -342 | N17: =+'Balance Sheet'!N90 -> -377 | O17: =+'Balance Sheet'!O90 -> -364.5 | P17: =+'Balance Sheet'!P90 -> -374.5 | Q17: =+'Balance Sheet'!Q90 -> -374.5 | R17: =+'Balance Sheet'!R90 -> -384.5 | S17: =+'Balance Sheet'!S90 -> -384.5 | T17: =+'Balance Sheet'!T90 -> -394.5 | U17: =+'Balance Sheet'!U90 -> -394.5 | ... Z17: =+'Balance Sheet'!Z90 -> -424.5 | AE17: -497 | AF17: -462 | AG17: -458 | AH17: -640 | AI17: -680 | AJ17: =+'Balance Sheet'!AJ90 -> -739 | AK17: =+'Balance Sheet'!AK90 -> -759 | AL17: =+'Balance Sheet'!AL90 -> -779 | AM17: =+'Balance Sheet'!AM90 -> -799 | AN17: =+'Balance Sheet'!AN90 -> -819 | AO17: =+'Balance Sheet'!AO90 -> -839
A18: Other net finance income/expenses | B18: -25 | C18: =D18-B18 -> -34 | D18: -59 | E18: -58 | F18: =AE18-E18 -> -85 | G18: 24 | H18: =AF18-G18 -> -10 | I18: 37 | J18: =AG18-I18 -> 11 | K18: -186 | L18: =AH18-K18 -> -189 | M18: -142 | N18: =AI18-M18 -> -93 | P18: =AK18-O18 -> 0 | R18: =AM18-Q18 -> 0 | T18: =AO18-S18 -> 0 | V18: =AQ18-U18 -> 0 | X18: =AS18-W18 -> 0 | Z18: =AU18-Y18 -> 0 | AE18: -143 | AF18: 14 | AG18: 48 | AH18: -375 | AI18: -235
A19: Net finance expense | B19: =SUM(B16:B18) -> -252 | C19: =SUM(C16:C18) -> -261 | D19: =SUM(D16:D18) -> -513 | E19: =SUM(E16:E18) -> -265 | F19: =SUM(F16:F18) -> -325 | G19: =SUM(G16:G18) -> -178 | H19: =SUM(H16:H18) -> -221 | I19: =SUM(I16:I18) -> -148 | ... Z19: =SUM(Z16:Z18) -> -424.5 | AE19: =SUM(AE16:AE18) -> -590 | AF19: =SUM(AF16:AF18) -> -399 | AG19: =SUM(AG16:AG18) -> -336 | AH19: =SUM(AH16:AH18) -> -925 | AI19: =SUM(AI16:AI18) -> -805 | AJ19: =SUM(AJ16:AJ18) -> -739 | AK19: =SUM(AK16:AK18) -> -759 | AL19: =SUM(AL16:AL18) -> -779 | ... AO19: =SUM(AO16:AO18) -> -839
A20: Share of profit/(loss) of associates and joint ventures | B20: 80 | C20: =D20-B20 -> 84 | D20: 164 | E20: -41 | F20: =AE20-E20 -> 10 | G20: 70 | H20: =AF20-G20 -> 180 | I20: 80 | J20: =AG20-I20 -> 143 | K20: 100 | L20: =AH20-K20 -> 118 | M20: -766 | N20: =AI20-M20 -> 61 | P20: =AK20-O20 -> 0 | R20: =AM20-Q20 -> 0 | T20: =AO20-S20 -> 0 | V20: =AQ20-U20 -> 0 | X20: =AS20-W20 -> 0 | Z20: =AU20-Y20 -> 0 | AE20: -31 | AF20: 250 | AG20: 223 | AH20: 218 | AI20: -705
A21: PBT | B21: =B14+B19+B20 -> 1476 | C21: =C14+C19+C20 -> 1808 | D21: =D14+D19+D20 -> 3284 | E21: =E14+E19+E20 -> -221 | F21: =F14+F19+F20 -> 378 | G21: =G14+G19+G20 -> 1609 | H21: =H14+H19+H20 -> 2725 | I21: =I14+I19+I20 -> 2002 | ... Z21: =Z14+Z19+Z20 -> 4790.8931 | AE21: =AE14+AE19+AE20 -> -19558 | AF21: =AF14+AF19+AF20 -> 4334 | AG21: =AG14+AG19+AG20 -> 4170 | AH21: =AH14+AH19+AH20 -> 2522 | AI21: =AI14+AI19+AI20 -> 2007 | AJ21: =AJ14+AJ19+AJ20 -> 3393.2638 | AK21: =AK14+AK19+AK20 -> 3908.4864 | AL21: =AL14+AL19+AL20 -> 4543.8665 | ... AO21: =AO14+AO19+AO20 -> 7352.3031
A22: Tax | B22: -438 | C22: =D22-B22 -> -472 | D22: -910 | E22: -51 | F22: =AE22-E22 -> -194 | G22: -440 | H22: =AF22-G22 -> -359 | I22: -547 | J22: =AG22-I22 -> -584 | K22: -89 | L22: =AH22-K22 -> -32 | M22: -387 | N22: =-N23*N21 -> -137.26818 | O22: =-O21*O23 -> -175.42361 | P22: =AJ22-O22 -> -1254.9208 | Q22: =-Q21*Q23 -> -192.28119 | R22: =AK22-Q22 -> -1455.2422 | S22: =-S21*S23 -> -218.29017 | T22: =AL22-S22 -> -1697.0616 | U22: =-U21*U23 -> -253.92626 | V22: =AM22-U22 -> -1986.2632 | W22: =-W21*W23 -> -300.1925 | X22: =AN22-W22 -> -2330.7446 | Y22: =-Y21*Y23 -> -358.59739 | Z22: =AO22-Y22 -> -2740.5797 | AE22: -245 | AF22: -799 | AG22: -1131 | AH22: -121 | AI22: -846 | AJ22: =-AJ23*AJ21 -> -1430.3444 | AK22: =-AK23*AK21 -> -1647.5234 | AL22: =-AL23*AL21 -> -1915.3518 | AM22: =-AM23*AM21 -> -2240.1895 | AN22: =-AN23*AN21 -> -2630.9371 | AO22: =-AO23*AO21 -> -3099.1771
B23: =-B22/B21 -> 0.29674797 | C23: =-C22/C21 -> 0.26106195 | D23: =-D22/D21 -> 0.2771011 | E23: =-E22/E21 -> -0.23076923 | F23: =-F22/F21 -> 0.51322751 | G23: =-G22/G21 -> 0.27346178 | H23: =-H22/H21 -> 0.13174312 | I23: =-I22/I21 -> 0.27322677 | ... M23: =-M22/M21 -> 1.1415929 | N23: 0.14 | O23: 0.14 | P23: =-P22/P21 -> 0.58634637 | Q23: 0.14 | R23: =-R22/R21 -> 0.57404887 | S23: 0.14 | T23: =-T22/T21 -> 0.56859634 | U23: 0.14 | V23: =-V22/V21 -> 0.56738494 | W23: 0.14 | X23: =-X22/X21 -> 0.56885636 | Y23: 0.14 | Z23: =-Z22/Z21 -> 0.57203941 | AE23: =-AE22/AE21 -> -0.012526843 | AF23: =-AF22/AF21 -> 0.18435625 | AG23: =-AG22/AG21 -> 0.27122302 | AH23: =-AH22/AH21 -> 0.047977795 | AI23: =-AI22/AI21 -> 0.42152466 | AJ23: =AI23 -> 0.42152466 | AK23: =AJ23 -> 0.42152466 | AL23: =AK23 -> 0.42152466 | AM23: =AL23 -> 0.42152466 | AN23: =AM23 -> 0.42152466 | AO23: =AN23 -> 0.42152466
A24: PAT | B24: =B21+B22 -> 1038 | C24: =C21+C22 -> 1336 | D24: =D21+D22 -> 2374 | E24: =E21+E22 -> -272 | F24: =F21+F22 -> 184 | G24: =G21+G22 -> 1169 | H24: =H21+H22 -> 2366 | I24: =I21+I22 -> 1455 | ... Z24: =Z21+Z22 -> 2050.3134 | AE24: =AE21+AE22 -> -19803 | AF24: =AF21+AF22 -> 3535 | AG24: =AG21+AG22 -> 3039 | AH24: =AH21+AH22 -> 2401 | AI24: =AI21+AI22 -> 1161 | AJ24: =AJ21+AJ22 -> 1962.9194 | AK24: =AK21+AK22 -> 2260.963 | AL24: =AL21+AL22 -> 2628.5147 | ... AO24: =AO21+AO22 -> 4253.126
A26: Attributable to:
A27: Shareholders | B27: 471 | C27: =D27-B27 -> 616 | D27: 1087 | E27: -297 | F27: =AE27-E27 -> 93 | G27: 1034 | H27: =AF27-G27 -> 2290 | I27: 1265 | J27: =AG27-I27 -> 1417 | K27: 1156 | L27: =AH27-K27 -> 1148 | M27: -95 | N27: =M27/M24*N24 -> 1668.8706 | O27: =N27/N24*O24 -> 2132.7543 | P27: =AJ27-O27 -> -479.23566 | Q27: =Q30 -> 2337.7043 | R27: =AJ27-Q27 -> -684.18566 | S27: =S30 -> 2653.9148 | T27: =AL27-S27 -> -439.71376 | U27: =U30 -> 3087.169 | V27: =AM27-U27 -> -497.4464 | W27: =W30 -> 3649.6618 | X27: =AN27-W27 -> -608.22395 | Y27: =Y30 -> 4359.7332 | Z27: =AO27-Y27 -> -776.99656 | AE27: -204 | AF27: 3324 | AG27: 2682 | AH27: 2304 | AI27: 978 | AJ27: =AI27/AI24*AJ24 -> 1653.5187 | AK27: =AJ27/AJ24*AK24 -> 1904.5838 | AL27: =AK27/AK24*AL24 -> 2214.201 | AM27: =AL27/AL24*AM24 -> 2589.7226 | AN27: =AM27/AM24*AN24 -> 3041.4379 | AO27: =AN27/AN24*AO24 -> 3582.7366
A28: Minority Interests | B28: =465+102 -> 567 | C28: =D28-B28 -> 720 | D28: =1079+208 -> 1287 | E28: 25 | F28: =AE28-E28 -> 91 | G28: 135 | H28: =AF28-G28 -> 76 | I28: 190 | J28: =AG28-I28 -> 167 | K28: 31 | L28: =AH28-K28 -> 66 | M28: 47 | N28: =M28/M24*N24 -> -825.65176 | O28: =N28/N24*O24 -> -1055.1521 | P28: =AJ28-O28 -> 1364.5529 | Q28: =Q31 -> -1156.5485 | R28: =AK28-Q28 -> 1512.9276 | S28: =S31 -> -1312.9894 | T28: =AL28-S28 -> 1727.3031 | U28: =U31 -> -1527.3362 | V28: =AM28-U28 -> 2011.9162 | W28: =W31 -> -1805.6222 | X28: =AN28-W28 -> 2374.7256 | Y28: =Y31 -> -2156.9206 | Z28: =AO28-Y28 -> 2827.31 | AE28: 116 | AF28: 211 | AG28: 357 | AH28: 97 | AI28: 183 | AJ28: =AI28/AI24*AJ24 -> 309.40073 | AK28: =AJ28/AJ24*AK24 -> 356.37918 | AL28: =AK28/AK24*AL24 -> 414.31369 | AM28: =AL28/AL24*AM24 -> 484.58 | AN28: =AM28/AM24*AN24 -> 569.10341 | AO28: =AN28/AN24*AO24 -> 670.38937
N30: =N27/N24 -> 1.9791667 | Q30: =N$30*Q24 -> 2337.7043 | S30: =$N$30*S24 -> 2653.9148 | U30: =$N$30*U24 -> 3087.169 | W30: =$N$30*W24 -> 3649.6618 | Y30: =$N$30*Y24 -> 4359.7332
N31: =N28/N24 -> -0.97916667 | Q31: =N$31*Q24 -> -1156.5485 | S31: =$N$31*S24 -> -1312.9894 | U31: =$N$31*U24 -> -1527.3362 | W31: =$N$31*W24 -> -1805.6222 | Y31: =$N$31*Y24 -> -2156.9206
A32: EPS
A33: Basic | B33: =B27/B37 -> 1.6352454 | C33: =C27/C37 -> 2.1386649 | D33: =D27/D37 -> 3.7739102 | E33: =E27/E37 -> -0.51604855 | F33: =F27/F37 -> 0.16156335 | G33: =G27/G37 -> 1.7959493 | H33: =H27/H37 -> 3.977488 | I33: =I27/I37 -> 2.1977012 | ... Z33: =Z27/Z37 -> -1.3870258 | AE33: =AE27/AE37 -> -0.35439703 | AF33: =AF27/AF37 -> 5.7734367 | AG33: =AG27/AG37 -> 4.6597812 | AH33: =AH27/AH37 -> 4.0891024 | AI33: =AI27/AI37 -> 1.7458395 | AJ33: =AJ27/AJ37 -> 2.9517159 | AK33: =AK27/AK37 -> 3.3998953 | AL33: =AL27/AL37 -> 3.9525967 | ... AO33: =AO27/AO37 -> 6.3955859
A34: Diluted | B34: =B27/B38 -> 1.6352454 | C34: =C27/C38 -> 2.1386649 | D34: =D27/D38 -> 3.7739102 | E34: =E27/E38 -> -0.51604855 | F34: =F27/F38 -> 0.16156335 | G34: =G27/G38 -> 1.79576 | H34: =H27/H38 -> 3.9759057 | I34: =I27/I38 -> 2.1971904 | ... Z34: =Z27/Z38 -> -1.3859124 | AE34: =AE27/AE38 -> -0.35439703 | AF34: =AF27/AF38 -> 5.77114 | AG34: =AG27/AG38 -> 4.6560389 | AH34: =AH27/AH38 -> 4.085254 | AI34: =AI27/AI38 -> 1.7444379 | AJ34: =AJ27/AJ38 -> 2.9493463 | AK34: =AK27/AK38 -> 3.397166 | AL34: =AL27/AL38 -> 3.9494236 | ... AO34: =AO27/AO38 -> 6.3904517
A36: Shares
A37: WASO - Basic | B37: 288.03017 | C37: =D37 -> 288.03017 | D37: 288.03017 | E37: 575.52725 | F37: =AE37 -> 575.6256 | G37: 575.74008 | H37: =AF37 -> 575.74027 | I37: 575.60145 | J37: =AG37 -> 575.5635 | K37: 566.68019 | L37: =AH37 -> 563.44885 | M37: 560.21409 | N37: =AI37 -> 560.18896 | O37: =N37 -> 560.18896 | P37: =AJ37 -> 560.18896 | Q37: =P37 -> 560.18896 | R37: =AK37 -> 560.18896 | S37: =R37 -> 560.18896 | T37: =AL37 -> 560.18896 | U37: =T37 -> 560.18896 | V37: =AM37 -> 560.18896 | W37: =V37 -> 560.18896 | X37: =AN37 -> 560.18896 | Y37: =X37 -> 560.18896 | Z37: =AO37 -> 560.18896 | AE37: 575.6256 | AF37: 575.74027 | AG37: 575.5635 | AH37: 563.44885 | AI37: 560.18896 | AJ37: =AI37 -> 560.18896 | AK37: =AJ37 -> 560.18896 | AL37: =AK37 -> 560.18896 | AM37: =AL37 -> 560.18896 | AN37: =AM37 -> 560.18896 | AO37: =AN37 -> 560.18896
A38: WASO - Diluted | B38: 288.03017 | C38: =D38 -> 288.03017 | D38: 288.03017 | E38: 575.52725 | F38: =AE38 -> 575.6256 | G38: 575.80076 | H38: =AF38 -> 575.96939 | I38: 575.73527 | J38: =AG38 -> 576.02612 | K38: 566.90014 | L38: =AH38 -> 563.97962 | M38: 560.44677 | N38: =AI38 -> 560.63903 | O38: =N38 -> 560.63903 | P38: =O38 -> 560.63903 | Q38: =P38 -> 560.63903 | R38: =Q38 -> 560.63903 | S38: =R38 -> 560.63903 | T38: =S38 -> 560.63903 | U38: =T38 -> 560.63903 | V38: =U38 -> 560.63903 | ... Z38: =Y38 -> 560.63903 | AE38: 575.6256 | AF38: 575.96939 | AG38: 576.02612 | AH38: 563.97962 | AI38: 560.63903 | AJ38: =AI38 -> 560.63903 | AK38: =AJ38 -> 560.63903 | AL38: =AK38 -> 560.63903 | AM38: =AL38 -> 560.63903 | AN38: =AM38 -> 560.63903 | AO38: =AN38 -> 560.63903
A41: eia | AG41: =AG42-AG5 -> -25 | AH41: =AH42-AH5 -> -54 | AI41: =AI42-AI5 -> 2702.624
A42: Net Revenue (beia) | I42: =Total!I17 -> 13485 | J42: =J5 -> 15234 | K42: =Total!K17 -> 14514 | L42: =L5 -> 15838 | M42: =Total!M17 -> 14815 | N42: =N5 -> 14997 | O42: =Total!O17 -> 15432.843 | P42: =P5 -> 19885.332 | Q42: =Total!Q17 -> 16386.674 | R42: =R5 -> 22330.016 | S42: =Total!S17 -> 17678.547 | T42: =T5 -> 25098.108 | U42: =Total!U17 -> 19330.782 | V42: =V5 -> 28255.609 | W42: =Total!W17 -> 21384.123 | X42: =X5 -> 31881.428 | Y42: =Total!Y17 -> 23897.321 | Z42: =Z5 -> 36070.143 | AG42: =Total!AG17 -> 28694 | AH42: =Total!AH17 -> 30308 | AI42: =Total!AI17 -> 32523.624 | AJ42: =Total!AJ17 -> 35318.175 | AK42: =Total!AK17 -> 38716.689 | AL42: =Total!AL17 -> 42776.655 | AM42: =Total!AM17 -> 47586.391 | AN42: =Total!AN17 -> 53265.551 | AO42: =Total!AO17 -> 59967.464

Sheet Balance Sheet
A1: ='Profit and Loss Statement '!A1 -> In millions of € | B1: ='Profit and Loss Statement '!B1 -> H1'19 | C1: ='Profit and Loss Statement '!C1 -> H2'19 | D1: ='Profit and Loss Statement '!D1 -> FY'19 | E1: ='Profit and Loss Statement '!E1 -> H1'20 | F1: ='Profit and Loss Statement '!F1 -> H2'20 | G1: ='Profit and Loss Statement '!G1 -> H1'21 | H1: ='Profit and Loss Statement '!H1 -> H2'21 | ... Z1: ='Profit and Loss Statement '!Z1 -> H2'30 | AE1: ='Profit and Loss Statement '!AE1 -> FY'20 | AF1: ='Profit and Loss Statement '!AF1 -> FY'21 | AG1: ='Profit and Loss Statement '!AG1 -> FY'22 | AH1: ='Profit and Loss Statement '!AH1 -> FY'23 | AI1: ='Profit and Loss Statement '!AI1 -> FY'24 | AJ1: ='Profit and Loss Statement '!AJ1 -> FY'25 | AK1: ='Profit and Loss Statement '!AK1 -> FY'26 | AL1: ='Profit and Loss Statement '!AL1 -> FY'27 | ... AO1: ='Profit and Loss Statement '!AO1 -> FY'30
A3: Intangible Assets | B3: 17569 | C3: =D3 -> 17769 | D3: 17769 | E3: 16461 | F3: =AE3 -> 15767 | G3: 16112 | H3: =AF3 -> 20762 | I3: 21357 | J3: =AG3 -> 21408 | K3: 22653 | L3: =AH3 -> 21781 | M3: 21771 | N3: =AI3 -> 21701 | O3: =O70 -> 21024.328 | P3: =P70 -> 20946.182 | Q3: =Q70 -> 20268.453 | R3: =R70 -> 20211.221 | S3: =S70 -> 19534.796 | T3: =T70 -> 19501.374 | U3: =U70 -> 18828.638 | V3: =V70 -> 18822.513 | ... Z3: =Z70 -> 17586.019 | AE3: 15767 | AF3: 20762 | AG3: 21408 | AH3: 21781 | AI3: 21701 | AJ3: =AJ70 -> 20946.182 | AK3: =AK70 -> 20211.221 | AL3: =AL70 -> 19501.374 | AM3: =AM70 -> 18822.513 | AN3: =AN70 -> 18181.41 | AO3: =AO70 -> 17586.019 | AU3: =P3-Q3 -> 677.72872
A4: PP&E | B4: 12545 | C4: =D4 -> 13269 | D4: 13269 | E4: 11857 | F4: =AE4 -> 11551 | G4: 11668 | H4: =AF4 -> 12401 | I4: 12697 | J4: =AG4 -> 13623 | K4: 14299 | L4: =AH4 -> 14772 | M4: 14463 | N4: =AI4 -> 14677 | O4: =O60 -> 14741.431 | P4: =P60+P61 -> 14785.831 | Q4: =Q60 -> 14843.918 | R4: =R60+R61 -> 14950.236 | S4: =S60 -> 15016.146 | T4: =T60+T61 -> 15195.628 | U4: =U60 -> 15283.675 | V4: =V60+V61 -> 15549.944 | W4: =W60 -> 15675.535 | X4: =X60+X61 -> 16045.145 | Y4: =Y60 -> 16225.65 | Z4: =Z60+Z61 -> 16718.747 | AE4: 11551 | AF4: 12401 | AG4: 13623 | AH4: 14772 | AI4: 14677 | AJ4: =AJ60 -> 14785.831 | AK4: =AK60+$AI$61 -> 14950.236 | AL4: =AL60+$AI$61 -> 15195.628 | AM4: =AM60+$AI$61 -> 15549.944 | AN4: =AN60+$AI$61 -> 16045.145 | AO4: =AO60+$AI$61 -> 16718.747 | AU4: =P4-Q4 -> -58.087698
A6: Investments in associates and JV | B6: 4884 | C6: =D6 -> 4868 | D6: 4868 | E6: 4705 | F6: =AE6 -> 4437 | G6: 5248 | H6: =AF6 -> 4148 | I6: 4412 | J6: =AG6 -> 4296 | K6: 4242 | L6: =AH6 -> 4130 | M6: 3452 | N6: =AI6 -> 3500 | O6: =N6 -> 3500 | P6: =AJ6 -> 3500 | Q6: =P6 -> 3500 | R6: =AK6 -> 3500 | S6: =R6 -> 3500 | T6: =AL6 -> 3500 | U6: =T6 -> 3500 | V6: =AM6 -> 3500 | W6: =V6 -> 3500 | X6: =AN6 -> 3500 | Y6: =X6 -> 3500 | Z6: =AO6 -> 3500 | AE6: 4437 | AF6: 4148 | AG6: 4296 | AH6: 4130 | AI6: 3500 | AJ6: =AI6 -> 3500 | AK6: =AJ6 -> 3500 | AL6: =AK6 -> 3500 | AM6: =AL6 -> 3500 | AN6: =AM6 -> 3500 | AO6: =AN6 -> 3500 | AU6: =P6-Q6 -> 0
A7: Loans and advances to customers | B7: 348 | C7: =D7 -> 277 | D7: 277 | E7: 183 | F7: =AE7 -> 194 | G7: 195 | H7: =AF7 -> 209 | I7: 200 | J7: =AG7 -> 216 | K7: 251 | L7: =AH7 -> 239 | M7: 270 | N7: =AI7 -> 258 | O7: =N7 -> 258 | P7: =AJ7 -> 258 | Q7: =P7 -> 258 | R7: =AK7 -> 258 | S7: =R7 -> 258 | T7: =AL7 -> 258 | U7: =T7 -> 258 | V7: =AM7 -> 258 | W7: =V7 -> 258 | X7: =AN7 -> 258 | Y7: =X7 -> 258 | Z7: =AO7 -> 258 | AE7: 194 | AF7: 209 | AG7: 216 | AH7: 239 | AI7: 258 | AJ7: =AI7 -> 258 | AK7: =AJ7 -> 258 | AL7: =AK7 -> 258 | AM7: =AL7 -> 258 | AN7: =AM7 -> 258 | AO7: =AN7 -> 258 | AU7: =P7-Q7 -> 0
A8: Deferred tax assets | B8: 662 | C8: =D8 -> 647 | D8: 647 | E8: 701 | F8: =AE8 -> 779 | G8: 740 | H8: =AF8 -> 682 | I8: 642 | J8: =AG8 -> 618 | K8: 871 | L8: =AH8 -> 1292 | M8: 1215 | N8: =AI8 -> 1264 | O8: =N8 -> 1264 | P8: =AJ8 -> 1264 | Q8: =P8 -> 1264 | R8: =AK8 -> 1264 | S8: =R8 -> 1264 | T8: =AL8 -> 1264 | U8: =T8 -> 1264 | V8: =AM8 -> 1264 | W8: =V8 -> 1264 | X8: =AN8 -> 1264 | Y8: =X8 -> 1264 | Z8: =AO8 -> 1264 | AE8: 779 | AF8: 682 | AG8: 618 | AH8: 1292 | AI8: 1264 | AJ8: =AI8 -> 1264 | AK8: =AJ8 -> 1264 | AL8: =AK8 -> 1264 | AM8: =AL8 -> 1264 | AN8: =AM8 -> 1264 | AO8: =AN8 -> 1264 | AU8: =P8-Q8 -> 0
A9: Equity instruments | J9: =AG9 -> 145 | K9: 598 | L9: =AH9 -> 562 | M9: 535 | N9: =AI9 -> 465 | O9: =N9 -> 465 | P9: =AJ9 -> 465 | Q9: =P9 -> 465 | R9: =AK9 -> 465 | S9: =R9 -> 465 | T9: =AL9 -> 465 | U9: =T9 -> 465 | V9: =AM9 -> 465 | W9: =V9 -> 465 | X9: =AN9 -> 465 | Y9: =X9 -> 465 | Z9: =AO9 -> 465 | AG9: 145 | AH9: 562 | AI9: 465 | AJ9: =AI9 -> 465 | AK9: =AJ9 -> 465 | AL9: =AK9 -> 465 | AM9: =AL9 -> 465 | AN9: =AM9 -> 465 | AO9: =AN9 -> 465 | AU9: =P9-Q9 -> 0
A10: Other non-current assets | B10: 1401 | C10: =D10 -> 1255 | D10: 1255 | E10: 1115 | F10: =AE10 -> 884 | G10: 1112 | H10: =AF10 -> 1070 | I10: 1276 | J10: =AG10 -> 1085 | K10: 1155 | L10: =AH10 -> 978 | M10: 988 | N10: =AI10 -> 1009 | O10: =N10 -> 1009 | P10: =AJ10 -> 1009 | Q10: =P10 -> 1009 | R10: =AK10 -> 1009 | S10: =R10 -> 1009 | T10: =AL10 -> 1009 | U10: =T10 -> 1009 | V10: =AM10 -> 1009 | W10: =V10 -> 1009 | X10: =AN10 -> 1009 | Y10: =X10 -> 1009 | Z10: =AO10 -> 1009 | AE10: 884 | AF10: 1070 | AG10: 1085 | AH10: 978 | AI10: 1009 | AJ10: =AI10 -> 1009 | AK10: =AJ10 -> 1009 | AL10: =AK10 -> 1009 | AM10: =AL10 -> 1009 | AN10: =AM10 -> 1009 | AO10: =AN10 -> 1009 | AU10: =P10-Q10 -> 0
A11: Total non-current assets | B11: =SUM(B3:B4)+SUM(B6:B10) -> 37409 | C11: =SUM(C3:C4)+SUM(C6:C10) -> 38085 | D11: =SUM(D3:D4)+SUM(D6:D10) -> 38085 | E11: =SUM(E3:E4)+SUM(E6:E10) -> 35022 | F11: =SUM(F3:F4)+SUM(F6:F10) -> 33612 | G11: =SUM(G3:G4)+SUM(G6:G10) -> 35075 | H11: =SUM(H3:H4)+SUM(H6:H10) -> 39272 | I11: =SUM(I3:I4)+SUM(I6:I10) -> 40584 | ... Z11: =SUM(Z3:Z4)+SUM(Z6:Z10) -> 40800.766 | AE11: =SUM(AE3:AE4)+SUM(AE6:AE10) -> 33612 | AF11: =SUM(AF3:AF4)+SUM(AF6:AF10) -> 39272 | AG11: =SUM(AG3:AG4)+SUM(AG6:AG10) -> 41391 | AH11: =SUM(AH3:AH4)+SUM(AH6:AH10) -> 43754 | AI11: =SUM(AI3:AI4)+SUM(AI6:AI10) -> 42874 | AJ11: =SUM(AJ3:AJ4)+SUM(AJ6:AJ10) -> 42228.012 | AK11: =SUM(AK3:AK4)+SUM(AK6:AK10) -> 41657.457 | AL11: =SUM(AL3:AL4)+SUM(AL6:AL10) -> 41193.002 | ... AO11: =SUM(AO3:AO4)+SUM(AO6:AO10) -> 40800.766
A13: Inventories | B13: 2275 | C13: =D13 -> 2213 | D13: 2213 | E13: 2163 | F13: =AE13 -> 1958 | G13: 2345 | H13: =AF13 -> 2438 | I13: 3143 | J13: =AG13 -> 3250 | K13: 4370 | L13: =AH13 -> 3721 | M13: 3859 | N13: =AI13 -> 3572 | O13: =O99 -> 3760.9109 | P13: =AJ13 -> 4328.4016 | Q13: =Q99 -> 3566.8554 | R13: =AK13 -> 4744.9048 | S13: =S99 -> 3756.5143 | T13: =AL13 -> 5242.472 | U13: =U99 -> 4037.7976 | V13: =AM13 -> 5815.9926 | W13: =W99 -> 4413.6596 | X13: =AN13 -> 6527.9335 | Y13: =Y99 -> 4893.1346 | Z13: =AO13 -> 7349.2831 | AE13: 1958 | AF13: 2438 | AG13: 3250 | AH13: 3721 | AI13: 3572 | AJ13: =AJ99 -> 4328.4016 | AK13: =AK99 -> 4744.9048 | AL13: =AL99 -> 5242.472 | AM13: =AM99 -> 5815.9926 | AN13: =AN99 -> 6527.9335 | AO13: =AO99 -> 7349.2831 | AU13: =P13-Q13 -> 761.54626
A14: Trade and other receivables | B14: 4595 | C14: =D14 -> 4123 | D14: 4123 | E14: 3983 | F14: =AE14 -> 2807 | G14: 3911 | H14: =AF14 -> 3662 | I14: 4966 | J14: =AG14 -> 4531 | K14: 5715 | L14: =AH14 -> 5019 | M14: 5385 | N14: =AI14 -> 4588 | O14: =O100 -> 5072.833 | P14: =AJ14 -> 5838.2821 | Q14: =Q100 -> 4811.0849 | R14: =AK14 -> 6400.0746 | S14: =S100 -> 5066.9028 | T14: =AL14 -> 7071.2085 | U14: =U100 -> 5446.3065 | V14: =AM14 -> 7844.7908 | W14: =W100 -> 5953.2806 | X14: =AN14 -> 8805.0788 | Y14: =Y100 -> 6600.0114 | Z14: =AO14 -> 9912.9406 | AE14: 2807 | AF14: 3662 | AG14: 4531 | AH14: 5019 | AI14: 4588 | AJ14: =AJ100 -> 5838.2821 | AK14: =AK100 -> 6400.0746 | AL14: =AL100 -> 7071.2085 | AM14: =AM100 -> 7844.7908 | AN14: =AN100 -> 8805.0788 | AO14: =AO100 -> 9912.9406 | AU14: =P14-Q14 -> 1027.1972
A15: Current tax assets | B15: 65 | C15: =D15 -> 123 | D15: 123 | E15: 204 | F15: =AE15 -> 154 | G15: 105 | H15: =AF15 -> 97 | I15: 107 | J15: =AG15 -> 84 | K15: 180 | L15: =AH15 -> 196 | M15: 166 | N15: =AI15 -> 165 | O15: =N15 -> 165 | P15: =AJ15 -> 165 | Q15: =P15 -> 165 | R15: =AK15 -> 165 | S15: =R15 -> 165 | T15: =AL15 -> 165 | U15: =T15 -> 165 | V15: =AM15 -> 165 | W15: =V15 -> 165 | X15: =AN15 -> 165 | Y15: =X15 -> 165 | Z15: =AO15 -> 165 | AE15: 154 | AF15: 97 | AG15: 84 | AH15: 196 | AI15: 165 | AJ15: =AI15 -> 165 | AK15: =AJ15 -> 165 | AL15: =AK15 -> 165 | AM15: =AL15 -> 165 | AN15: =AM15 -> 165 | AO15: =AN15 -> 165 | AU15: =P15-Q15 -> 0
A16: Derivative assets | B16: 24 | C16: =D16 -> 28 | D16: 28 | E16: 97 | F16: =AE16 -> 77 | G16: 74 | H16: =AF16 -> 96 | I16: 68 | J16: =AG16 -> 70 | K16: 37 | L16: =AH16 -> 58 | M16: 143 | N16: =AI16 -> 169 | O16: =N16 -> 169 | P16: =AJ16 -> 169 | Q16: =P16 -> 169 | R16: =AK16 -> 169 | S16: =R16 -> 169 | T16: =AL16 -> 169 | U16: =T16 -> 169 | V16: =AM16 -> 169 | W16: =V16 -> 169 | X16: =AN16 -> 169 | Y16: =X16 -> 169 | Z16: =AO16 -> 169 | AE16: 77 | AF16: 96 | AG16: 70 | AH16: 58 | AI16: 169 | AJ16: =AI16 -> 169 | AK16: =AJ16 -> 169 | AL16: =AK16 -> 169 | AM16: =AL16 -> 169 | AN16: =AM16 -> 169 | AO16: =AN16 -> 169 | AU16: =P16-Q16 -> 0
A17: Cash and Cash Equivalents | B17: 1751 | C17: =D17 -> 1821 | D17: 1821 | E17: 4266 | F17: =AE17 -> 4000 | G17: 1967 | H17: =AF17 -> 3248 | I17: 2889 | J17: =AG17 -> 2765 | K17: 2168 | L17: =AH17 -> 2377 | M17: 2277 | N17: =AI17 -> 2350 | O17: ='Cash Flow Statement'!O50+N17-'Cash Flow Statement'!N50 -> 4163.2655 | P17: =AJ17 -> 5437.8665 | Q17: ='Cash Flow Statement'!Q50+P17-'Cash Flow Statement'!P50 -> 7347.0375 | R17: =AK17 -> 8846.8426 | S17: ='Cash Flow Statement'!S50+R17-'Cash Flow Statement'!R50 -> 10864.47 | T17: =AL17 -> 12532.345 | U17: ='Cash Flow Statement'!U50+T17-'Cash Flow Statement'!T50 -> 14702.832 | V17: =AM17 -> 16537.852 | W17: ='Cash Flow Statement'!W50+V17-'Cash Flow Statement'!V50 -> 18911.985 | X17: =AN17 -> 20926.696 | Y17: ='Cash Flow Statement'!Y50+X17-'Cash Flow Statement'!X50 -> 23552.303 | Z17: =AO17 -> 25754.359 | AE17: 4000 | AF17: 3248 | AG17: 2765 | AH17: 2377 | AI17: 2350 | AJ17: ='Cash Flow Statement'!AJ50 -> 5437.8665 | AK17: ='Cash Flow Statement'!AK50 -> 8846.8426 | AL17: ='Cash Flow Statement'!AL50 -> 12532.345 | AM17: ='Cash Flow Statement'!AM50 -> 16537.852 | AN17: ='Cash Flow Statement'!AN50 -> 20926.696 | AO17: ='Cash Flow Statement'!AO50 -> 25754.359 | AU17: =P17-Q17 -> -1909.171
A18: Assets classified as held for sale | B18: 108 | C18: =D18 -> 111 | D18: 111 | E18: 61 | F18: =AE18 -> 24 | G18: 17 | H18: =AF18 -> 37 | I18: 550 | J18: =AG18 -> 315 | K18: 374 | L18: =AH18 -> 28 | M18: 40 | N18: =AI18 -> 55 | O18: =N18 -> 55 | P18: =AJ18 -> 55 | Q18: =P18 -> 55 | R18: =AK18 -> 55 | S18: =R18 -> 55 | T18: =AL18 -> 55 | U18: =T18 -> 55 | V18: =AM18 -> 55 | W18: =V18 -> 55 | X18: =AN18 -> 55 | Y18: =X18 -> 55 | Z18: =AO18 -> 55 | AE18: 24 | AF18: 37 | AG18: 315 | AH18: 28 | AI18: 55 | AJ18: =AI18 -> 55 | AK18: =AJ18 -> 55 | AL18: =AK18 -> 55 | AM18: =AL18 -> 55 | AN18: =AM18 -> 55 | AO18: =AN18 -> 55 | AU18: =P18-Q18 -> 0
A19: Other current assets | B19: 0 | C19: =D19 -> 0 | D19: 0 | E19: 0 | F19: =AE19 -> 0 | G19: 0 | H19: =AF19 -> 0 | I19: 42 | J19: =AG19 -> 0 | K19: 0 | L19: =AH19 -> 0 | M19: 0 | N19: =AI19 -> 0 | O19: =N19 -> 0 | P19: =AJ19 -> 0 | Q19: =P19 -> 0 | R19: =AK19 -> 0 | S19: =R19 -> 0 | T19: =AL19 -> 0 | U19: =T19 -> 0 | V19: =AM19 -> 0 | W19: =V19 -> 0 | X19: =AN19 -> 0 | Y19: =X19 -> 0 | Z19: =AO19 -> 0 | AE19: 0 | AF19: 0 | AG19: 0 | AH19: 0 | AI19: =AH19 -> 0 | AJ19: =AI19 -> 0 | AK19: =AJ19 -> 0 | AL19: =AK19 -> 0 | AM19: =AL19 -> 0 | AN19: =AM19 -> 0 | AO19: =AN19 -> 0 | AU19: =P19-Q19 -> 0
A20: Total Current Assets | B20: =SUM(B13:B19) -> 8818 | C20: =SUM(C13:C19) -> 8419 | D20: =SUM(D13:D19) -> 8419 | E20: =SUM(E13:E18) -> 10774 | F20: =SUM(F13:F18) -> 9020 | G20: =SUM(G13:G19) -> 8419 | H20: =SUM(H13:H19) -> 9578 | I20: =SUM(I13:I19) -> 11765 | J20: =SUM(J13:J19) -> 11015 | K20: =SUM(K13:K19) -> 12844 | L20: =SUM(L13:L19) -> 11399 | M20: =SUM(M13:M19) -> 11870 | N20: =SUM(N13:N19) -> 10899 | O20: =SUM(O13:O18) -> 13386.009 | P20: =SUM(P13:P19) -> 15993.55 | Q20: =SUM(Q13:Q18) -> 16113.978 | R20: =SUM(R13:R19) -> 20380.822 | S20: =SUM(S13:S18) -> 20076.888 | T20: =SUM(T13:T19) -> 25235.026 | U20: =SUM(U13:U18) -> 24575.936 | V20: =SUM(V13:V19) -> 30587.635 | W20: =SUM(W13:W18) -> 29667.925 | X20: =SUM(X13:X19) -> 36648.708 | Y20: =SUM(Y13:Y18) -> 35434.449 | Z20: =SUM(Z13:Z19) -> 43405.582 | AE20: =SUM(AE13:AE18) -> 9020 | AF20: =SUM(AF13:AF19) -> 9578 | AG20: =SUM(AG13:AG19) -> 11015 | AH20: =SUM(AH13:AH19) -> 11399 | AI20: =SUM(AI13:AI19) -> 10899 | AJ20: =SUM(AJ13:AJ18) -> 15993.55 | AK20: =SUM(AK13:AK18) -> 20380.822 | AL20: =SUM(AL13:AL18) -> 25235.026 | AM20: =SUM(AM13:AM18) -> 30587.635 | AN20: =SUM(AN13:AN18) -> 36648.708 | AO20: =SUM(AO13:AO18) -> 43405.582
A22: Total Assets | B22: =B11+B20 -> 46227 | C22: =C11+C20 -> 46504 | D22: =D11+D20 -> 46504 | E22: =E11+E20 -> 45796 | F22: =F11+F20 -> 42632 | G22: =G11+G20 -> 43494 | H22: =H11+H20 -> 48850 | I22: =I11+I20 -> 52349 | ... Z22: =Z11+Z20 -> 84206.348 | AE22: =AE11+AE20 -> 42632 | AF22: =AF11+AF20 -> 48850 | AG22: =AG11+AG20 -> 52406 | AH22: =AH11+AH20 -> 55153 | AI22: =AI11+AI20 -> 53773 | AJ22: =AJ11+AJ20 -> 58221.563 | AK22: =AK11+AK20 -> 62038.279 | AL22: =AL11+AL20 -> 66428.028 | ... AO22: =AO11+AO20 -> 84206.348
A24: Share Capital | B24: 461 | C24: =D24 -> 461 | D24: 461 | E24: 922 | F24: =AE24 -> 922 | G24: 922 | H24: =AF24 -> 922 | I24: 922 | J24: =AG24 -> 922 | K24: 922 | L24: =AH24 -> 922 | M24: 922 | N24: =AI24 -> 922 | O24: =N24 -> 922 | P24: =AJ24 -> 922 | Q24: =P24 -> 922 | R24: =AK24 -> 922 | S24: =R24 -> 922 | T24: =AL24 -> 922 | U24: =T24 -> 922 | V24: =AM24 -> 922 | W24: =V24 -> 922 | X24: =AN24 -> 922 | Y24: =X24 -> 922 | Z24: =AO24 -> 922 | AE24: 922 | AF24: 922 | AG24: 922 | AH24: 922 | AI24: 922 | AJ24: =AI24 -> 922 | AK24: =AJ24 -> 922 | AL24: =AK24 -> 922 | AM24: =AL24 -> 922 | AN24: =AM24 -> 922 | AO24: =AN24 -> 922 | AU24: =Q24-P24 -> 0
A25: Share Premium | B25: 1257 | C25: =D25 -> 1257 | D25: 1257 | E25: 2701 | F25: =AE25 -> 2701 | G25: 2701 | H25: =AF25 -> 2701 | I25: 2701 | J25: =AG25 -> 2701 | K25: 2701 | L25: =AH25 -> 2701 | M25: 2701 | N25: =AI25 -> 2701 | O25: =N25 -> 2701 | P25: =AJ25 -> 2701 | Q25: =P25 -> 2701 | R25: =AK25 -> 2701 | S25: =R25 -> 2701 | T25: =AL25 -> 2701 | U25: =T25 -> 2701 | V25: =AM25 -> 2701 | W25: =V25 -> 2701 | X25: =AN25 -> 2701 | Y25: =X25 -> 2701 | Z25: =AO25 -> 2701 | AE25: 2701 | AF25: 2701 | AG25: 2701 | AH25: 2701 | AI25: =AH25 -> 2701 | AJ25: =AI25 -> 2701 | AK25: =AJ25 -> 2701 | AL25: =AK25 -> 2701 | AM25: =AL25 -> 2701 | AN25: =AM25 -> 2701 | AO25: =AN25 -> 2701 | AU25: =Q25-P25 -> 0
A26: Reserves | B26: =-1591-13+2+185+534 -> -883 | C26: =D26 -> -799 | D26: =-1511-8+2+158+560 -> -799 | E26: =-4527+33+1+171+1109-25 -> -3238 | F26: =AE26 -> -3714 | G26: =-4541+27-5+57+1180-23 -> -3305 | H26: =AF26 -> -2808 | I26: =-2935-79-9+56+1094-40 -> -1913 | J26: =AG26 -> -2423 | K26: =-3504-174-6+104+1339-966 -> -3207 | L26: =AH26 -> -2641 | M26: =-3798+99-7+61+1890-966 -> -2721 | N26: =AI26 -> -3248 | O26: =N26 -> -3248 | P26: =AJ26 -> -3248 | Q26: =P26 -> -3248 | R26: =AK26 -> -3248 | S26: =R26 -> -3248 | T26: =AL26 -> -3248 | U26: =T26 -> -3248 | V26: =AM26 -> -3248 | W26: =V26 -> -3248 | X26: =AN26 -> -3248 | Y26: =X26 -> -3248 | Z26: =AO26 -> -3248 | AE26: =-4940+28-2+54+1171-25 -> -3714 | AF26: =-4003+56-8+56+1128-37 -> -2808 | AG26: =-3619-47-9+70+1242-60 -> -2423 | AH26: =-3705-14-7+71+1980-966 -> -2641 | AI26: =-4297+100-8-32+1978-989 -> -3248 | AJ26: =AI26 -> -3248 | AK26: =AJ26 -> -3248 | AL26: =AK26 -> -3248 | AM26: =AL26 -> -3248 | AN26: =AM26 -> -3248 | AO26: =AN26 -> -3248 | AU26: =Q26-P26 -> 0
A27: Retained Earnings | B27: 6689 | C27: =D27 -> 7074 | D27: 7074 | E27: 13208 | F27: =AE27 -> 13483 | G27: 14219 | H27: =AF27 -> 16541 | I27: 17434 | J27: =AG27 -> 18351 | K27: 18898 | L27: =AH27 -> 19074 | M27: 18506 | N27: =AI27 -> 19206 | O27: =N27+'Profit and Loss Statement '!O27 -> 21338.754 | P27: =AJ27 -> 20859.519 | Q27: =P27+'Profit and Loss Statement '!Q27 -> 23197.223 | R27: =AK27 -> 22764.102 | S27: =R27+'Profit and Loss Statement '!S27 -> 25418.017 | T27: =AL27 -> 24978.304 | U27: =T27+'Profit and Loss Statement '!U27 -> 28065.473 | V27: =AM27 -> 27568.026 | W27: =V27+'Profit and Loss Statement '!W27 -> 31217.688 | X27: =AN27 -> 30609.464 | Y27: =X27+'Profit and Loss Statement '!Y27 -> 34969.197 | Z27: =AO27 -> 34192.201 | AE27: 13483 | AF27: 16541 | AG27: 18351 | AH27: 19074 | AI27: 19206 | AJ27: =AI27+'Profit and Loss Statement '!AJ27 -> 20859.519 | AK27: =AJ27+'Profit and Loss Statement '!AK27 -> 22764.102 | AL27: =AK27+'Profit and Loss Statement '!AL27 -> 24978.304 | AM27: =AL27+'Profit and Loss Statement '!AM27 -> 27568.026 | AN27: =AM27+'Profit and Loss Statement '!AN27 -> 30609.464 | AO27: =AN27+'Profit and Loss Statement '!AO27 -> 34192.201 | AU27: =Q27-P27 -> 2337.7043
A28: Minority Interests | B28: =7690+1069 -> 8759 | C28: =D28 -> 9318 | D28: =8154+1164 -> 9318 | E28: 967 | F28: =AE28 -> 1000 | G28: 970 | H28: =AF28 -> 2344 | I28: 2412 | J28: =AG28 -> 2369 | K28: 2749 | L28: =AH28 -> 2733 | M28: 2674 | N28: =AI28 -> 2821 | O28: =N28+'Profit and Loss Statement '!O28 -> 1765.8479 | P28: =AJ28 -> 3130.4007 | Q28: =P28+'Profit and Loss Statement '!Q28 -> 1973.8523 | R28: =AK28 -> 3486.7799 | S28: =R28+'Profit and Loss Statement '!S28 -> 2173.7905 | T28: =AL28 -> 3901.0936 | U28: =T28+'Profit and Loss Statement '!U28 -> 2373.7574 | V28: =AM28 -> 4385.6736 | W28: =V28+'Profit and Loss Statement '!W28 -> 2580.0514 | X28: =AN28 -> 4954.777 | Y28: =X28+'Profit and Loss Statement '!Y28 -> 2797.8564 | Z28: =AO28 -> 5625.1664 | AE28: 1000 | AF28: 2344 | AG28: 2369 | AH28: 2733 | AI28: 2821 | AJ28: =AI28+'Profit and Loss Statement '!AJ28 -> 3130.4007 | AK28: =AJ28+'Profit and Loss Statement '!AK28 -> 3486.7799 | AL28: =AK28+'Profit and Loss Statement '!AL28 -> 3901.0936 | AM28: =AL28+'Profit and Loss Statement '!AM28 -> 4385.6736 | AN28: =AM28+'Profit and Loss Statement '!AN28 -> 4954.777 | AO28: =AN28+'Profit and Loss Statement '!AO28 -> 5625.1664 | AU28: =Q28-P28 -> -1156.5485
A29: Total Equity | B29: =SUM(B24:B28) -> 16283 | C29: =SUM(C24:C28) -> 17311 | D29: =SUM(D24:D28) -> 17311 | E29: =SUM(E24:E28) -> 14560 | F29: =SUM(F24:F28) -> 14392 | G29: =SUM(G24:G28) -> 15507 | H29: =SUM(H24:H28) -> 19700 | I29: =SUM(I24:I28) -> 21556 | ... Z29: =SUM(Z24:Z28) -> 40192.367 | AE29: =SUM(AE24:AE28) -> 14392 | AF29: =SUM(AF24:AF28) -> 19700 | AG29: =SUM(AG24:AG28) -> 21920 | AH29: =SUM(AH24:AH28) -> 22789 | AI29: =SUM(AI24:AI28) -> 22402 | AJ29: =SUM(AJ24:AJ28) -> 24364.919 | AK29: =SUM(AK24:AK28) -> 26625.882 | AL29: =SUM(AL24:AL28) -> 29254.397 | ... AO29: =SUM(AO24:AO28) -> 40192.367
A31: Borrowings | B31: 14112 | C31: =D31 -> 13366 | D31: 13366 | E31: 15564 | F31: =AE31 -> 14616 | G31: 13831 | H31: =AF31 -> 13640 | I31: 13026 | J31: =AG31 -> 12893 | K31: 14441 | L31: =AH31 -> 14046 | M31: 13792 | N31: =AI31 -> 13783 | O31: =O82 -> 14033 | P31: =AJ31 -> 14283 | Q31: =Q82 -> 14533 | R31: =AK31 -> 14783 | S31: =S82 -> 15033 | T31: =AL31 -> 15283 | U31: =U82 -> 15533 | V31: =AM31 -> 15783 | W31: =W82 -> 16033 | X31: =AN31 -> 16283 | Y31: =Y82 -> 16533 | Z31: =AO31 -> 16783 | AE31: 14616 | AF31: 13640 | AG31: 12893 | AH31: 14046 | AI31: 13783 | AJ31: =AJ82 -> 14283 | AK31: =AK82 -> 14783 | AL31: =AL82 -> 15283 | AM31: =AM82 -> 15783 | AN31: =AN82 -> 16283 | AO31: =AO82 -> 16783 | AU31: =Q31-P31 -> 250
A32: Post-retirement obligations | B32: 1101 | C32: =D32 -> 1189 | D32: 1189 | E32: 1206 | F32: =AE32 -> 938 | G32: 832 | H32: =AF32 -> 668 | I32: 555 | J32: =AG32 -> 568 | K32: 533 | L32: =AH32 -> 586 | M32: 628 | N32: =AI32 -> 519 | O32: =N32 -> 519 | P32: =AJ32 -> 519 | Q32: =P32 -> 519 | R32: =AK32 -> 519 | S32: =R32 -> 519 | T32: =AL32 -> 519 | U32: =T32 -> 519 | V32: =AM32 -> 519 | W32: =V32 -> 519 | X32: =AN32 -> 519 | Y32: =X32 -> 519 | Z32: =AO32 -> 519 | AE32: 938 | AF32: 668 | AG32: 568 | AH32: 586 | AI32: 519 | AJ32: =AI32 -> 519 | AK32: =AJ32 -> 519 | AL32: =AK32 -> 519 | AM32: =AL32 -> 519 | AN32: =AM32 -> 519 | AO32: =AN32 -> 519 | AU32: =Q32-P32 -> 0
A33: Provisions | B33: 769 | C33: =D33 -> 756 | D33: 756 | E33: 602 | F33: =AE33 -> 688 | G33: 676 | H33: =AF33 -> 636 | I33: 636 | J33: =AG33 -> 572 | K33: 651 | L33: =AH33 -> 627 | M33: 586 | N33: =AI33 -> 586 | O33: =N33 -> 586 | P33: =AJ33 -> 586 | Q33: =P33 -> 586 | R33: =AK33 -> 586 | S33: =R33 -> 586 | T33: =AL33 -> 586 | U33: =T33 -> 586 | V33: =AM33 -> 586 | W33: =V33 -> 586 | X33: =AN33 -> 586 | Y33: =X33 -> 586 | Z33: =AO33 -> 586 | AE33: 688 | AF33: 636 | AG33: 572 | AH33: 627 | AI33: 586 | AJ33: =AI33 -> 586 | AK33: =AJ33 -> 586 | AL33: =AK33 -> 586 | AM33: =AL33 -> 586 | AN33: =AM33 -> 586 | AO33: =AN33 -> 586 | AU33: =Q33-P33 -> 0
A34: Deffered tax liabilities | B34: 1417 | C34: =D34 -> 1422 | D34: 1422 | E34: 1198 | F34: =AE34 -> 999 | G34: 1073 | H34: =AF34 -> 1971 | I34: 2078 | J34: =AG34 -> 2138 | K34: 2403 | L34: =AH34 -> 2213 | M34: 2105 | N34: =AI34 -> 2155 | O34: =N34 -> 2155 | P34: =AJ34 -> 2155 | Q34: =P34 -> 2155 | R34: =AK34 -> 2155 | S34: =R34 -> 2155 | T34: =AL34 -> 2155 | U34: =T34 -> 2155 | V34: =AM34 -> 2155 | W34: =V34 -> 2155 | X34: =AN34 -> 2155 | Y34: =X34 -> 2155 | Z34: =AO34 -> 2155 | AE34: 999 | AF34: 1971 | AG34: 2138 | AH34: 2213 | AI34: 2155 | AJ34: =AI34 -> 2155 | AK34: =AJ34 -> 2155 | AL34: =AK34 -> 2155 | AM34: =AL34 -> 2155 | AN34: =AM34 -> 2155 | AO34: =AN34 -> 2155 | AU34: =Q34-P34 -> 0
A35: Other non-current liabilities | B35: 172 | C35: =D35 -> 153 | D35: 153 | E35: 108 | F35: =AE35 -> 131 | G35: 136 | H35: =AF35 -> 141 | I35: 179 | J35: =AG35 -> 125 | K35: 75 | L35: =AH35 -> 67 | M35: 81 | N35: =AI35 -> 90 | O35: =N35 -> 90 | P35: =AJ35 -> 90 | Q35: =P35 -> 90 | R35: =AK35 -> 90 | S35: =R35 -> 90 | T35: =AL35 -> 90 | U35: =T35 -> 90 | V35: =AM35 -> 90 | W35: =V35 -> 90 | X35: =AN35 -> 90 | Y35: =X35 -> 90 | Z35: =AO35 -> 90 | AE35: 131 | AF35: 141 | AG35: 125 | AH35: 67 | AI35: 90 | AJ35: =AI35 -> 90 | AK35: =AJ35 -> 90 | AL35: =AK35 -> 90 | AM35: =AL35 -> 90 | AN35: =AM35 -> 90 | AO35: =AN35 -> 90 | AU35: =Q35-P35 -> 0
A36: Total non-current liabilities | B36: =SUM(B31:B35) -> 17571 | C36: =SUM(C31:C35) -> 16886 | D36: =SUM(D31:D35) -> 16886 | E36: =SUM(E31:E35) -> 18678 | F36: =SUM(F31:F35) -> 17372 | G36: =SUM(G31:G35) -> 16548 | H36: =SUM(H31:H35) -> 17056 | I36: =SUM(I31:I35) -> 16474 | ... Z36: =SUM(Z31:Z35) -> 20133 | AE36: =SUM(AE31:AE35) -> 17372 | AF36: =SUM(AF31:AF35) -> 17056 | AG36: =SUM(AG31:AG35) -> 16296 | AH36: =SUM(AH31:AH35) -> 17539 | AI36: =SUM(AI31:AI35) -> 17133 | AJ36: =SUM(AJ31:AJ35) -> 17633 | AK36: =SUM(AK31:AK35) -> 18133 | AL36: =SUM(AL31:AL35) -> 18633 | ... AO36: =SUM(AO31:AO35) -> 20133
A38: Borrowings | B38: 3727 | C38: =D38 -> 3686 | D38: 3686 | E38: 5423 | F38: =AE38 -> 3580 | G38: 3155 | H38: =AF38 -> 3233 | I38: 3556 | J38: =AG38 -> 3484 | K38: 5416 | L38: =AH38 -> 4192 | M38: 4705 | N38: =AI38 -> 3266 | O38: =O83 -> 4192 | P38: =AJ38 -> 4192 | Q38: =Q83 -> 4192 | R38: =AK38 -> 4192 | S38: =S83 -> 4192 | T38: =AL38 -> 4192 | U38: =U83 -> 4192 | V38: =AM38 -> 4192 | W38: =W83 -> 4192 | X38: =AN38 -> 4192 | Y38: =Y83 -> 4192 | Z38: =AO38 -> 4192 | AE38: 3580 | AF38: 3233 | AG38: 3484 | AH38: 4192 | AI38: 3266 | AJ38: =AJ83 -> 4192 | AK38: =AK83 -> 4192 | AL38: =AL83 -> 4192 | AM38: =AM83 -> 4192 | AN38: =AN83 -> 4192 | AO38: =AO83 -> 4192 | AU38: =Q38-P38 -> 0
A39: Trade and other payables | B39: 7595 | C39: =D39 -> 7520 | D39: 7520 | E39: 6115 | F39: =AE39 -> 6107 | G39: 7100 | H39: =AF39 -> 7750 | I39: 9091 | J39: =AG39 -> 9283 | K39: 9744 | L39: =AH39 -> 9432 | M39: 9401 | N39: =AI39 -> 9912 | O39: =O101 -> 9533.1662 | P39: =AJ39 -> 10971.643 | Q39: =Q101 -> 9041.2738 | R39: =AK39 -> 12027.397 | S39: =S101 -> 9522.0218 | T39: =AL39 -> 13288.631 | U39: =U101 -> 10235.019 | V39: =AM39 -> 14742.392 | W39: =W101 -> 11187.755 | X39: =AN39 -> 16547.022 | Y39: =Y101 -> 12403.13 | Z39: =AO39 -> 18628.981 | AE39: 6107 | AF39: 7750 | AG39: 9283 | AH39: 9432 | AI39: 9912 | AJ39: =AJ101 -> 10971.643 | AK39: =AK101 -> 12027.397 | AL39: =AL101 -> 13288.631 | AM39: =AM101 -> 14742.392 | AN39: =AN101 -> 16547.022 | AO39: =AO101 -> 18628.981 | AU39: =Q39-P39 -> -1930.3694
A40: Returnable packaging deposits | B40: 610 | C40: =D40 -> 565 | D40: 565 | E40: 528 | F40: =AE40 -> 454 | G40: 524 | H40: =AF40 -> 476 | I40: 590 | J40: =AG40 -> 545 | K40: 578 | L40: =AH40 -> 531 | M40: 583 | N40: =AI40 -> 525 | O40: =N40 -> 525 | P40: =AJ40 -> 525 | Q40: =P40 -> 525 | R40: =AK40 -> 525 | S40: =R40 -> 525 | T40: =AL40 -> 525 | U40: =T40 -> 525 | V40: =AM40 -> 525 | W40: =V40 -> 525 | X40: =AN40 -> 525 | Y40: =X40 -> 525 | Z40: =AO40 -> 525 | AE40: 454 | AF40: 476 | AG40: 545 | AH40: 531 | AI40: 525 | AJ40: =AI40 -> 525 | AK40: =AJ40 -> 525 | AL40: =AK40 -> 525 | AM40: =AL40 -> 525 | AN40: =AM40 -> 525 | AO40: =AN40 -> 525 | AU40: =Q40-P40 -> 0
A41: Provisions | B41: 134 | C41: =D41 -> 184 | D41: 184 | E41: 176 | F41: =AE41 -> 416 | G41: 336 | H41: =AF41 -> 301 | I41: 257 | J41: =AG41 -> 226 | K41: 174 | L41: =AH41 -> 206 | M41: 201 | N41: =AI41 -> 176 | O41: =N41 -> 176 | P41: =AJ41 -> 176 | Q41: =P41 -> 176 | R41: =AK41 -> 176 | S41: =R41 -> 176 | T41: =AL41 -> 176 | U41: =T41 -> 176 | V41: =AM41 -> 176 | W41: =V41 -> 176 | X41: =AN41 -> 176 | Y41: =X41 -> 176 | Z41: =AO41 -> 176 | AE41: 416 | AF41: 301 | AG41: 226 | AH41: 206 | AI41: 176 | AJ41: =AI41 -> 176 | AK41: =AJ41 -> 176 | AL41: =AK41 -> 176 | AM41: =AL41 -> 176 | AN41: =AM41 -> 176 | AO41: =AN41 -> 176 | AU41: =Q41-P41 -> 0
A42: Current tax liabilities | B42: 248 | C42: =D42 -> 283 | D42: 283 | E42: 259 | F42: =AE42 -> 259 | G42: 262 | H42: =AF42 -> 268 | I42: 344 | J42: =AG42 -> 352 | K42: 322 | L42: =AH42 -> 332 | M42: 346 | N42: =AI42 -> 307 | O42: =N42 -> 307 | P42: =AJ42 -> 307 | Q42: =P42 -> 307 | R42: =AK42 -> 307 | S42: =R42 -> 307 | T42: =AL42 -> 307 | U42: =T42 -> 307 | V42: =AM42 -> 307 | W42: =V42 -> 307 | X42: =AN42 -> 307 | Y42: =X42 -> 307 | Z42: =AO42 -> 307 | AE42: 259 | AF42: 268 | AG42: 352 | AH42: 332 | AI42: 307 | AJ42: =AI42 -> 307 | AK42: =AJ42 -> 307 | AL42: =AK42 -> 307 | AM42: =AL42 -> 307 | AN42: =AM42 -> 307 | AO42: =AN42 -> 307 | AU42: =Q42-P42 -> 0
A43: Derivative liabilities | B43: 59 | C43: =D43 -> 69 | D43: 69 | E43: 57 | F43: =AE43 -> 52 | G43: 62 | H43: =AF43 -> 46 | I43: 158 | J43: =AG43 -> 119 | K43: 251 | L43: =AH43 -> 132 | M43: 54 | N43: =AI43 -> 52 | O43: =N43 -> 52 | P43: =AJ43 -> 52 | Q43: =P43 -> 52 | R43: =AK43 -> 52 | S43: =R43 -> 52 | T43: =AL43 -> 52 | U43: =T43 -> 52 | V43: =AM43 -> 52 | W43: =V43 -> 52 | X43: =AN43 -> 52 | Y43: =X43 -> 52 | Z43: =AO43 -> 52 | AE43: 52 | AF43: 46 | AG43: 119 | AH43: 132 | AI43: 52 | AJ43: =AI43 -> 52 | AK43: =AJ43 -> 52 | AL43: =AK43 -> 52 | AM43: =AL43 -> 52 | AN43: =AM43 -> 52 | AO43: =AN43 -> 52 | AU43: =Q43-P43 -> 0
A44: Liabilities associated with assets classified as held for sale | B44: 0 | C44: =D44 -> 0 | D44: 0 | E44: 0 | F44: =AE44 -> 0 | G44: 0 | H44: =AF44 -> 20 | I44: 323 | J44: =AG44 -> 181 | K44: 262 | L44: =AH44 -> 0 | M44: 0 | N44: =AI44 -> 0 | O44: =N44 -> 0 | P44: =AJ44 -> 0 | Q44: =P44 -> 0 | R44: =AK44 -> 0 | S44: =R44 -> 0 | T44: =AL44 -> 0 | U44: =T44 -> 0 | V44: =AM44 -> 0 | W44: =V44 -> 0 | X44: =AN44 -> 0 | Y44: =X44 -> 0 | Z44: =AO44 -> 0 | AE44: 0 | AF44: 20 | AG44: 181 | AH44: 0 | AI44: =AH44 -> 0 | AJ44: =AI44 -> 0 | AK44: =AJ44 -> 0 | AL44: =AK44 -> 0 | AM44: =AL44 -> 0 | AN44: =AM44 -> 0 | AO44: =AN44 -> 0 | AU44: =Q44-P44 -> 0
A45: Total current liabilities | B45: =SUM(B38:B44) -> 12373 | C45: =SUM(C38:C44) -> 12307 | D45: =SUM(D38:D44) -> 12307 | E45: =SUM(E38:E43) -> 12558 | F45: =SUM(F38:F43) -> 10868 | G45: =SUM(G38:G44) -> 11439 | H45: =SUM(H38:H44) -> 12094 | I45: =SUM(I38:I44) -> 14319 | J45: =SUM(J38:J44) -> 14190 | K45: =SUM(K38:K44) -> 16747 | L45: =SUM(L38:L44) -> 14825 | M45: =SUM(M38:M44) -> 15290 | N45: =SUM(N38:N44) -> 14238 | O45: =SUM(O38:O43) -> 14785.166 | P45: =SUM(P38:P44) -> 16223.643 | Q45: =SUM(Q38:Q43) -> 14293.274 | R45: =SUM(R38:R44) -> 17279.397 | S45: =SUM(S38:S43) -> 14774.022 | T45: =SUM(T38:T44) -> 18540.631 | U45: =SUM(U38:U43) -> 15487.019 | V45: =SUM(V38:V44) -> 19994.392 | W45: =SUM(W38:W43) -> 16439.755 | X45: =SUM(X38:X44) -> 21799.022 | Y45: =SUM(Y38:Y43) -> 17655.13 | Z45: =SUM(Z38:Z44) -> 23880.981 | AE45: =SUM(AE38:AE43) -> 10868 | AF45: =SUM(AF38:AF44) -> 12094 | AG45: =SUM(AG38:AG44) -> 14190 | AH45: =SUM(AH38:AH44) -> 14825 | AI45: =SUM(AI38:AI44) -> 14238 | AJ45: =SUM(AJ38:AJ43) -> 16223.643 | AK45: =SUM(AK38:AK43) -> 17279.397 | AL45: =SUM(AL38:AL43) -> 18540.631 | AM45: =SUM(AM38:AM43) -> 19994.392 | AN45: =SUM(AN38:AN43) -> 21799.022 | AO45: =SUM(AO38:AO43) -> 23880.981
A47: Total Equity and Liabilities | B47: =B29+B36+B45 -> 46227 | C47: =C29+C36+C45 -> 46504 | D47: =D29+D36+D45 -> 46504 | E47: =E29+E36+E45 -> 45796 | F47: =F29+F36+F45 -> 42632 | G47: =G29+G36+G45 -> 43494 | H47: =H29+H36+H45 -> 48850 | I47: =I29+I36+I45 -> 52349 | ... Z47: =Z29+Z36+Z45 -> 84206.348 | AE47: =AE29+AE36+AE45 -> 42632 | AF47: =AF29+AF36+AF45 -> 48850 | AG47: =AG29+AG36+AG45 -> 52406 | AH47: =AH29+AH36+AH45 -> 55153 | AI47: =AI29+AI36+AI45 -> 53773 | AJ47: =AJ29+AJ36+AJ45 -> 58221.563 | AK47: =AK29+AK36+AK45 -> 62038.279 | AL47: =AL29+AL36+AL45 -> 66428.028 | ... AO47: =AO29+AO36+AO45 -> 84206.348
B49: =B22=B47 -> TRUE | C49: =C22=C47 -> TRUE | D49: =D22=D47 -> TRUE | E49: =E22=E47 -> TRUE | F49: =F22=F47 -> TRUE | G49: =G22=G47 -> TRUE | H49: =H22=H47 -> TRUE | I49: =I22=I47 -> TRUE | ... Z49: =Z22=Z47 -> TRUE | AE49: =AE22=AE47 -> TRUE | AF49: =AF22=AF47 -> TRUE | AG49: =AG22=AG47 -> TRUE | AH49: =AH22=AH47 -> TRUE | AI49: =AI22=AI47 -> TRUE | AJ49: =AJ22=AJ47 -> TRUE | AK49: =AK22=AK47 -> TRUE | AL49: =AL22=AL47 -> TRUE | ... AO49: =AO22=AO47 -> TRUE
...

Sheet Cash Flow Statement
A1: ='Profit and Loss Statement '!A1 -> In millions of € | B1: ='Profit and Loss Statement '!B1 -> H1'19 | C1: ='Profit and Loss Statement '!C1 -> H2'19 | D1: ='Profit and Loss Statement '!D1 -> FY'19 | E1: ='Profit and Loss Statement '!E1 -> H1'20 | F1: ='Profit and Loss Statement '!F1 -> H2'20 | G1: ='Profit and Loss Statement '!G1 -> H1'21 | H1: ='Profit and Loss Statement '!H1 -> H2'21 | ... Z1: ='Profit and Loss Statement '!Z1 -> H2'30 | AE1: ='Profit and Loss Statement '!AE1 -> FY'20 | AF1: ='Profit and Loss Statement '!AF1 -> FY'21 | AG1: ='Profit and Loss Statement '!AG1 -> FY'22 | AH1: ='Profit and Loss Statement '!AH1 -> FY'23 | AI1: ='Profit and Loss Statement '!AI1 -> FY'24 | AJ1: ='Profit and Loss Statement '!AJ1 -> FY'25 | AK1: ='Profit and Loss Statement '!AK1 -> FY'26 | AL1: ='Profit and Loss Statement '!AL1 -> FY'27 | ... AO1: ='Profit and Loss Statement '!AO1 -> FY'30
A3: Profit/Loss | B3: 1038 | C3: =D3-B3 -> 1336 | D3: 2374 | E3: -272 | F3: =AE3-E3 -> 184 | G3: 1169 | H3: =AF3-G3 -> 2366 | I3: 1455 | J3: =AG3-I3 -> 1584 | K3: 1187 | L3: =AH3-K3 -> 1214 | M3: ='Profit and Loss Statement '!M24 -> -48 | N3: ='Profit and Loss Statement '!N24 -> 843.21882 | O3: ='Profit and Loss Statement '!O24 -> 1077.6022 | P3: ='Profit and Loss Statement '!P24 -> 885.31721 | Q3: ='Profit and Loss Statement '!Q24 -> 1181.1559 | R3: ='Profit and Loss Statement '!R24 -> 1079.8071 | S3: ='Profit and Loss Statement '!S24 -> 1340.9254 | T3: ='Profit and Loss Statement '!T24 -> 1287.5893 | ... Z3: ='Profit and Loss Statement '!Z24 -> 2050.3134 | AE3: -88 | AF3: 3535 | AG3: 3039 | AH3: 2401 | AI3: 1161 | AJ3: ='Profit and Loss Statement '!AJ24 -> 1962.9194 | AK3: ='Profit and Loss Statement '!AK24 -> 2260.963 | AL3: ='Profit and Loss Statement '!AL24 -> 2628.5147 | AM3: ='Profit and Loss Statement '!AM24 -> 3074.3026 | AN3: ='Profit and Loss Statement '!AN24 -> 3610.5413 | AO3: ='Profit and Loss Statement '!AO24 -> 4253.126
A4: Adjustments:
A5: D&A | B5: 911 | C5: =D5-B5 -> 1048 | D5: 1959 | E5: 1479 | F5: =AE5-E5 -> 1395 | G5: 870 | H5: =AF5-G5 -> 1089 | I5: 932 | J5: =AG5-I5 -> 954 | K5: 1244 | L5: =AH5-K5 -> 1852 | M5: 1367 | N5: =-'Profit and Loss Statement '!N13 -> 1238 | O5: =-'Profit and Loss Statement '!O13 -> 1692.54 | P5: =-'Profit and Loss Statement '!P13 -> 1425.72 | Q5: =-'Profit and Loss Statement '!Q13 -> 1766.7082 | R5: =-'Profit and Loss Statement '!R13 -> 1514.0154 | S5: =-'Profit and Loss Statement '!S13 -> 1848.0132 | T5: =-'Profit and Loss Statement '!T13 -> 1610.8072 | U5: =-'Profit and Loss Statement '!U13 -> 1937.8442 | ... Z5: =-'Profit and Loss Statement '!Z13 -> 1969.8787 | AE5: 2874 | AF5: 1959 | AG5: 1886 | AH5: 3096 | AI5: 2605 | AJ5: =-'Profit and Loss Statement '!AJ13 -> 3118.26 | AK5: =-'Profit and Loss Statement '!AK13 -> 3280.7236 | AL5: =-'Profit and Loss Statement '!AL13 -> 3458.8204 | AM5: =-'Profit and Loss Statement '!AM13 -> 3655.593 | AN5: =-'Profit and Loss Statement '!AN13 -> 3874.4904 | AO5: =-'Profit and Loss Statement '!AO13 -> 4119.5119
A6: Interest Expenses | B6: 227 | C6: =D6-B6 -> 227 | D6: 454 | E6: 207 | F6: =AE6-E6 -> 240 | G6: 202 | H6: =AF6-G6 -> 211 | I6: 185 | J6: =AG6-I6 -> 199 | K6: 249 | L6: =AH6-K6 -> 301 | M6: 295 | N6: =AI6-M6 -> 275 | AE6: 447 | AF6: 413 | AG6: 384 | AH6: 550 | AI6: 570
A7: Other Income | B7: -78 | C7: =D7-B7 -> -17 | D7: -95 | E7: -5 | F7: =AE7-E7 -> -51 | G7: -20 | H7: =AF7-G7 -> -1306 | I7: -31 | J7: =AG7-I7 -> -116 | K7: -103 | L7: =AH7-K7 -> -249 | M7: -5 | N7: =AI7-M7 -> -32 | AE7: -56 | AF7: -1326 | AG7: -147 | AH7: -352 | AI7: -37 | AU7: 0
A8: Profit/Loss asociates & JVs | B8: -85 | C8: =D8-B8 -> -88 | D8: -173 | E8: 32 | F8: =AE8-E8 -> -11 | G8: -75 | H8: =AF8-G8 -> -181 | I8: -85 | J8: =AG8-I8 -> -145 | K8: -107 | L8: =AH8-K8 -> -119 | M8: 751 | N8: =AI8-M8 -> -64 | AE8: 21 | AF8: -256 | AG8: -230 | AH8: -226 | AI8: 687 | AU8: 0
A9: Income tax expenses | B9: 438 | C9: =D9-B9 -> 472 | D9: 910 | E9: 51 | F9: =AE9-E9 -> 194 | G9: 440 | H9: =AF9-G9 -> 359 | I9: 547 | J9: =AG9-I9 -> 584 | K9: 89 | L9: =AH9-K9 -> 32 | M9: 387 | N9: =AI9-M9 -> 459 | AE9: 245 | AF9: 799 | AG9: 1131 | AH9: 121 | AI9: 846 | AU9: 0
A10: Other non-cash items | B10: 182 | C10: =D10-B10 -> 58 | D10: 240 | E10: 85 | F10: =AE10-E10 -> 146 | G10: -9 | H10: =AF10-G10 -> 39 | I10: 97 | J10: =AG10-I10 -> 187 | K10: 316 | L10: =AH10-K10 -> 221 | M10: 169 | N10: =AI10-M10 -> 57 | O10: ='Balance Sheet'!O38-'Balance Sheet'!N38 -> 926 | AE10: 231 | AF10: 30 | AG10: 284 | AH10: 537 | AI10: 226 | AJ10: ='Balance Sheet'!AJ38-'Balance Sheet'!AI38+'Balance Sheet'!AJ40-'Balance Sheet'!AI40+'Balance Sheet'!AJ41-'Balance Sheet'!AI41+'Balance Sheet'!AJ42-'Balance Sheet'!AI42+'Balance Sheet'!AJ43-'Balance Sheet'!AI43+'Balance Sheet'!AI15-'Balance Sheet'!AJ15+'Balance Sheet'!AI16-'Balance Sheet'!AJ16+'Balance Sheet'!AI18-'Balance Sheet'!AJ18 -> 926 | AK10: ='Balance Sheet'!AK38-'Balance Sheet'!AJ38+'Balance Sheet'!AK40-'Balance Sheet'!AJ40+'Balance Sheet'!AK41-'Balance Sheet'!AJ41+'Balance Sheet'!AK42-'Balance Sheet'!AJ42+'Balance Sheet'!AK43-'Balance Sheet'!AJ43+'Balance Sheet'!AJ15-'Balance Sheet'!AK15+'Balance Sheet'!AJ16-'Balance Sheet'!AK16+'Balance Sheet'!AJ18-'Balance Sheet'!AK18 -> 0 | AL10: ='Balance Sheet'!AL38-'Balance Sheet'!AK38+'Balance Sheet'!AL40-'Balance Sheet'!AK40+'Balance Sheet'!AL41-'Balance Sheet'!AK41+'Balance Sheet'!AL42-'Balance Sheet'!AK42+'Balance Sheet'!AL43-'Balance Sheet'!AK43+'Balance Sheet'!AK15-'Balance Sheet'!AL15+'Balance Sheet'!AK16-'Balance Sheet'!AL16+'Balance Sheet'!AK18-'Balance Sheet'!AL18 -> 0 | AM10: ='Balance Sheet'!AM38-'Balance Sheet'!AL38+'Balance Sheet'!AM40-'Balance Sheet'!AL40+'Balance Sheet'!AM41-'Balance Sheet'!AL41+'Balance Sheet'!AM42-'Balance Sheet'!AL42+'Balance Sheet'!AM43-'Balance Sheet'!AL43+'Balance Sheet'!AL15-'Balance Sheet'!AM15+'Balance Sheet'!AL16-'Balance Sheet'!AM16+'Balance Sheet'!AL18-'Balance Sheet'!AM18 -> 0 | AN10: ='Balance Sheet'!AN38-'Balance Sheet'!AM38+'Balance Sheet'!AN40-'Balance Sheet'!AM40+'Balance Sheet'!AN41-'Balance Sheet'!AM41+'Balance Sheet'!AN42-'Balance Sheet'!AM42+'Balance Sheet'!AN43-'Balance Sheet'!AM43+'Balance Sheet'!AM15-'Balance Sheet'!AN15+'Balance Sheet'!AM16-'Balance Sheet'!AN16+'Balance Sheet'!AM18-'Balance Sheet'!AN18 -> 0 | AO10: ='Balance Sheet'!AO38-'Balance Sheet'!AN38+'Balance Sheet'!AO40-'Balance Sheet'!AN40+'Balance Sheet'!AO41-'Balance Sheet'!AN41+'Balance Sheet'!AO42-'Balance Sheet'!AN42+'Balance Sheet'!AO43-'Balance Sheet'!AN43+'Balance Sheet'!AN15-'Balance Sheet'!AO15+'Balance Sheet'!AN16-'Balance Sheet'!AO16+'Balance Sheet'!AN18-'Balance Sheet'!AO18 -> 0 | AU10: 0
A11: Cash Flow before WC | B11: =B3+SUM(B5:B10) -> 2633 | C11: =C3+SUM(C5:C10) -> 3036 | D11: =D3+SUM(D5:D10) -> 5669 | E11: =E3+SUM(E5:E10) -> 1577 | F11: =F3+SUM(F5:F10) -> 2097 | G11: =G3+SUM(G5:G10) -> 2577 | H11: =H3+SUM(H5:H10) -> 2577 | I11: =I3+SUM(I5:I10) -> 3100 | ... Z11: =Z3+SUM(Z5:Z10) -> 4020.1921 | AE11: =AE3+SUM(AE5:AE10) -> 3674 | AF11: =AF3+SUM(AF5:AF10) -> 5154 | AG11: =AG3+SUM(AG5:AG10) -> 6347 | AH11: =AH3+SUM(AH5:AH10) -> 6127 | AI11: =AI3+SUM(AI5:AI10) -> 6058 | AJ11: =AJ3+SUM(AJ5:AJ10) -> 6007.1794 | AK11: =AK3+SUM(AK5:AK10) -> 5541.6866 | AL11: =AL3+SUM(AL5:AL10) -> 6087.3351 | ... AO11: =AO3+SUM(AO5:AO10) -> 8372.6379 | AU11: 0
