Workbook

Sheet Revenue Model
B2: In Euro millions | C2: H1'21 | D2: H2'21 | E2: FY21 | F2: H1'22 | G2: H2'22 | H2: H1'23 | I2: H2'23 | J2: H1'24 | K2: H2'24 | L2: H1'25 | M2: H2'25 | N2: H1'26 | O2: H2'26 | P2: H1'27 | Q2: H2'27 | R2: H1'28 | S2: H2'28 | T2: H1'29 | U2: H2'29 | V2: H1'30 | W2: H2'30 | AC2: FY22 | AD2: FY23 | AE2: FY24 | AF2: FY25 | AG2: FY26 | AH2: FY27 | AI2: FY28 | AJ2: FY29 | AK2: FY30
B4: Americas
B5: Organic | F5: 196 | G5: =AC5-F5 -> 123 | H5: 118 | I5: =AD5-H5 -> -56 | J5: -145 | K5: =AE5-J5 -> -14 | L5: -81 | M5: =K5*(1+M6) -> -13.86 | N5: =L5*(1+N6) -> -83.43 | O5: =M5*(1+O6) -> -14.2758 | P5: =N5*(1+P6) -> -85.9329 | Q5: =O5*(1+Q6) -> -14.704074 | R5: =P5*(1+R6) -> -88.510887 | S5: =Q5*(1+S6) -> -15.145196 | T5: =R5*(1+T6) -> -91.166214 | ... W5: =U5*(1+W6) -> -16.067539 | AC5: 319 | AD5: 62 | AE5: -159 | AF5: =L5+M5 -> -94.86 | AG5: =N5+O5 -> -97.7058 | AH5: =P5+Q5 -> -100.63697 | AI5: =R5+S5 -> -103.65608 | AJ5: =T5+U5 -> -106.76577 | AK5: =V5+W5 -> -109.96874
B6: Organic growth (%) | C6: =IFERROR(C5/#REF!-1, "-") -> - | D6: =IFERROR(D5/#REF!-1, "-") -> - | E6: =IFERROR(E5/#REF!-1, "-") -> - | F6: =F5/C11 -> 0.13980029 | G6: =G5/D11 -> 0.10040816 | H6: =H5/F11 -> 0.072039072 | I6: =I5/G11 -> -0.037458194 | J6: =J5/H11 -> -0.072319202 | K6: =K5/I11 -> -0.0094915254 | L6: =L5/J11 -> -0.043548387 | M6: -0.01 | N6: 0.03 | O6: 0.03 | P6: 0.03 | Q6: 0.03 | R6: 0.03 | S6: 0.03 | T6: 0.03 | U6: 0.03 | V6: 0.03 | W6: 0.03 | AC6: =AC5/E11 -> 0.12143129 | AD6: =AD5/AC11 -> 0.019789339 | AE6: =AE5/AD11 -> -0.04567653 | AF6: =AF5/AE5-1 -> -0.40339623 | AG6: =AG5/AF5-1 -> 0.03 | AH6: =AH5/AG5-1 -> 0.03 | AI6: =AI5/AH5-1 -> 0.03 | AJ6: =AJ5/AI5-1 -> 0.03 | AK6: =AK5/AJ5-1 -> 0.03
B7: Fx | F7: 22 | G7: =AC7-F7 -> 134 | H7: 220 | I7: =AD7-H7 -> -42 | J7: -173 | K7: =AE7-J7 -> -92 | L7: -98 | M7: =K7*(1+M8) -> -91.08 | N7: =L7*(1+N8) -> -100.94 | O7: =M7*(1+O8) -> -93.8124 | P7: =N7*(1+P8) -> -103.9682 | Q7: =O7*(1+Q8) -> -96.626772 | R7: =P7*(1+R8) -> -107.08725 | S7: =Q7*(1+S8) -> -99.525575 | T7: =R7*(1+T8) -> -110.29986 | ... W7: =U7*(1+W8) -> -105.58668 | AC7: 156 | AD7: 178 | AE7: -265 | AF7: =L7+M7 -> -189.08 | AG7: =N7+O7 -> -194.7524 | AH7: =P7+Q7 -> -200.59497 | AI7: =R7+S7 -> -206.61282 | AJ7: =T7+U7 -> -212.81121 | AK7: =V7+W7 -> -219.19554
B8: Fx growth (%) | C8: =IFERROR(C7/#REF!-1, "-") -> - | D8: =IFERROR(D7/#REF!-1, "-") -> - | E8: =IFERROR(E7/#REF!-1, "-") -> - | F8: =F7/C11 -> 0.015691869 | G8: =G7/D11 -> 0.10938776 | H8: =H7/F11 -> 0.13431013 | I8: =I7/G11 -> -0.028093645 | J8: =J7/H11 -> -0.086284289 | K8: =K7/I11 -> -0.062372881 | L8: =L7/J11 -> -0.052688172 | M8: -0.01 | N8: 0.03 | O8: 0.03 | P8: 0.03 | Q8: 0.03 | R8: 0.03 | S8: 0.03 | T8: 0.03 | U8: 0.03 | V8: 0.03 | W8: 0.03 | AC8: =AC7/E11 -> 0.059383327 | AD8: =AD7/AC11 -> 0.056814555 | AE8: =AE7/AD11 -> -0.07612755 | AF8: =AF7/AE7-1 -> -0.28649057 | AG8: =AG7/AF7-1 -> 0.03 | AH8: =AH7/AG7-1 -> 0.03 | AI8: =AI7/AH7-1 -> 0.03 | AJ8: =AJ7/AI7-1 -> 0.03 | AK8: =AK7/AJ7-1 -> 0.03
B9: Scope | F9: 17 | G9: =AC9-F9 -> 13 | H9: 30 | I9: =AD9-H9 -> 78 | J9: 173 | K9: =AE9-J9 -> 110 | L9: 57 | M9: =K9*(1+M10) -> 108.9 | N9: =L9*(1+N10) -> 58.71 | O9: =M9*(1+O10) -> 112.167 | P9: =N9*(1+P10) -> 60.4713 | Q9: =O9*(1+Q10) -> 115.53201 | R9: =P9*(1+R10) -> 62.285439 | S9: =Q9*(1+S10) -> 118.99797 | T9: =R9*(1+T10) -> 64.154002 | ... W9: =U9*(1+W10) -> 126.24495 | AC9: 30 | AD9: 108 | AE9: 283 | AF9: =L9+M9 -> 165.9 | AG9: =N9+O9 -> 170.877 | AH9: =P9+Q9 -> 176.00331 | AI9: =R9+S9 -> 181.28341 | AJ9: =T9+U9 -> 186.72191 | AK9: =V9+W9 -> 192.32357
B10: Scope growth (%) | C10: =IFERROR(C9/#REF!-1, "-") -> - | D10: =IFERROR(D9/#REF!-1, "-") -> - | E10: =IFERROR(E9/#REF!-1, "-") -> - | F10: =F9/C11 -> 0.012125535 | G10: =G9/D11 -> 0.010612245 | H10: =H9/F11 -> 0.018315018 | I10: =I9/G11 -> 0.052173913 | J10: =J9/H11 -> 0.086284289 | K10: =K9/I11 -> 0.074576271 | L10: =L9/J11 -> 0.030645161 | M10: -0.01 | N10: 0.03 | O10: 0.03 | P10: 0.03 | Q10: 0.03 | R10: 0.03 | S10: 0.03 | T10: 0.03 | U10: 0.03 | V10: 0.03 | W10: 0.03 | AC10: =AC9/E11 -> 0.011419871 | AD10: =AD9/AC11 -> 0.034471752 | AE10: =AE9/AD11 -> 0.081298477 | AF10: =IFERROR(AF9/AE9-1, "-") -> -0.41378092 | AG10: =IFERROR(AG9/AF9-1, "-") -> 0.03 | AH10: =IFERROR(AH9/AG9-1, "-") -> 0.03 | AI10: =IFERROR(AI9/AH9-1, "-") -> 0.03 | AJ10: =IFERROR(AJ9/AI9-1, "-") -> 0.03 | AK10: =IFERROR(AK9/AJ9-1, "-") -> 0.03
B11: Total Sales - Americas | C11: 1402 | D11: =E11-C11 -> 1225 | E11: 2627 | F11: =C11+F5+F7+F9+1 -> 1638 | G11: =D11+G5+G7+G9 -> 1495 | H11: =F11+H5+H7+H9-1 -> 2005 | I11: =G11+I5+I7+I9 -> 1475 | J11: =H11+J5+J7+J9 -> 1860 | K11: =I11+K5+K7+K9 -> 1479 | L11: =J11+L5+L7+L9 -> 1738 | M11: =K11+M5+M7+M9 -> 1482.96 | N11: =L11+N5+N7+N9 -> 1612.34 | O11: =M11+O5+O7+O9 -> 1487.0388 | P11: =N11+P5+P7+P9 -> 1482.9102 | ... W11: =U11+W5+W7+W9 -> 1504.6149 | AC11: =E11+AC5+AC7+AC9+1 -> 3133 | AD11: =AC11+AD5+AD7+AD9 -> 3481 | AE11: =AD11+AE5+AE7+AE9 -> 3340 | AF11: =AE11+AF5+AF7+AF9 -> 3221.96 | AG11: =AF11+AG5+AG7+AG9 -> 3100.3788 | AH11: =AG11+AH5+AH7+AH9 -> 2975.1502 | AI11: =AH11+AI5+AI7+AI9 -> 2846.1647 | AJ11: =AI11+AJ5+AJ7+AJ9 -> 2713.3096 | AK11: =AJ11+AK5+AK7+AK9 -> 2576.4689
B12: Growth (%) | C12: =IFERROR(C11/#REF!-1, "-") -> - | D12: =IFERROR(D11/#REF!-1, "-") -> - | E12: =IFERROR(E11/#REF!-1, "-") -> - | F12: =IFERROR(F11/C11-1, "-") -> 0.16833096 | G12: =IFERROR(G11/D11-1, "-") -> 0.22040816 | H12: =IFERROR(H11/F11-1, "-") -> 0.22405372 | I12: =IFERROR(I11/G11-1, "-") -> -0.013377926 | J12: =IFERROR(J11/H11-1, "-") -> -0.072319202 | K12: =IFERROR(K11/I11-1, "-") -> 0.0027118644 | L12: =IFERROR(L11/J11-1, "-") -> -0.065591398 | M12: =IFERROR(M11/K11-1, "-") -> 0.0026774848 | N12: =IFERROR(N11/L11-1, "-") -> -0.072301496 | O12: =IFERROR(O11/M11-1, "-") -> 0.0027504451 | ... W12: =IFERROR(W11/U11-1, "-") -> 0.0030604342 | AC12: =IFERROR(AC11/E11-1, "-") -> 0.19261515 | AD12: =IFERROR(AD11/AC11-1, "-") -> 0.11107565 | AE12: =IFERROR(AE11/AD11-1, "-") -> -0.040505602 | AF12: =IFERROR(AF11/AE11-1, "-") -> -0.035341317 | AG12: =IFERROR(AG11/AF11-1, "-") -> -0.037735167 | AH12: =IFERROR(AH11/AG11-1, "-") -> -0.040391399 | AI12: =IFERROR(AI11/AH11-1, "-") -> -0.043354281 | AJ12: =IFERROR(AJ11/AI11-1, "-") -> -0.046678627 | AK12: =IFERROR(AK11/AJ11-1, "-") -> -0.050433136
B14: Asia/Row
B15: Organic | F15: 338 | G15: =AC15-F15 -> 336 | H15: 460 | I15: =AD15-H15 -> 295 | J15: 16 | K15: =AE15-J15 -> 151 | L15: -156 | M15: =K15*(1+M16) -> 149.49 | N15: =L15*(1+N16) -> -160.68 | O15: =M15*(1+O16) -> 153.9747 | P15: =N15*(1+P16) -> -165.5004 | Q15: =O15*(1+Q16) -> 158.59394 | R15: =P15*(1+R16) -> -170.46541 | S15: =Q15*(1+S16) -> 163.35176 | T15: =R15*(1+T16) -> -175.57937 | ... W15: =U15*(1+W16) -> 173.29988 | AC15: 674 | AD15: 755 | AE15: 167 | AF15: =L15+M15 -> -6.51 | AG15: =N15+O15 -> -6.7053 | AH15: =P15+Q15 -> -6.906459 | AI15: =R15+S15 -> -7.1136528 | AJ15: =T15+U15 -> -7.3270624 | AK15: =V15+W15 -> -7.5468742
B16: Organic growth (%) | C16: =IFERROR(C15/#REF!-1, "-") -> - | D16: =IFERROR(D15/#REF!-1, "-") -> - | E16: =IFERROR(E15/#REF!-1, "-") -> - | F16: =F15/C21 -> 0.15890926 | G16: =G15/D21 -> 0.22207535 | H16: =H15/F21 -> 0.1822504 | I16: =I15/G21 -> 0.15412748 | J16: =J15/H21 -> 0.0051249199 | K16: =K15/I21 -> 0.072982117 | L16: =L15/J21 -> -0.054736842 | M16: -0.01 | N16: 0.03 | O16: 0.03 | P16: 0.03 | Q16: 0.03 | R16: 0.03 | S16: 0.03 | T16: 0.03 | U16: 0.03 | V16: 0.03 | W16: 0.03 | AC16: =AC15/E21 -> 0.18516484 | AD16: =AD15/AC21 -> 0.17012168 | AE16: =AE15/AD21 -> 0.032171065 | AF16: =AF15/AE15-1 -> -1.038982 | AG16: =AG15/AF15-1 -> 0.03 | AH16: =AH15/AG15-1 -> 0.03 | AI16: =AI15/AH15-1 -> 0.03 | AJ16: =AJ15/AI15-1 -> 0.03 | AK16: =AK15/AJ15-1 -> 0.03
B17: Fx | F17: 60 | G17: =AC17-F17 -> 65 | H17: 90 | I17: =AD17-H17 -> -176 | J17: -366 | K17: =AE17-J17 -> -130 | L17: -80 | M17: =K17*(1+M18) -> -128.7 | N17: =L17*(1+N18) -> -82.4 | O17: =M17*(1+O18) -> -132.561 | P17: =N17*(1+P18) -> -84.872 | Q17: =O17*(1+Q18) -> -136.53783 | R17: =P17*(1+R18) -> -87.41816 | S17: =Q17*(1+S18) -> -140.63396 | T17: =R17*(1+T18) -> -90.040705 | ... W17: =U17*(1+W18) -> -149.19857 | AC17: 125 | AD17: -86 | AE17: -496 | AF17: =L17+M17 -> -208.7 | AG17: =N17+O17 -> -214.961 | AH17: =P17+Q17 -> -221.40983 | AI17: =R17+S17 -> -228.05212 | AJ17: =T17+U17 -> -234.89369 | AK17: =V17+W17 -> -241.9405
B18: Fx growth (%) | C18: =IFERROR(C17/#REF!-1, "-") -> - | D18: =IFERROR(D17/#REF!-1, "-") -> - | E18: =IFERROR(E17/#REF!-1, "-") -> - | F18: =F17/C21 -> 0.028208745 | G18: =G17/D21 -> 0.042961005 | H18: =H17/F21 -> 0.035657686 | I18: =I17/G21 -> -0.091954023 | J18: =J17/H21 -> -0.11723254 | K18: =K17/I21 -> -0.062832286 | L18: =L17/J21 -> -0.028070175 | M18: -0.01 | N18: 0.03 | O18: 0.03 | P18: 0.03 | Q18: 0.03 | R18: 0.03 | S18: 0.03 | T18: 0.03 | U18: 0.03 | V18: 0.03 | W18: 0.03 | AC18: =AC17/E21 -> 0.034340659 | AD18: =AD17/AC21 -> -0.019378098 | AE18: =AE17/AD21 -> -0.09554999 | AF18: =AF17/AE17-1 -> -0.57923387 | AG18: =AG17/AF17-1 -> 0.03 | AH18: =AH17/AG17-1 -> 0.03 | AI18: =AI17/AH17-1 -> 0.03 | AJ18: =AJ17/AI17-1 -> 0.03 | AK18: =AK17/AJ17-1 -> 0.03
B19: Scope | F19: 0 | G19: =AC19-F19 -> 0 | H19: 48 | I19: =AD19-H19 -> 36 | J19: 79 | K19: =AE19-J19 -> 32 | L19: 5 | M19: =K19*(1+M20) -> 31.68 | N19: =L19*(1+N20) -> 5.15 | O19: =M19*(1+O20) -> 32.6304 | P19: =N19*(1+P20) -> 5.3045 | Q19: =O19*(1+Q20) -> 33.609312 | R19: =P19*(1+R20) -> 5.463635 | S19: =Q19*(1+S20) -> 34.617591 | T19: =R19*(1+T20) -> 5.6275441 | ... W19: =U19*(1+W20) -> 36.725803 | AC19: 0 | AD19: 84 | AE19: 111 | AF19: =L19+M19 -> 36.68 | AG19: =N19+O19 -> 37.7804 | AH19: =P19+Q19 -> 38.913812 | AI19: =R19+S19 -> 40.081226 | AJ19: =T19+U19 -> 41.283663 | AK19: =V19+W19 -> 42.522173
B20: Scope growth (%) | C20: =IFERROR(C19/#REF!-1, "-") -> - | D20: =IFERROR(D19/#REF!-1, "-") -> - | E20: =IFERROR(E19/#REF!-1, "-") -> - | F20: =F19/C21 -> 0 | G20: =G19/D21 -> 0 | H20: =H19/F21 -> 0.019017433 | I20: =I19/G21 -> 0.018808777 | J20: =J19/H21 -> 0.025304292 | K20: =K19/I21 -> 0.015466409 | L20: =L19/J21 -> 0.001754386 | M20: -0.01 | N20: 0.03 | O20: 0.03 | P20: 0.03 | Q20: 0.03 | R20: 0.03 | S20: 0.03 | T20: 0.03 | U20: 0.03 | V20: 0.03 | W20: 0.03 | AC20: =AC19/E21 -> 0 | AD20: =AD19/AC21 -> 0.018927445 | AE20: =AE19/AD21 -> 0.021383163 | AF20: =IFERROR(AF19/AE19-1, "-") -> -0.66954955 | AG20: =IFERROR(AG19/AF19-1, "-") -> 0.03 | AH20: =IFERROR(AH19/AG19-1, "-") -> 0.03 | AI20: =IFERROR(AI19/AH19-1, "-") -> 0.03 | AJ20: =IFERROR(AJ19/AI19-1, "-") -> 0.03 | AK20: =IFERROR(AK19/AJ19-1, "-") -> 0.03
B21: Total Sales - Asia/Row | C21: 2127 | D21: =E21-C21 -> 1513 | E21: 3640 | F21: =C21+F15+F17+F19-1 -> 2524 | G21: =D21+G15+G17+G19 -> 1914 | H21: =F21+H15+H17+H19 -> 3122 | I21: =G21+I15+I17+I19 -> 2069 | J21: =H21+J15+J17+J19-1 -> 2850 | K21: =I21+K15+K17+K19 -> 2122 | L21: =J21+L15+L17+L19 -> 2619 | M21: =K21+M15+M17+M19 -> 2174.47 | N21: =L21+N15+N17+N19 -> 2381.07 | O21: =M21+O15+O17+O19 -> 2228.5141 | P21: =N21+P15+P17+P19 -> 2136.0021 | Q21: =O21+Q15+Q17+Q19 -> 2284.1795 | R21: =P21+R15+R17+R19 -> 1883.5822 | ... W21: =U21+W15+W17+W19 -> 2461.3975 | AC21: =E21+AC15+AC17+AC19-1 -> 4438 | AD21: =AC21+AD15+AD17+AD19 -> 5191 | AE21: =AD21+AE15+AE17+AE19 -> 4973 | AF21: =AE21+AF15+AF17+AF19 -> 4794.47 | AG21: =AF21+AG15+AG17+AG19 -> 4610.5841 | AH21: =AG21+AH15+AH17+AH19 -> 4421.1816 | AI21: =AH21+AI15+AI17+AI19 -> 4226.0971 | AJ21: =AI21+AJ15+AJ17+AJ19 -> 4025.16 | AK21: =AJ21+AK15+AK17+AK19 -> 3818.1948
B22: Growth (%) | C22: =IFERROR(C21/#REF!-1, "-") -> - | D22: =IFERROR(D21/#REF!-1, "-") -> - | E22: =IFERROR(E21/#REF!-1, "-") -> - | F22: =IFERROR(F21/C21-1, "-") -> 0.18664786 | G22: =IFERROR(G21/D21-1, "-") -> 0.26503635 | H22: =IFERROR(H21/F21-1, "-") -> 0.23692552 | I22: =IFERROR(I21/G21-1, "-") -> 0.080982236 | J22: =IFERROR(J21/H21-1, "-") -> -0.087123639 | K22: =IFERROR(K21/I21-1, "-") -> 0.02561624 | L22: =IFERROR(L21/J21-1, "-") -> -0.081052632 | M22: =IFERROR(M21/K21-1, "-") -> 0.024726673 | N22: =IFERROR(N21/L21-1, "-") -> -0.090847652 | O22: =IFERROR(O21/M21-1, "-") -> 0.024853918 | ... W22: =IFERROR(W21/U21-1, "-") -> 0.025338608 | AC22: =IFERROR(AC21/E21-1, "-") -> 0.21923077 | AD22: =IFERROR(AD21/AC21-1, "-") -> 0.16967102 | AE22: =IFERROR(AE21/AD21-1, "-") -> -0.041995762 | AF22: =IFERROR(AF21/AE21-1, "-") -> -0.035899859 | AG22: =IFERROR(AG21/AF21-1, "-") -> -0.038353749 | AH22: =IFERROR(AH21/AG21-1, "-") -> -0.041079931 | AI22: =IFERROR(AI21/AH21-1, "-") -> -0.04412498 | AJ22: =IFERROR(AJ21/AI21-1, "-") -> -0.047546728 | AK22: =IFERROR(AK21/AJ21-1, "-") -> -0.051417882
B24: Europe
B25: Organic | F25: 300 | G25: =AC25-F25 -> 183 | H25: 108 | I25: =AD25-H25 -> 143 | J25: -84 | K25: =AE25-J25 -> -74 | L25: -30 | M25: =K25*(1+M26) -> -73.26 | N25: =L25*(1+N26) -> -30.9 | O25: =M25*(1+O26) -> -75.4578 | P25: =N25*(1+P26) -> -31.827 | Q25: =O25*(1+Q26) -> -77.721534 | R25: =P25*(1+R26) -> -32.78181 | S25: =Q25*(1+S26) -> -80.05318 | T25: =R25*(1+T26) -> -33.765264 | ... W25: =U25*(1+W26) -> -84.928419 | AC25: 483 | AD25: 251 | AE25: -158 | AF25: =L25+M25 -> -103.26 | AG25: =N25+O25 -> -106.3578 | AH25: =P25+Q25 -> -109.54853 | AI25: =R25+S25 -> -112.83499 | AJ25: =T25+U25 -> -116.22004 | AK25: =V25+W25 -> -119.70664
B26: Organic growth (%) | C26: =IFERROR(C25/#REF!-1, "-") -> - | D26: =IFERROR(D25/#REF!-1, "-") -> - | E26: =IFERROR(E25/#REF!-1, "-") -> - | F26: =F25/C31 -> 0.20604396 | G26: =G25/D31 -> 0.16621253 | H26: =H25/F31 -> 0.060100167 | I26: =I25/G31 -> 0.10727682 | J26: =J25/H31 -> -0.042232278 | K26: =K25/I31 -> -0.050101557 | L26: =L25/J31 -> -0.015965939 | M26: -0.01 | N26: 0.03 | O26: 0.03 | P26: 0.03 | Q26: 0.03 | R26: 0.03 | S26: 0.03 | T26: 0.03 | U26: 0.03 | V26: 0.03 | W26: 0.03 | AC26: =AC25/E31 -> 0.18889323 | AD26: =AD25/AC31 -> 0.080191693 | AE26: =AE25/AD31 -> -0.045598846 | AF26: =AF25/AE25-1 -> -0.3464557 | AG26: =AG25/AF25-1 -> 0.03 | AH26: =AH25/AG25-1 -> 0.03 | AI26: =AI25/AH25-1 -> 0.03 | AJ26: =AJ25/AI25-1 -> 0.03 | AK26: =AK25/AJ25-1 -> 0.03
B27: Fx | F27: 22 | G27: =AC27-F27 -> 13 | H27: 45 | I27: =AD27-H27 -> -18 | J27: -37 | K27: =AE27-J27 -> 14 | L27: 1 | M27: =K27*(1+M28) -> 13.86 | N27: =L27*(1+N28) -> 1.03 | O27: =M27*(1+O28) -> 14.2758 | P27: =N27*(1+P28) -> 1.0609 | Q27: =O27*(1+Q28) -> 14.704074 | R27: =P27*(1+R28) -> 1.092727 | S27: =Q27*(1+S28) -> 15.145196 | T27: =R27*(1+T28) -> 1.1255088 | ... W27: =U27*(1+W28) -> 16.067539 | AC27: 35 | AD27: 27 | AE27: -23 | AF27: =L27+M27 -> 14.86 | AG27: =N27+O27 -> 15.3058 | AH27: =P27+Q27 -> 15.764974 | AI27: =R27+S27 -> 16.237923 | AJ27: =T27+U27 -> 16.725061 | AK27: =V27+W27 -> 17.226813
B28: Fx growth (%) | C28: =IFERROR(C27/#REF!-1, "-") -> - | D28: =IFERROR(D27/#REF!-1, "-") -> - | E28: =IFERROR(E27/#REF!-1, "-") -> - | F28: =F27/C31 -> 0.01510989 | G28: =G27/D31 -> 0.011807448 | H28: =H27/F31 -> 0.025041736 | I28: =I27/G31 -> -0.013503376 | J28: =J27/H31 -> -0.018602313 | K28: =K27/I31 -> 0.009478673 | L28: =L27/J31 -> 0.00053219798 | M28: -0.01 | N28: 0.03 | O28: 0.03 | P28: 0.03 | Q28: 0.03 | R28: 0.03 | S28: 0.03 | T28: 0.03 | U28: 0.03 | V28: 0.03 | W28: 0.03 | AC28: =AC27/E31 -> 0.013687916 | AD28: =AD27/AC31 -> 0.0086261981 | AE28: =AE27/AD31 -> -0.0066378066 | AF28: =AF27/AE27-1 -> -1.646087 | AG28: =AG27/AF27-1 -> 0.03 | AH28: =AH27/AG27-1 -> 0.03 | AI28: =AI27/AH27-1 -> 0.03 | AJ28: =AJ27/AI27-1 -> 0.03 | AK28: =AK27/AJ27-1 -> 0.03
B29: Scope | F29: 19 | G29: =AC29-F29 -> 36 | H29: 38 | I29: =AD29-H29 -> 19 | J29: 12 | K29: =AE29-J29 -> -11 | L29: -33 | M29: =K29*(1+M30) -> -10.89 | N29: =L29*(1+N30) -> -33.99 | O29: =M29*(1+O30) -> -11.2167 | P29: =N29*(1+P30) -> -35.0097 | Q29: =O29*(1+Q30) -> -11.553201 | R29: =P29*(1+R30) -> -36.059991 | S29: =Q29*(1+S30) -> -11.899797 | T29: =R29*(1+T30) -> -37.141791 | ... W29: =U29*(1+W30) -> -12.624495 | AC29: 55 | AD29: 57 | AE29: 1 | AF29: =L29+M29 -> -43.89 | AG29: =N29+O29 -> -45.2067 | AH29: =P29+Q29 -> -46.562901 | AI29: =R29+S29 -> -47.959788 | AJ29: =T29+U29 -> -49.398582 | AK29: =V29+W29 -> -50.880539
B30: Scope growth (%) | C30: =IFERROR(C29/#REF!-1, "-") -> - | D30: =IFERROR(D29/#REF!-1, "-") -> - | E30: =IFERROR(E29/#REF!-1, "-") -> - | F30: =F29/C31 -> 0.013049451 | G30: =G29/D31 -> 0.032697548 | H30: =H29/F31 -> 0.021146355 | I30: =I29/G31 -> 0.014253563 | J30: =J29/H31 -> 0.0060331825 | K30: =K29/I31 -> -0.0074475288 | L30: =L29/J31 -> -0.017562533 | M30: -0.01 | N30: 0.03 | O30: 0.03 | P30: 0.03 | Q30: 0.03 | R30: 0.03 | S30: 0.03 | T30: 0.03 | U30: 0.03 | V30: 0.03 | W30: 0.03 | AC30: =AC29/E31 -> 0.021509582 | AD30: =AD29/AC31 -> 0.018210863 | AE30: =AE29/AD31 -> 0.00028860029 | AF30: =AF29/AE29-1 -> -44.89 | AG30: =AG29/AF29-1 -> 0.03 | AH30: =AH29/AG29-1 -> 0.03 | AI30: =AI29/AH29-1 -> 0.03 | AJ30: =AJ29/AI29-1 -> 0.03 | AK30: =AK29/AJ29-1 -> 0.03
B31: Total Sales - Europe | C31: 1456 | D31: =E31-C31 -> 1101 | E31: 2557 | F31: =C31+F25+F27+F29 -> 1797 | G31: =D31+G25+G27+G29 -> 1333 | H31: =F31+H25+H27+H29+1 -> 1989 | I31: =G31+I25+I27+I29 -> 1477 | J31: =H31+J25+J27+J29-1 -> 1879 | K31: =I31+K25+K27+K29 -> 1406 | L31: =J31+L25+L27+L29-1 -> 1816 | M31: =K31+M25+M27+M29 -> 1335.71 | N31: =L31+N25+N27+N29 -> 1752.14 | O31: =M31+O25+O27+O29 -> 1263.3113 | P31: =N31+P25+P27+P29 -> 1686.3642 | Q31: =O31+Q25+Q27+Q29 -> 1188.7406 | R31: =P31+R25+R27+R29 -> 1618.6151 | S31: =Q31+S25+S27+S29 -> 1111.9329 | T31: =R31+T25+T27+T29 -> 1548.8336 | ... W31: =U31+W25+W27+W29 -> 951.33547 | AC31: =E31+AC25+AC27+AC29 -> 3130 | AD31: =AC31+AD25+AD27+AD29 -> 3465 | AE31: =AD31+AE25+AE27+AE29 -> 3285 | AF31: =AE31+AF25+AF27+AF29 -> 3152.71 | AG31: =AF31+AG25+AG27+AG29 -> 3016.4513 | AH31: =AG31+AH25+AH27+AH29 -> 2876.1048 | AI31: =AH31+AI25+AI27+AI29 -> 2731.548 | AJ31: =AI31+AJ25+AJ27+AJ29 -> 2582.6544 | AK31: =AJ31+AK25+AK27+AK29 -> 2429.2941
B32: Growth (%) | C32: =IFERROR(C31/#REF!-1, "-") -> - | D32: =IFERROR(D31/#REF!-1, "-") -> - | E32: =IFERROR(E31/#REF!-1, "-") -> - | F32: =IFERROR(F31/C31-1, "-") -> 0.2342033 | G32: =IFERROR(G31/D31-1, "-") -> 0.21071753 | H32: =IFERROR(H31/F31-1, "-") -> 0.10684474 | I32: =IFERROR(I31/G31-1, "-") -> 0.10802701 | J32: =IFERROR(J31/H31-1, "-") -> -0.055304173 | K32: =IFERROR(K31/I31-1, "-") -> -0.048070413 | L32: =IFERROR(L31/J31-1, "-") -> -0.033528473 | M32: =IFERROR(M31/K31-1, "-") -> -0.049992888 | N32: =IFERROR(N31/L31-1, "-") -> -0.035165198 | O32: =IFERROR(O31/M31-1, "-") -> -0.054202409 | ... W32: =IFERROR(W31/U31-1, "-") -> -0.078895943 | AC32: =IFERROR(AC31/E31-1, "-") -> 0.22409073 | AD32: =IFERROR(AD31/AC31-1, "-") -> 0.10702875 | AE32: =IFERROR(AE31/AD31-1, "-") -> -0.051948052 | AF32: =IFERROR(AF31/AE31-1, "-") -> -0.040270928 | AG32: =IFERROR(AG31/AF31-1, "-") -> -0.043219548 | AH32: =IFERROR(AH31/AG31-1, "-") -> -0.04652701 | AI32: =IFERROR(AI31/AH31-1, "-") -> -0.05026133 | AJ32: =IFERROR(AJ31/AI31-1, "-") -> -0.054508858 | AK32: =IFERROR(AK31/AJ31-1, "-") -> -0.059380909
B34: Total
B35: Organic | F35: =F5+F15+F25 -> 834 | G35: =AC35-F35 -> 642 | H35: =H5+H15+H25 -> 686 | I35: =AD35-H35 -> 382 | J35: =J5+J15+J25 -> -213 | K35: =AE35-J35 -> 63 | L35: =L5+L15+L25 -> -267 | M35: =AF35-L35 -> 62.37 | N35: =N5+N15+N25 -> -275.01 | O35: =AG35-N35 -> 64.2411 | P35: =P5+P15+P25 -> -283.2603 | Q35: =AH35-P35 -> 66.168333 | R35: =R5+R15+R25 -> -291.75811 | S35: =AI35-R35 -> 68.153383 | T35: =T5+T15+T25 -> -300.51085 | U35: =AJ35-T35 -> 70.197984 | V35: =V5+V15+V25 -> -309.52618 | W35: =AK35-V35 -> 72.303924 | AC35: =AC5+AC15+AC25 -> 1476 | AD35: =AD5+AD15+AD25 -> 1068 | AE35: =AE5+AE15+AE25 -> -150 | AF35: =AF5+AF15+AF25 -> -204.63 | AG35: =AG5+AG15+AG25 -> -210.7689 | AH35: =AH5+AH15+AH25 -> -217.09197 | AI35: =AI5+AI15+AI25 -> -223.60473 | AJ35: =AJ5+AJ15+AJ25 -> -230.31287 | AK35: =AK5+AK15+AK25 -> -237.22225
B36: Organic growth (%) | F36: =F35/C41 -> 0.16730191 | G36: =G35/D41 -> 0.16723105 | H36: =H35/F41 -> 0.11511999 | I36: =I35/G41 -> 0.080556727 | J36: =J35/H41 -> -0.029932546 | K36: =K35/I41 -> 0.012547301 | L36: =L35/J41 -> -0.040509786 | M36: =M35/K41 -> 0.012456561 | N36: =N35/L41 -> -0.044528821 | O36: =O35/M41 -> 0.012865872 | ... W36: =W35/U41 -> 0.014655957 | AC36: =AC35/E41 -> 0.16727108 | AD36: =AD35/AC41 -> 0.099803757 | AE36: =AE35/AD41 -> -0.012358903 | AF36: =AF35/AE41 -> -0.017643559 | AG36: =AG35/AF41 -> -0.018870647 | AH36: =AH35/AG41 -> -0.02023712 | AI36: =AI35/AH41 -> -0.021767448 | AJ36: =AJ35/AI41 -> -0.023492181 | AK36: =AK35/AJ41 -> -0.025449962
B37: Fx | F37: =F7+F17+F27 -> 104 | G37: =AC37-F37 -> 212 | H37: =H7+H17+H27 -> 355 | I37: =AD37-H37 -> -236 | J37: =J7+J17+J27 -> -576 | K37: =AE37-J37 -> -208 | L37: =L7+L17+L27 -> -177 | M37: =AF37-L37 -> -205.92 | N37: =N7+N17+N27 -> -182.31 | O37: =AG37-N37 -> -212.0976 | P37: =P7+P17+P27 -> -187.7793 | Q37: =AH37-P37 -> -218.46053 | R37: =R7+R17+R27 -> -193.41268 | S37: =AI37-R37 -> -225.01434 | T37: =T7+T17+T27 -> -199.21506 | U37: =AJ37-T37 -> -231.76477 | V37: =V7+V17+V27 -> -205.19151 | W37: =AK37-V37 -> -238.71772 | AC37: =AC7+AC17+AC27 -> 316 | AD37: =AD7+AD17+AD27 -> 119 | AE37: =AE7+AE17+AE27 -> -784 | AF37: =AF7+AF17+AF27 -> -382.92 | AG37: =AG7+AG17+AG27 -> -394.4076 | AH37: =AH7+AH17+AH27 -> -406.23983 | AI37: =AI7+AI17+AI27 -> -418.42702 | AJ37: =AJ7+AJ17+AJ27 -> -430.97983 | AK37: =AK7+AK17+AK27 -> -443.90923
B38: Fx growth (%) | F38: =F37/C41 -> 0.020862588 | G38: =G37/D41 -> 0.055222714 | H38: =H37/F41 -> 0.059573754 | I38: =I37/G41 -> -0.04976803 | J38: =J37/H41 -> -0.080944351 | K38: =K37/I41 -> -0.041426011 | L38: =L37/J41 -> -0.026854802 | M38: =M37/K41 -> -0.041126423 | N38: =N37/L41 -> -0.029519106 | O38: =O37/M41 -> -0.0424778 | ... W38: =W37/U41 -> -0.048387922 | AC38: =AC37/E41 -> 0.035811423 | AD38: =AD37/AC41 -> 0.011120456 | AE38: =AE37/AD41 -> -0.064595864 | AF38: =AF37/AE41 -> -0.033016037 | AG38: =AG37/AF41 -> -0.035312262 | AH38: =AH37/AG41 -> -0.037869315 | AI38: =AI37/AH41 -> -0.040732987 | AJ38: =AJ37/AI41 -> -0.043960445 | AK38: =AK37/AJ41 -> -0.047624002
B39: Scope | F39: =F9+F19+F29 -> 36 | G39: =AC39-F39 -> 49 | H39: =H9+H19+H29 -> 116 | I39: =AD39-H39 -> 133 | J39: =J9+J19+J29 -> 264 | K39: =AE39-J39 -> 131 | L39: =L9+L19+L29 -> 29 | M39: =AF39-L39 -> 129.69 | N39: =N9+N19+N29 -> 29.87 | O39: =AG39-N39 -> 133.5807 | P39: =P9+P19+P29 -> 30.7661 | Q39: =AH39-P39 -> 137.58812 | R39: =R9+R19+R29 -> 31.689083 | S39: =AI39-R39 -> 141.71576 | T39: =T9+T19+T29 -> 32.639755 | U39: =AJ39-T39 -> 145.96724 | V39: =V9+V19+V29 -> 33.618948 | W39: =AK39-V39 -> 150.34625 | AC39: =AC9+AC19+AC29 -> 85 | AD39: =AD9+AD19+AD29 -> 249 | AE39: =AE9+AE19+AE29 -> 395 | AF39: =AF9+AF19+AF29 -> 158.69 | AG39: =AG9+AG19+AG29 -> 163.4507 | AH39: =AH9+AH19+AH29 -> 168.35422 | AI39: =AI9+AI19+AI29 -> 173.40485 | AJ39: =AJ9+AJ19+AJ29 -> 178.60699 | AK39: =AK9+AK19+AK29 -> 183.9652
B40: Scope growth (%) | F40: =F39/C41 -> 0.007221665 | G40: =G39/D41 -> 0.012763741 | H40: =H39/F41 -> 0.019466353 | I40: =I39/G41 -> 0.028047237 | J40: =J39/H41 -> 0.037099494 | K40: =K39/I41 -> 0.02609042 | L40: =L39/J41 -> 0.0043999393 | M40: =M39/K41 -> 0.025901738 | N40: =N39/L41 -> 0.0048364637 | O40: =O39/M41 -> 0.026752845 | ... W40: =W39/U41 -> 0.030475085 | AC40: =AC39/E41 -> 0.0096328196 | AD40: =AD39/AC41 -> 0.023268853 | AE40: =AE39/AD41 -> 0.03254511 | AF40: =AF39/AE41 -> 0.013682531 | AG40: =AG39/AF41 -> 0.014634135 | AH40: =AH39/AG41 -> 0.015693831 | AI40: =AI39/AH41 -> 0.016880596 | AJ40: =AJ39/AI41 -> 0.018218121 | AK40: =AK39/AJ41 -> 0.019736375
B41: Total Sales | C41: =C11+C31+C21 -> 4985 | D41: =D11+D31+D21 -> 3839 | E41: =E11+E31+E21 -> 8824 | F41: =F11+F31+F21 -> 5959 | G41: =D41+G35+G37+G39 -> 4742 | H41: =F41+H35+H37+H39 -> 7116 | I41: =I11+I31+I21 -> 5021 | J41: =H41+J35+J37+J39 -> 6591 | K41: =K11+K31+K21 -> 5007 | L41: =J41+L35+L37+L39 -> 6176 | M41: =M11+M31+M21 -> 4993.14 | N41: =L41+N35+N37+N39 -> 5748.55 | O41: =O11+O31+O21 -> 4978.8642 | P41: =N41+P35+P37+P39 -> 5308.2765 | Q41: =Q11+Q31+Q21 -> 4964.1601 | R41: =P41+R35+R37+R39 -> 4854.7948 | S41: =S11+S31+S21 -> 4949.0149 | T41: =R41+T35+T37+T39 -> 4387.7086 | U41: =U11+U31+U21 -> 4933.4154 | V41: =T41+V35+V37+V39 -> 3906.6099 | W41: =W11+W31+W21 -> 4917.3478 | AC41: =E41+AC35+AC37+AC39 -> 10701 | AD41: =AC41+AD35+AD37+AD39 -> 12137 | AE41: =AD41+AE35+AE37+AE39 -> 11598 | AF41: =AE41+AF35+AF37+AF39 -> 11169.14 | AG41: =AF41+AG35+AG37+AG39 -> 10727.414 | AH41: =AG41+AH35+AH37+AH39 -> 10272.437 | AI41: =AH41+AI35+AI37+AI39 -> 9803.8097 | AJ41: =AI41+AJ35+AJ37+AJ39 -> 9321.124 | AK41: =AJ41+AK35+AK37+AK39 -> 8823.9577
B42: Growth (%) | C42: =IFERROR(C41/#REF!-1, "-") -> - | D42: =IFERROR(D41/#REF!-1, "-") -> - | E42: =IFERROR(E41/#REF!-1, "-") -> - | F42: =IFERROR(F41/C41-1, "-") -> 0.19538616 | G42: =IFERROR(G41/D41-1, "-") -> 0.2352175 | H42: =IFERROR(H41/F41-1, "-") -> 0.19416009 | I42: =IFERROR(I41/G41-1, "-") -> 0.058835934 | J42: =IFERROR(J41/H41-1, "-") -> -0.073777403 | K42: =IFERROR(K41/I41-1, "-") -> -0.0027882892 | L42: =IFERROR(L41/J41-1, "-") -> -0.062964649 | M42: =IFERROR(M41/K41-1, "-") -> -0.0027681246 | N42: =IFERROR(N41/L41-1, "-") -> -0.069211464 | O42: =IFERROR(O41/M41-1, "-") -> -0.0028590827 | ... W42: =IFERROR(W41/U41-1, "-") -> -0.0032568794 | AC42: =IFERROR(AC41/E41-1, "-") -> 0.21271532 | AD42: =IFERROR(AD41/AC41-1, "-") -> 0.13419307 | AE42: =IFERROR(AE41/AD41-1, "-") -> -0.044409656 | AF42: =IFERROR(AF41/AE41-1, "-") -> -0.036977065 | AG42: =IFERROR(AG41/AF41-1, "-") -> -0.039548775 | AH42: =IFERROR(AH41/AG41-1, "-") -> -0.042412604 | AI42: =IFERROR(AI41/AH41-1, "-") -> -0.045619839 | AJ42: =IFERROR(AJ41/AI41-1, "-") -> -0.049234504 | AK42: =IFERROR(AK41/AJ41-1, "-") -> -0.053337589

Sheet Revenue Model-Segment
B2: In Euro millions | C2: H1'21 | D2: H2'21 | E2: FY21 | F2: H1'22 | G2: H2'22 | H2: H1'23 | I2: H2'23 | J2: H1'24 | K2: H2'24 | L2: H1'25 | M2: H2'25 | N2: H1'26 | O2: H2'26 | P2: H1'27 | Q2: H2'27 | R2: H1'28 | S2: H2'28 | T2: H1'29 | U2: H2'29 | V2: H1'30 | W2: H2'30 | AC2: FY22 | AD2: FY23 | AE2: FY24 | AF2: FY25 | AG2: FY26 | AH2: FY27 | AI2: FY28 | AJ2: FY29 | AK2: FY30
B4: Americas
B5: Organic | G5: =AC5-F5 -> 0 | I5: =AD5-H5 -> 0 | K5: =AE5-J5 -> 0 | M5: =K5*(1+M6) -> 0 | N5: =L5*(1+N6) -> 0 | O5: =M5*(1+O6) -> 0 | P5: =N5*(1+P6) -> 0 | Q5: =O5*(1+Q6) -> 0 | R5: =P5*(1+R6) -> 0 | S5: =Q5*(1+S6) -> 0 | T5: =R5*(1+T6) -> 0 | ... W5: =U5*(1+W6) -> 0 | AF5: =L5+M5 -> 0 | AG5: =N5+O5 -> 0 | AH5: =P5+Q5 -> 0 | AI5: =R5+S5 -> 0 | AJ5: =T5+U5 -> 0 | AK5: =V5+W5 -> 0
B6: Organic growth (%) | C6: =IFERROR(C5/#REF!-1, "-") -> - | D6: =IFERROR(D5/#REF!-1, "-") -> - | E6: =IFERROR(E5/#REF!-1, "-") -> - | F6: =F5/C11 -> #DIV/0! | G6: =G5/D11 -> #DIV/0! | H6: =H5/F11 -> 0 | I6: =I5/G11 -> #DIV/0! | J6: =J5/H11 -> #DIV/0! | K6: =K5/I11 -> #DIV/0! | L6: =L5/J11 -> #DIV/0! | AC6: =AC5/E11 -> #DIV/0! | AD6: =AD5/AC11 -> 0 | AE6: =AE5/AD11 -> 0 | AF6: =AF5/AE5-1 -> #DIV/0! | AG6: =AG5/AF5-1 -> #DIV/0! | AH6: =AH5/AG5-1 -> #DIV/0! | AI6: =AI5/AH5-1 -> #DIV/0! | AJ6: =AJ5/AI5-1 -> #DIV/0! | AK6: =AK5/AJ5-1 -> #DIV/0!
B7: Fx | G7: =AC7-F7 -> 0 | I7: =AD7-H7 -> 0 | K7: =AE7-J7 -> 0 | M7: =K7*(1+M8) -> 0 | N7: =L7*(1+N8) -> 0 | O7: =M7*(1+O8) -> 0 | P7: =N7*(1+P8) -> 0 | Q7: =O7*(1+Q8) -> 0 | R7: =P7*(1+R8) -> 0 | S7: =Q7*(1+S8) -> 0 | T7: =R7*(1+T8) -> 0 | ... W7: =U7*(1+W8) -> 0 | AF7: =L7+M7 -> 0 | AG7: =N7+O7 -> 0 | AH7: =P7+Q7 -> 0 | AI7: =R7+S7 -> 0 | AJ7: =T7+U7 -> 0 | AK7: =V7+W7 -> 0
B8: Fx growth (%) | C8: =IFERROR(C7/#REF!-1, "-") -> - | D8: =IFERROR(D7/#REF!-1, "-") -> - | E8: =IFERROR(E7/#REF!-1, "-") -> - | F8: =F7/C11 -> #DIV/0! | G8: =G7/D11 -> #DIV/0! | H8: =H7/F11 -> 0 | I8: =I7/G11 -> #DIV/0! | J8: =J7/H11 -> #DIV/0! | K8: =K7/I11 -> #DIV/0! | L8: =L7/J11 -> #DIV/0! | AC8: =AC7/E11 -> #DIV/0! | AD8: =AD7/AC11 -> 0 | AE8: =AE7/AD11 -> 0 | AF8: =AF7/AE7-1 -> #DIV/0! | AG8: =AG7/AF7-1 -> #DIV/0! | AH8: =AH7/AG7-1 -> #DIV/0! | AI8: =AI7/AH7-1 -> #DIV/0! | AJ8: =AJ7/AI7-1 -> #DIV/0! | AK8: =AK7/AJ7-1 -> #DIV/0!
B9: Scope | G9: =AC9-F9 -> 0 | I9: =AD9-H9 -> 0 | K9: =AE9-J9 -> 0 | M9: =K9*(1+M10) -> 0 | N9: =L9*(1+N10) -> 0 | O9: =M9*(1+O10) -> 0 | P9: =N9*(1+P10) -> 0 | Q9: =O9*(1+Q10) -> 0 | R9: =P9*(1+R10) -> 0 | S9: =Q9*(1+S10) -> 0 | T9: =R9*(1+T10) -> 0 | ... W9: =U9*(1+W10) -> 0 | AF9: =L9+M9 -> 0 | AG9: =N9+O9 -> 0 | AH9: =P9+Q9 -> 0 | AI9: =R9+S9 -> 0 | AJ9: =T9+U9 -> 0 | AK9: =V9+W9 -> 0
B10: Scope growth (%) | C10: =IFERROR(C9/#REF!-1, "-") -> - | D10: =IFERROR(D9/#REF!-1, "-") -> - | E10: =IFERROR(E9/#REF!-1, "-") -> - | F10: =F9/C11 -> #DIV/0! | G10: =G9/D11 -> #DIV/0! | H10: =H9/F11 -> 0 | I10: =I9/G11 -> #DIV/0! | J10: =J9/H11 -> #DIV/0! | K10: =K9/I11 -> #DIV/0! | L10: =L9/J11 -> #DIV/0! | AC10: =AC9/E11 -> #DIV/0! | AD10: =AD9/AC11 -> 0 | AE10: =AE9/AD11 -> 0 | AF10: =IFERROR(AF9/AE9-1, "-") -> - | AG10: =IFERROR(AG9/AF9-1, "-") -> - | AH10: =IFERROR(AH9/AG9-1, "-") -> - | AI10: =IFERROR(AI9/AH9-1, "-") -> - | AJ10: =IFERROR(AJ9/AI9-1, "-") -> - | AK10: =IFERROR(AK9/AJ9-1, "-") -> -
B11: Total Sales - Americas | D11: =E11-C11 -> 0 | F11: =C11+F5+F7+F9+1 -> 1 | G11: =D11+G5+G7+G9 -> 0 | H11: =F11+H5+H7+H9-1 -> 0 | I11: =G11+I5+I7+I9 -> 0 | J11: =H11+J5+J7+J9 -> 0 | K11: =I11+K5+K7+K9 -> 0 | L11: =J11+L5+L7+L9 -> 0 | M11: =K11+M5+M7+M9 -> 0 | N11: =L11+N5+N7+N9 -> 0 | O11: =M11+O5+O7+O9 -> 0 | P11: =N11+P5+P7+P9 -> 0 | ... W11: =U11+W5+W7+W9 -> 0 | AC11: =E11+AC5+AC7+AC9+1 -> 1 | AD11: =AC11+AD5+AD7+AD9 -> 1 | AE11: =AD11+AE5+AE7+AE9 -> 1 | AF11: =AE11+AF5+AF7+AF9 -> 1 | AG11: =AF11+AG5+AG7+AG9 -> 1 | AH11: =AG11+AH5+AH7+AH9 -> 1 | AI11: =AH11+AI5+AI7+AI9 -> 1 | AJ11: =AI11+AJ5+AJ7+AJ9 -> 1 | AK11: =AJ11+AK5+AK7+AK9 -> 1
B12: Growth (%) | C12: =IFERROR(C11/#REF!-1, "-") -> - | D12: =IFERROR(D11/#REF!-1, "-") -> - | E12: =IFERROR(E11/#REF!-1, "-") -> - | F12: =IFERROR(F11/C11-1, "-") -> - | G12: =IFERROR(G11/D11-1, "-") -> - | H12: =IFERROR(H11/F11-1, "-") -> -1 | I12: =IFERROR(I11/G11-1, "-") -> - | J12: =IFERROR(J11/H11-1, "-") -> - | K12: =IFERROR(K11/I11-1, "-") -> - | L12: =IFERROR(L11/J11-1, "-") -> - | M12: =IFERROR(M11/K11-1, "-") -> - | N12: =IFERROR(N11/L11-1, "-") -> - | O12: =IFERROR(O11/M11-1, "-") -> - | ... W12: =IFERROR(W11/U11-1, "-") -> - | AC12: =IFERROR(AC11/E11-1, "-") -> - | AD12: =IFERROR(AD11/AC11-1, "-") -> 0 | AE12: =IFERROR(AE11/AD11-1, "-") -> 0 | AF12: =IFERROR(AF11/AE11-1, "-") -> 0 | AG12: =IFERROR(AG11/AF11-1, "-") -> 0 | AH12: =IFERROR(AH11/AG11-1, "-") -> 0 | AI12: =IFERROR(AI11/AH11-1, "-") -> 0 | AJ12: =IFERROR(AJ11/AI11-1, "-") -> 0 | AK12: =IFERROR(AK11/AJ11-1, "-") -> 0
B14: Asia/Row
B15: Organic | G15: =AC15-F15 -> 0 | I15: =AD15-H15 -> 0 | K15: =AE15-J15 -> 0 | M15: =K15*(1+M16) -> 0 | N15: =L15*(1+N16) -> 0 | O15: =M15*(1+O16) -> 0 | P15: =N15*(1+P16) -> 0 | Q15: =O15*(1+Q16) -> 0 | R15: =P15*(1+R16) -> 0 | S15: =Q15*(1+S16) -> 0 | T15: =R15*(1+T16) -> 0 | ... W15: =U15*(1+W16) -> 0 | AF15: =L15+M15 -> 0 | AG15: =N15+O15 -> 0 | AH15: =P15+Q15 -> 0 | AI15: =R15+S15 -> 0 | AJ15: =T15+U15 -> 0 | AK15: =V15+W15 -> 0
B16: Organic growth (%) | C16: =IFERROR(C15/#REF!-1, "-") -> - | D16: =IFERROR(D15/#REF!-1, "-") -> - | E16: =IFERROR(E15/#REF!-1, "-") -> - | F16: =F15/C21 -> #DIV/0! | G16: =G15/D21 -> #DIV/0! | H16: =H15/F21 -> 0 | I16: =I15/G21 -> #DIV/0! | J16: =J15/H21 -> 0 | K16: =K15/I21 -> #DIV/0! | L16: =L15/J21 -> 0 | AC16: =AC15/E21 -> #DIV/0! | AD16: =AD15/AC21 -> 0 | AE16: =AE15/AD21 -> 0 | AF16: =AF15/AE15-1 -> #DIV/0! | AG16: =AG15/AF15-1 -> #DIV/0! | AH16: =AH15/AG15-1 -> #DIV/0! | AI16: =AI15/AH15-1 -> #DIV/0! | AJ16: =AJ15/AI15-1 -> #DIV/0! | AK16: =AK15/AJ15-1 -> #DIV/0!
B17: Fx | G17: =AC17-F17 -> 0 | I17: =AD17-H17 -> 0 | K17: =AE17-J17 -> 0 | M17: =K17*(1+M18) -> 0 | N17: =L17*(1+N18) -> 0 | O17: =M17*(1+O18) -> 0 | P17: =N17*(1+P18) -> 0 | Q17: =O17*(1+Q18) -> 0 | R17: =P17*(1+R18) -> 0 | S17: =Q17*(1+S18) -> 0 | T17: =R17*(1+T18) -> 0 | ... W17: =U17*(1+W18) -> 0 | AF17: =L17+M17 -> 0 | AG17: =N17+O17 -> 0 | AH17: =P17+Q17 -> 0 | AI17: =R17+S17 -> 0 | AJ17: =T17+U17 -> 0 | AK17: =V17+W17 -> 0
B18: Fx growth (%) | C18: =IFERROR(C17/#REF!-1, "-") -> - | D18: =IFERROR(D17/#REF!-1, "-") -> - | E18: =IFERROR(E17/#REF!-1, "-") -> - | F18: =F17/C21 -> #DIV/0! | G18: =G17/D21 -> #DIV/0! | H18: =H17/F21 -> 0 | I18: =I17/G21 -> #DIV/0! | J18: =J17/H21 -> 0 | K18: =K17/I21 -> #DIV/0! | L18: =L17/J21 -> 0 | AC18: =AC17/E21 -> #DIV/0! | AD18: =AD17/AC21 -> 0 | AE18: =AE17/AD21 -> 0 | AF18: =AF17/AE17-1 -> #DIV/0! | AG18: =AG17/AF17-1 -> #DIV/0! | AH18: =AH17/AG17-1 -> #DIV/0! | AI18: =AI17/AH17-1 -> #DIV/0! | AJ18: =AJ17/AI17-1 -> #DIV/0! | AK18: =AK17/AJ17-1 -> #DIV/0!
B19: Scope | G19: =AC19-F19 -> 0 | I19: =AD19-H19 -> 0 | K19: =AE19-J19 -> 0 | M19: =K19*(1+M20) -> 0 | N19: =L19*(1+N20) -> 0 | O19: =M19*(1+O20) -> 0 | P19: =N19*(1+P20) -> 0 | Q19: =O19*(1+Q20) -> 0 | R19: =P19*(1+R20) -> 0 | S19: =Q19*(1+S20) -> 0 | T19: =R19*(1+T20) -> 0 | ... W19: =U19*(1+W20) -> 0 | AF19: =L19+M19 -> 0 | AG19: =N19+O19 -> 0 | AH19: =P19+Q19 -> 0 | AI19: =R19+S19 -> 0 | AJ19: =T19+U19 -> 0 | AK19: =V19+W19 -> 0
B20: Scope growth (%) | C20: =IFERROR(C19/#REF!-1, "-") -> - | D20: =IFERROR(D19/#REF!-1, "-") -> - | E20: =IFERROR(E19/#REF!-1, "-") -> - | F20: =F19/C21 -> #DIV/0! | G20: =G19/D21 -> #DIV/0! | H20: =H19/F21 -> 0 | I20: =I19/G21 -> #DIV/0! | J20: =J19/H21 -> 0 | K20: =K19/I21 -> #DIV/0! | L20: =L19/J21 -> 0 | AC20: =AC19/E21 -> #DIV/0! | AD20: =AD19/AC21 -> 0 | AE20: =AE19/AD21 -> 0 | AF20: =IFERROR(AF19/AE19-1, "-") -> - | AG20: =IFERROR(AG19/AF19-1, "-") -> - | AH20: =IFERROR(AH19/AG19-1, "-") -> - | AI20: =IFERROR(AI19/AH19-1, "-") -> - | AJ20: =IFERROR(AJ19/AI19-1, "-") -> - | AK20: =IFERROR(AK19/AJ19-1, "-") -> -
B21: Total Sales - Asia/Row | D21: =E21-C21 -> 0 | F21: =C21+F15+F17+F19-1 -> -1 | G21: =D21+G15+G17+G19 -> 0 | H21: =F21+H15+H17+H19 -> -1 | I21: =G21+I15+I17+I19 -> 0 | J21: =H21+J15+J17+J19-1 -> -2 | K21: =I21+K15+K17+K19 -> 0 | L21: =J21+L15+L17+L19 -> -2 | M21: =K21+M15+M17+M19 -> 0 | N21: =L21+N15+N17+N19 -> -2 | O21: =M21+O15+O17+O19 -> 0 | P21: =N21+P15+P17+P19 -> -2 | Q21: =O21+Q15+Q17+Q19 -> 0 | R21: =P21+R15+R17+R19 -> -2 | ... W21: =U21+W15+W17+W19 -> 0 | AC21: =E21+AC15+AC17+AC19-1 -> -1 | AD21: =AC21+AD15+AD17+AD19 -> -1 | AE21: =AD21+AE15+AE17+AE19 -> -1 | AF21: =AE21+AF15+AF17+AF19 -> -1 | AG21: =AF21+AG15+AG17+AG19 -> -1 | AH21: =AG21+AH15+AH17+AH19 -> -1 | AI21: =AH21+AI15+AI17+AI19 -> -1 | AJ21: =AI21+AJ15+AJ17+AJ19 -> -1 | AK21: =AJ21+AK15+AK17+AK19 -> -1
B22: Growth (%) | C22: =IFERROR(C21/#REF!-1, "-") -> - | D22: =IFERROR(D21/#REF!-1, "-") -> - | E22: =IFERROR(E21/#REF!-1, "-") -> - | F22: =IFERROR(F21/C21-1, "-") -> - | G22: =IFERROR(G21/D21-1, "-") -> - | H22: =IFERROR(H21/F21-1, "-") -> 0 | I22: =IFERROR(I21/G21-1, "-") -> - | J22: =IFERROR(J21/H21-1, "-") -> 1 | K22: =IFERROR(K21/I21-1, "-") -> - | L22: =IFERROR(L21/J21-1, "-") -> 0 | M22: =IFERROR(M21/K21-1, "-") -> - | N22: =IFERROR(N21/L21-1, "-") -> 0 | O22: =IFERROR(O21/M21-1, "-") -> - | ... W22: =IFERROR(W21/U21-1, "-") -> - | AC22: =IFERROR(AC21/E21-1, "-") -> - | AD22: =IFERROR(AD21/AC21-1, "-") -> 0 | AE22: =IFERROR(AE21/AD21-1, "-") -> 0 | AF22: =IFERROR(AF21/AE21-1, "-") -> 0 | AG22: =IFERROR(AG21/AF21-1, "-") -> 0 | AH22: =IFERROR(AH21/AG21-1, "-") -> 0 | AI22: =IFERROR(AI21/AH21-1, "-") -> 0 | AJ22: =IFERROR(AJ21/AI21-1, "-") -> 0 | AK22: =IFERROR(AK21/AJ21-1, "-") -> 0
B24: Europe
B25: Organic | G25: =AC25-F25 -> 0 | I25: =AD25-H25 -> 0 | K25: =AE25-J25 -> 0 | M25: =K25*(1+M26) -> 0 | N25: =L25*(1+N26) -> 0 | O25: =M25*(1+O26) -> 0 | P25: =N25*(1+P26) -> 0 | Q25: =O25*(1+Q26) -> 0 | R25: =P25*(1+R26) -> 0 | S25: =Q25*(1+S26) -> 0 | T25: =R25*(1+T26) -> 0 | ... W25: =U25*(1+W26) -> 0 | AF25: =L25+M25 -> 0 | AG25: =N25+O25 -> 0 | AH25: =P25+Q25 -> 0 | AI25: =R25+S25 -> 0 | AJ25: =T25+U25 -> 0 | AK25: =V25+W25 -> 0
B26: Organic growth (%) | C26: =IFERROR(C25/#REF!-1, "-") -> - | D26: =IFERROR(D25/#REF!-1, "-") -> - | E26: =IFERROR(E25/#REF!-1, "-") -> - | F26: =F25/C31 -> #DIV/0! | G26: =G25/D31 -> #DIV/0! | H26: =H25/F31 -> #DIV/0! | I26: =I25/G31 -> #DIV/0! | J26: =J25/H31 -> 0 | K26: =K25/I31 -> #DIV/0! | L26: =L25/J31 -> #DIV/0! | AC26: =AC25/E31 -> #DIV/0! | AD26: =AD25/AC31 -> #DIV/0! | AE26: =AE25/AD31 -> #DIV/0! | AF26: =AF25/AE25-1 -> #DIV/0! | AG26: =AG25/AF25-1 -> #DIV/0! | AH26: =AH25/AG25-1 -> #DIV/0! | AI26: =AI25/AH25-1 -> #DIV/0! | AJ26: =AJ25/AI25-1 -> #DIV/0! | AK26: =AK25/AJ25-1 -> #DIV/0!
B27: Fx | G27: =AC27-F27 -> 0 | I27: =AD27-H27 -> 0 | K27: =AE27-J27 -> 0 | M27: =K27*(1+M28) -> 0 | N27: =L27*(1+N28) -> 0 | O27: =M27*(1+O28) -> 0 | P27: =N27*(1+P28) -> 0 | Q27: =O27*(1+Q28) -> 0 | R27: =P27*(1+R28) -> 0 | S27: =Q27*(1+S28) -> 0 | T27: =R27*(1+T28) -> 0 | ... W27: =U27*(1+W28) -> 0 | AF27: =L27+M27 -> 0 | AG27: =N27+O27 -> 0 | AH27: =P27+Q27 -> 0 | AI27: =R27+S27 -> 0 | AJ27: =T27+U27 -> 0 | AK27: =V27+W27 -> 0
B28: Fx growth (%) | C28: =IFERROR(C27/#REF!-1, "-") -> - | D28: =IFERROR(D27/#REF!-1, "-") -> - | E28: =IFERROR(E27/#REF!-1, "-") -> - | F28: =F27/C31 -> #DIV/0! | G28: =G27/D31 -> #DIV/0! | H28: =H27/F31 -> #DIV/0! | I28: =I27/G31 -> #DIV/0! | J28: =J27/H31 -> 0 | K28: =K27/I31 -> #DIV/0! | L28: =L27/J31 -> #DIV/0! | AC28: =AC27/E31 -> #DIV/0! | AD28: =AD27/AC31 -> #DIV/0! | AE28: =AE27/AD31 -> #DIV/0! | AF28: =AF27/AE27-1 -> #DIV/0! | AG28: =AG27/AF27-1 -> #DIV/0! | AH28: =AH27/AG27-1 -> #DIV/0! | AI28: =AI27/AH27-1 -> #DIV/0! | AJ28: =AJ27/AI27-1 -> #DIV/0! | AK28: =AK27/AJ27-1 -> #DIV/0!
B29: Scope | G29: =AC29-F29 -> 0 | I29: =AD29-H29 -> 0 | K29: =AE29-J29 -> 0 | M29: =K29*(1+M30) -> 0 | N29: =L29*(1+N30) -> 0 | O29: =M29*(1+O30) -> 0 | P29: =N29*(1+P30) -> 0 | Q29: =O29*(1+Q30) -> 0 | R29: =P29*(1+R30) -> 0 | S29: =Q29*(1+S30) -> 0 | T29: =R29*(1+T30) -> 0 | ... W29: =U29*(1+W30) -> 0 | AF29: =L29+M29 -> 0 | AG29: =N29+O29 -> 0 | AH29: =P29+Q29 -> 0 | AI29: =R29+S29 -> 0 | AJ29: =T29+U29 -> 0 | AK29: =V29+W29 -> 0
B30: Scope growth (%) | C30: =IFERROR(C29/#REF!-1, "-") -> - | D30: =IFERROR(D29/#REF!-1, "-") -> - | E30: =IFERROR(E29/#REF!-1, "-") -> - | F30: =F29/C31 -> #DIV/0! | G30: =G29/D31 -> #DIV/0! | H30: =H29/F31 -> #DIV/0! | I30: =I29/G31 -> #DIV/0! | J30: =J29/H31 -> 0 | K30: =K29/I31 -> #DIV/0! | L30: =L29/J31 -> #DIV/0! | AC30: =AC29/E31 -> #DIV/0! | AD30: =AD29/AC31 -> #DIV/0! | AE30: =AE29/AD31 -> #DIV/0! | AF30: =AF29/AE29-1 -> #DIV/0! | AG30: =AG29/AF29-1 -> #DIV/0! | AH30: =AH29/AG29-1 -> #DIV/0! | AI30: =AI29/AH29-1 -> #DIV/0! | AJ30: =AJ29/AI29-1 -> #DIV/0! | AK30: =AK29/AJ29-1 -> #DIV/0!
B31: Total Sales - Europe | D31: =E31-C31 -> 0 | F31: =C31+F25+F27+F29 -> 0 | G31: =D31+G25+G27+G29 -> 0 | H31: =F31+H25+H27+H29+1 -> 1 | I31: =G31+I25+I27+I29 -> 0 | J31: =H31+J25+J27+J29-1 -> 0 | K31: =I31+K25+K27+K29 -> 0 | L31: =J31+L25+L27+L29-1 -> -1 | M31: =K31+M25+M27+M29 -> 0 | N31: =L31+N25+N27+N29 -> -1 | O31: =M31+O25+O27+O29 -> 0 | P31: =N31+P25+P27+P29 -> -1 | Q31: =O31+Q25+Q27+Q29 -> 0 | R31: =P31+R25+R27+R29 -> -1 | S31: =Q31+S25+S27+S29 -> 0 | T31: =R31+T25+T27+T29 -> -1 | ... W31: =U31+W25+W27+W29 -> 0 | AC31: =E31+AC25+AC27+AC29 -> 0 | AD31: =AC31+AD25+AD27+AD29 -> 0 | AE31: =AD31+AE25+AE27+AE29 -> 0 | AF31: =AE31+AF25+AF27+AF29 -> 0 | AG31: =AF31+AG25+AG27+AG29 -> 0 | AH31: =AG31+AH25+AH27+AH29 -> 0 | AI31: =AH31+AI25+AI27+AI29 -> 0 | AJ31: =AI31+AJ25+AJ27+AJ29 -> 0 | AK31: =AJ31+AK25+AK27+AK29 -> 0
B32: Growth (%) | C32: =IFERROR(C31/#REF!-1, "-") -> - | D32: =IFERROR(D31/#REF!-1, "-") -> - | E32: =IFERROR(E31/#REF!-1, "-") -> - | F32: =IFERROR(F31/C31-1, "-") -> - | G32: =IFERROR(G31/D31-1, "-") -> - | H32: =IFERROR(H31/F31-1, "-") -> - | I32: =IFERROR(I31/G31-1, "-") -> - | J32: =IFERROR(J31/H31-1, "-") -> -1 | K32: =IFERROR(K31/I31-1, "-") -> - | L32: =IFERROR(L31/J31-1, "-") -> - | M32: =IFERROR(M31/K31-1, "-") -> - | N32: =IFERROR(N31/L31-1, "-") -> 0 | O32: =IFERROR(O31/M31-1, "-") -> - | ... W32: =IFERROR(W31/U31-1, "-") -> - | AC32: =IFERROR(AC31/E31-1, "-") -> - | AD32: =IFERROR(AD31/AC31-1, "-") -> - | AE32: =IFERROR(AE31/AD31-1, "-") -> - | AF32: =IFERROR(AF31/AE31-1, "-") -> - | AG32: =IFERROR(AG31/AF31-1, "-") -> - | AH32: =IFERROR(AH31/AG31-1, "-") -> - | AI32: =IFERROR(AI31/AH31-1, "-") -> - | AJ32: =IFERROR(AJ31/AI31-1, "-") -> - | AK32: =IFERROR(AK31/AJ31-1, "-") -> -
B34: Total
B35: Organic | F35: =F5+F15+F25 -> 0 | G35: =AC35-F35 -> 0 | H35: =H5+H15+H25 -> 0 | I35: =AD35-H35 -> 0 | J35: =J5+J15+J25 -> 0 | K35: =AE35-J35 -> 0 | L35: =L5+L15+L25 -> 0 | M35: =AF35-L35 -> 0 | N35: =N5+N15+N25 -> 0 | O35: =AG35-N35 -> 0 | P35: =P5+P15+P25 -> 0 | Q35: =AH35-P35 -> 0 | R35: =R5+R15+R25 -> 0 | S35: =AI35-R35 -> 0 | T35: =T5+T15+T25 -> 0 | U35: =AJ35-T35 -> 0 | V35: =V5+V15+V25 -> 0 | W35: =AK35-V35 -> 0 | AC35: =AC5+AC15+AC25 -> 0 | AD35: =AD5+AD15+AD25 -> 0 | AE35: =AE5+AE15+AE25 -> 0 | AF35: =AF5+AF15+AF25 -> 0 | AG35: =AG5+AG15+AG25 -> 0 | AH35: =AH5+AH15+AH25 -> 0 | AI35: =AI5+AI15+AI25 -> 0 | AJ35: =AJ5+AJ15+AJ25 -> 0 | AK35: =AK5+AK15+AK25 -> 0
B36: Organic growth (%) | F36: =F35/C41 -> #DIV/0! | G36: =G35/D41 -> #DIV/0! | H36: =H35/F41 -> #DIV/0! | I36: =I35/G41 -> #DIV/0! | J36: =J35/H41 -> #DIV/0! | K36: =K35/I41 -> #DIV/0! | L36: =L35/J41 -> #DIV/0! | M36: =M35/K41 -> #DIV/0! | N36: =N35/L41 -> #DIV/0! | O36: =O35/M41 -> #DIV/0! | ... W36: =W35/U41 -> #DIV/0! | AC36: =AC35/E41 -> #DIV/0! | AD36: =AD35/AC41 -> #DIV/0! | AE36: =AE35/AD41 -> #DIV/0! | AF36: =AF35/AE41 -> #DIV/0! | AG36: =AG35/AF41 -> #DIV/0! | AH36: =AH35/AG41 -> #DIV/0! | AI36: =AI35/AH41 -> #DIV/0! | AJ36: =AJ35/AI41 -> #DIV/0! | AK36: =AK35/AJ41 -> #DIV/0!
B37: Fx | F37: =F7+F17+F27 -> 0 | G37: =AC37-F37 -> 0 | H37: =H7+H17+H27 -> 0 | I37: =AD37-H37 -> 0 | J37: =J7+J17+J27 -> 0 | K37: =AE37-J37 -> 0 | L37: =L7+L17+L27 -> 0 | M37: =AF37-L37 -> 0 | N37: =N7+N17+N27 -> 0 | O37: =AG37-N37 -> 0 | P37: =P7+P17+P27 -> 0 | Q37: =AH37-P37 -> 0 | R37: =R7+R17+R27 -> 0 | S37: =AI37-R37 -> 0 | T37: =T7+T17+T27 -> 0 | U37: =AJ37-T37 -> 0 | V37: =V7+V17+V27 -> 0 | W37: =AK37-V37 -> 0 | AC37: =AC7+AC17+AC27 -> 0 | AD37: =AD7+AD17+AD27 -> 0 | AE37: =AE7+AE17+AE27 -> 0 | AF37: =AF7+AF17+AF27 -> 0 | AG37: =AG7+AG17+AG27 -> 0 | AH37: =AH7+AH17+AH27 -> 0 | AI37: =AI7+AI17+AI27 -> 0 | AJ37: =AJ7+AJ17+AJ27 -> 0 | AK37: =AK7+AK17+AK27 -> 0
B38: Fx growth (%) | F38: =F37/C41 -> #DIV/0! | G38: =G37/D41 -> #DIV/0! | H38: =H37/F41 -> #DIV/0! | I38: =I37/G41 -> #DIV/0! | J38: =J37/H41 -> #DIV/0! | K38: =K37/I41 -> #DIV/0! | L38: =L37/J41 -> #DIV/0! | M38: =M37/K41 -> #DIV/0! | N38: =N37/L41 -> #DIV/0! | O38: =O37/M41 -> #DIV/0! | ... W38: =W37/U41 -> #DIV/0! | AC38: =AC37/E41 -> #DIV/0! | AD38: =AD37/AC41 -> #DIV/0! | AE38: =AE37/AD41 -> #DIV/0! | AF38: =AF37/AE41 -> #DIV/0! | AG38: =AG37/AF41 -> #DIV/0! | AH38: =AH37/AG41 -> #DIV/0! | AI38: =AI37/AH41 -> #DIV/0! | AJ38: =AJ37/AI41 -> #DIV/0! | AK38: =AK37/AJ41 -> #DIV/0!
B39: Scope | F39: =F9+F19+F29 -> 0 | G39: =AC39-F39 -> 0 | H39: =H9+H19+H29 -> 0 | I39: =AD39-H39 -> 0 | J39: =J9+J19+J29 -> 0 | K39: =AE39-J39 -> 0 | L39: =L9+L19+L29 -> 0 | M39: =AF39-L39 -> 0 | N39: =N9+N19+N29 -> 0 | O39: =AG39-N39 -> 0 | P39: =P9+P19+P29 -> 0 | Q39: =AH39-P39 -> 0 | R39: =R9+R19+R29 -> 0 | S39: =AI39-R39 -> 0 | T39: =T9+T19+T29 -> 0 | U39: =AJ39-T39 -> 0 | V39: =V9+V19+V29 -> 0 | W39: =AK39-V39 -> 0 | AC39: =AC9+AC19+AC29 -> 0 | AD39: =AD9+AD19+AD29 -> 0 | AE39: =AE9+AE19+AE29 -> 0 | AF39: =AF9+AF19+AF29 -> 0 | AG39: =AG9+AG19+AG29 -> 0 | AH39: =AH9+AH19+AH29 -> 0 | AI39: =AI9+AI19+AI29 -> 0 | AJ39: =AJ9+AJ19+AJ29 -> 0 | AK39: =AK9+AK19+AK29 -> 0
B40: Scope growth (%) | F40: =F39/C41 -> #DIV/0! | G40: =G39/D41 -> #DIV/0! | H40: =H39/F41 -> #DIV/0! | I40: =I39/G41 -> #DIV/0! | J40: =J39/H41 -> #DIV/0! | K40: =K39/I41 -> #DIV/0! | L40: =L39/J41 -> #DIV/0! | M40: =M39/K41 -> #DIV/0! | N40: =N39/L41 -> #DIV/0! | O40: =O39/M41 -> #DIV/0! | ... W40: =W39/U41 -> #DIV/0! | AC40: =AC39/E41 -> #DIV/0! | AD40: =AD39/AC41 -> #DIV/0! | AE40: =AE39/AD41 -> #DIV/0! | AF40: =AF39/AE41 -> #DIV/0! | AG40: =AG39/AF41 -> #DIV/0! | AH40: =AH39/AG41 -> #DIV/0! | AI40: =AI39/AH41 -> #DIV/0! | AJ40: =AJ39/AI41 -> #DIV/0! | AK40: =AK39/AJ41 -> #DIV/0!
B41: Total Sales | C41: =C11+C31+C21 -> 0 | D41: =D11+D31+D21 -> 0 | E41: =E11+E31+E21 -> 0 | F41: =F11+F31+F21 -> 0 | G41: =D41+G35+G37+G39 -> 0 | H41: =F41+H35+H37+H39 -> 0 | I41: =I11+I31+I21 -> 0 | J41: =H41+J35+J37+J39 -> 0 | K41: =K11+K31+K21 -> 0 | L41: =J41+L35+L37+L39 -> 0 | M41: =M11+M31+M21 -> 0 | N41: =L41+N35+N37+N39 -> 0 | O41: =O11+O31+O21 -> 0 | P41: =N41+P35+P37+P39 -> 0 | Q41: =Q11+Q31+Q21 -> 0 | R41: =P41+R35+R37+R39 -> 0 | S41: =S11+S31+S21 -> 0 | T41: =R41+T35+T37+T39 -> 0 | U41: =U11+U31+U21 -> 0 | V41: =T41+V35+V37+V39 -> 0 | W41: =W11+W31+W21 -> 0 | AC41: =E41+AC35+AC37+AC39 -> 0 | AD41: =AC41+AD35+AD37+AD39 -> 0 | AE41: =AD41+AE35+AE37+AE39 -> 0 | AF41: =AE41+AF35+AF37+AF39 -> 0 | AG41: =AF41+AG35+AG37+AG39 -> 0 | AH41: =AG41+AH35+AH37+AH39 -> 0 | AI41: =AH41+AI35+AI37+AI39 -> 0 | AJ41: =AI41+AJ35+AJ37+AJ39 -> 0 | AK41: =AJ41+AK35+AK37+AK39 -> 0
B42: Growth (%) | C42: =IFERROR(C41/#REF!-1, "-") -> - | D42: =IFERROR(D41/#REF!-1, "-") -> - | E42: =IFERROR(E41/#REF!-1, "-") -> - | F42: =IFERROR(F41/C41-1, "-") -> - | G42: =IFERROR(G41/D41-1, "-") -> - | H42: =IFERROR(H41/F41-1, "-") -> - | I42: =IFERROR(I41/G41-1, "-") -> - | J42: =IFERROR(J41/H41-1, "-") -> - | K42: =IFERROR(K41/I41-1, "-") -> - | L42: =IFERROR(L41/J41-1, "-") -> - | M42: =IFERROR(M41/K41-1, "-") -> - | N42: =IFERROR(N41/L41-1, "-") -> - | O42: =IFERROR(O41/M41-1, "-") -> - | ... W42: =IFERROR(W41/U41-1, "-") -> - | AC42: =IFERROR(AC41/E41-1, "-") -> - | AD42: =IFERROR(AD41/AC41-1, "-") -> - | AE42: =IFERROR(AE41/AD41-1, "-") -> - | AF42: =IFERROR(AF41/AE41-1, "-") -> - | AG42: =IFERROR(AG41/AF41-1, "-") -> - | AH42: =IFERROR(AH41/AG41-1, "-") -> - | AI42: =IFERROR(AI41/AH41-1, "-") -> - | AJ42: =IFERROR(AJ41/AI41-1, "-") -> - | AK42: =IFERROR(AK41/AJ41-1, "-") -> -

Sheet Gross Margin
B2: In Euro millions | C2: H1'21 | D2: H2'21 | E2: FY21 | F2: H1'22 | G2: H2'22 | H2: H1'23 | I2: H2'23 | J2: H1'24 | K2: H2'24 | L2: H1'25 | M2: H2'25 | N2: H1'26 | O2: H2'26 | P2: H1'27 | Q2: H2'27 | R2: H1'28 | S2: H2'28 | T2: H1'29 | U2: H2'29 | V2: H1'30 | W2: H2'30 | AC2: FY22 | AD2: FY23 | AE2: FY24 | AF2: FY25 | AG2: FY26 | AH2: FY27 | AI2: FY28 | AJ2: FY29 | AK2: FY30
B4: Americas
B5: Organic | F5: 123 | G5: =AC5-F5 -> 56 | H5: 59 | I5: =AD5-H5 -> -49 | J5: -41 | K5: =AE5-J5 -> 8 | L5: -50 | M5: =K5*(1+M6) -> 8.32 | N5: =L5*(1+N6) -> -52 | O5: =M5*(1+O6) -> 8.6528 | P5: =N5*(1+P6) -> -54.08 | Q5: =O5*(1+Q6) -> 8.998912 | R5: =P5*(1+R6) -> -56.2432 | S5: =Q5*(1+S6) -> 9.3588685 | T5: =R5*(1+T6) -> -58.492928 | ... W5: =U5*(1+W6) -> 10.122552 | AC5: 179 | AD5: 10 | AE5: -33 | AF5: =L5+M5 -> -41.68 | AG5: =N5+O5 -> -43.3472 | AH5: =P5+Q5 -> -45.081088 | AI5: =R5+S5 -> -46.884332 | AJ5: =T5+U5 -> -48.759705 | AK5: =V5+W5 -> -50.710093
B6: Organic growth (%) | C6: =IFERROR(C5/#REF!-1, "-") -> - | D6: =IFERROR(D5/#REF!-1, "-") -> - | E6: =IFERROR(E5/#REF!-1, "-") -> - | F6: =F5/C11 -> 0.13531353 | G6: =G5/D11 -> 0.070886076 | H6: =H5/F11 -> 0.055140187 | I6: =I5/G11 -> -0.049544995 | J6: =J5/H11 -> -0.031202435 | K6: =K5/I11 -> 0.008839779 | L6: =L5/J11 -> -0.040584416 | M6: 0.04 | N6: 0.04 | O6: 0.04 | P6: 0.04 | Q6: 0.04 | R6: 0.04 | S6: 0.04 | T6: 0.04 | U6: 0.04 | V6: 0.04 | W6: 0.04 | AC6: =AC5/E11 -> 0.10535609 | AD6: =AD5/AC11 -> 0.0048567266 | AE6: =AE5/AD11 -> -0.014864865 | AF6: =AF5/AE5-1 -> 0.2630303 | AG6: =AG5/AF5-1 -> 0.04 | AH6: =AH5/AG5-1 -> 0.04 | AI6: =AI5/AH5-1 -> 0.04 | AJ6: =AJ5/AI5-1 -> 0.04 | AK6: =AK5/AJ5-1 -> 0.04
B7: Fx | F7: 27 | G7: =AC7-F7 -> 135 | H7: 168 | I7: =AD7-H7 -> -68 | J7: -127 | K7: =AE7-J7 -> -44 | L7: -48 | M7: =K7*(1+M8) -> -45.76 | N7: =L7*(1+N8) -> -49.92 | O7: =M7*(1+O8) -> -47.5904 | P7: =N7*(1+P8) -> -51.9168 | Q7: =O7*(1+Q8) -> -49.494016 | R7: =P7*(1+R8) -> -53.993472 | S7: =Q7*(1+S8) -> -51.473777 | T7: =R7*(1+T8) -> -56.153211 | ... W7: =U7*(1+W8) -> -55.674037 | AC7: 162 | AD7: 100 | AE7: -171 | AF7: =L7+M7 -> -93.76 | AG7: =N7+O7 -> -97.5104 | AH7: =P7+Q7 -> -101.41082 | AI7: =R7+S7 -> -105.46725 | AJ7: =T7+U7 -> -109.68594 | AK7: =V7+W7 -> -114.07338
B8: Fx growth (%) | C8: =IFERROR(C7/#REF!-1, "-") -> - | D8: =IFERROR(D7/#REF!-1, "-") -> - | E8: =IFERROR(E7/#REF!-1, "-") -> - | F8: =F7/C11 -> 0.02970297 | G8: =G7/D11 -> 0.17088608 | H8: =H7/F11 -> 0.15700935 | I8: =I7/G11 -> -0.06875632 | J8: =J7/H11 -> -0.096651446 | K8: =K7/I11 -> -0.048618785 | L8: =L7/J11 -> -0.038961039 | M8: 0.04 | N8: 0.04 | O8: 0.04 | P8: 0.04 | Q8: 0.04 | R8: 0.04 | S8: 0.04 | T8: 0.04 | U8: 0.04 | V8: 0.04 | W8: 0.04 | AC8: =AC7/E11 -> 0.095350206 | AD8: =AD7/AC11 -> 0.048567266 | AE8: =AE7/AD11 -> -0.077027027 | AF8: =AF7/AE7-1 -> -0.45169591 | AG8: =AG7/AF7-1 -> 0.04 | AH8: =AH7/AG7-1 -> 0.04 | AI8: =AI7/AH7-1 -> 0.04 | AJ8: =AJ7/AI7-1 -> 0.04 | AK8: =AK7/AJ7-1 -> 0.04
B9: Scope | F9: 11 | G9: =AC9-F9 -> 8 | H9: 18 | I9: =AD9-H9 -> 33 | J9: 86 | K9: =AE9-J9 -> 60 | L9: 20 | M9: =K9*(1+M10) -> 62.4 | N9: =L9*(1+N10) -> 20.8 | O9: =M9*(1+O10) -> 64.896 | P9: =N9*(1+P10) -> 21.632 | Q9: =O9*(1+Q10) -> 67.49184 | R9: =P9*(1+R10) -> 22.49728 | S9: =Q9*(1+S10) -> 70.191514 | T9: =R9*(1+T10) -> 23.397171 | ... W9: =U9*(1+W10) -> 75.919141 | AC9: 19 | AD9: 51 | AE9: 146 | AF9: =L9+M9 -> 82.4 | AG9: =N9+O9 -> 85.696 | AH9: =P9+Q9 -> 89.12384 | AI9: =R9+S9 -> 92.688794 | AJ9: =T9+U9 -> 96.396345 | AK9: =V9+W9 -> 100.2522
B10: Scope growth (%) | C10: =IFERROR(C9/#REF!-1, "-") -> - | D10: =IFERROR(D9/#REF!-1, "-") -> - | E10: =IFERROR(E9/#REF!-1, "-") -> - | F10: =F9/C11 -> 0.01210121 | G10: =G9/D11 -> 0.010126582 | H10: =H9/F11 -> 0.01682243 | I10: =I9/G11 -> 0.033367037 | J10: =J9/H11 -> 0.065449011 | K10: =K9/I11 -> 0.066298343 | L10: =L9/J11 -> 0.016233766 | M10: 0.04 | N10: 0.04 | O10: 0.04 | P10: 0.04 | Q10: 0.04 | R10: 0.04 | S10: 0.04 | T10: 0.04 | U10: 0.04 | V10: 0.04 | W10: 0.04 | AC10: =AC9/E11 -> 0.011183049 | AD10: =AD9/AC11 -> 0.024769305 | AE10: =AE9/AD11 -> 0.065765766 | AF10: =IFERROR(AF9/AE9-1, "-") -> -0.43561644 | AG10: =IFERROR(AG9/AF9-1, "-") -> 0.04 | AH10: =IFERROR(AH9/AG9-1, "-") -> 0.04 | AI10: =IFERROR(AI9/AH9-1, "-") -> 0.04 | AJ10: =IFERROR(AJ9/AI9-1, "-") -> 0.04 | AK10: =IFERROR(AK9/AJ9-1, "-") -> 0.04
B11: Total Sales - Americas | C11: 909 | D11: =E11-C11 -> 790 | E11: 1699 | F11: =C11+F5+F7+F9 -> 1070 | G11: =D11+G5+G7+G9 -> 989 | H11: =F11+H5+H7+H9-1 -> 1314 | I11: =G11+I5+I7+I9 -> 905 | J11: =H11+J5+J7+J9 -> 1232 | K11: =I11+K5+K7+K9 -> 929 | L11: =J11+L5+L7+L9 -> 1154 | M11: =K11+M5+M7+M9 -> 953.96 | N11: =L11+N5+N7+N9 -> 1072.88 | O11: =M11+O5+O7+O9 -> 979.9184 | P11: =N11+P5+P7+P9 -> 988.5152 | ... W11: =U11+W5+W7+W9 -> 1094.5591 | AC11: =E11+AC5+AC7+AC9 -> 2059 | AD11: =AC11+AD5+AD7+AD9 -> 2220 | AE11: =AD11+AE5+AE7+AE9 -> 2162 | AF11: =AE11+AF5+AF7+AF9 -> 2108.96 | AG11: =AF11+AG5+AG7+AG9 -> 2053.7984 | AH11: =AG11+AH5+AH7+AH9 -> 1996.4303 | AI11: =AH11+AI5+AI7+AI9 -> 1936.7675 | AJ11: =AI11+AJ5+AJ7+AJ9 -> 1874.7183 | AK11: =AJ11+AK5+AK7+AK9 -> 1810.187
B12: Growth (%) | C12: =IFERROR(C11/#REF!-1, "-") -> - | D12: =IFERROR(D11/#REF!-1, "-") -> - | E12: =IFERROR(E11/#REF!-1, "-") -> - | F12: =IFERROR(F11/C11-1, "-") -> 0.17711771 | G12: =IFERROR(G11/D11-1, "-") -> 0.25189873 | H12: =IFERROR(H11/F11-1, "-") -> 0.22803738 | I12: =IFERROR(I11/G11-1, "-") -> -0.084934277 | J12: =IFERROR(J11/H11-1, "-") -> -0.062404871 | K12: =IFERROR(K11/I11-1, "-") -> 0.026519337 | L12: =IFERROR(L11/J11-1, "-") -> -0.063311688 | M12: =IFERROR(M11/K11-1, "-") -> 0.0268676 | N12: =IFERROR(N11/L11-1, "-") -> -0.070294627 | O12: =IFERROR(O11/M11-1, "-") -> 0.027211204 | ... W12: =IFERROR(W11/U11-1, "-") -> 0.028535897 | AC12: =IFERROR(AC11/E11-1, "-") -> 0.21188935 | AD12: =IFERROR(AD11/AC11-1, "-") -> 0.078193298 | AE12: =IFERROR(AE11/AD11-1, "-") -> -0.026126126 | AF12: =IFERROR(AF11/AE11-1, "-") -> -0.02453284 | AG12: =IFERROR(AG11/AF11-1, "-") -> -0.02615583 | AH12: =IFERROR(AH11/AG11-1, "-") -> -0.027932666 | AI12: =IFERROR(AI11/AH11-1, "-") -> -0.029884733 | AJ12: =IFERROR(AJ11/AI11-1, "-") -> -0.032037556 | AK12: =IFERROR(AK11/AJ11-1, "-") -> -0.03442185
B14: Asia/Row
B15: Organic | F15: 198 | G15: =AC15-F15 -> 185 | H15: 285 | I15: =AD15-H15 -> 216 | J15: 62 | K15: =AE15-J15 -> 93 | L15: -98 | M15: =K15*(1+M16) -> 96.72 | N15: =L15*(1+N16) -> -101.92 | O15: =M15*(1+O16) -> 100.5888 | P15: =N15*(1+P16) -> -105.9968 | Q15: =O15*(1+Q16) -> 104.61235 | R15: =P15*(1+R16) -> -110.23667 | S15: =Q15*(1+S16) -> 108.79685 | T15: =R15*(1+T16) -> -114.64614 | ... W15: =U15*(1+W16) -> 117.67467 | AC15: 383 | AD15: 501 | AE15: 155 | AF15: =L15+M15 -> -1.28 | AG15: =N15+O15 -> -1.3312 | AH15: =P15+Q15 -> -1.384448 | AI15: =R15+S15 -> -1.4398259 | AJ15: =T15+U15 -> -1.497419 | AK15: =V15+W15 -> -1.5573157
B16: Organic growth (%) | C16: =IFERROR(C15/#REF!-1, "-") -> - | D16: =IFERROR(D15/#REF!-1, "-") -> - | E16: =IFERROR(E15/#REF!-1, "-") -> - | F16: =F15/C21 -> 0.16071429 | G16: =G15/D21 -> 0.22342995 | H16: =H15/F21 -> 0.19547325 | I16: =I15/G21 -> 0.20829315 | J16: =J15/H21 -> 0.033935413 | K16: =K15/I21 -> 0.08150745 | L16: =L15/J21 -> -0.057680989 | M16: 0.04 | N16: 0.04 | O16: 0.04 | P16: 0.04 | Q16: 0.04 | R16: 0.04 | S16: 0.04 | T16: 0.04 | U16: 0.04 | V16: 0.04 | W16: 0.04 | AC16: =AC15/E21 -> 0.18592233 | AD16: =AD15/AC21 -> 0.20072115 | AE16: =AE15/AD21 -> 0.05220613 | AF16: =AF15/AE15-1 -> -1.0082581 | AG16: =AG15/AF15-1 -> 0.04 | AH16: =AH15/AG15-1 -> 0.04 | AI16: =AI15/AH15-1 -> 0.04 | AJ16: =AJ15/AI15-1 -> 0.04 | AK16: =AK15/AJ15-1 -> 0.04
B17: Fx | F17: 29 | G17: =AC17-F17 -> 24 | H17: 36 | I17: =AD17-H17 -> -138 | J17: -279 | K17: =AE17-J17 -> -119 | L17: -83 | M17: =K17*(1+M18) -> -123.76 | N17: =L17*(1+N18) -> -86.32 | O17: =M17*(1+O18) -> -128.7104 | P17: =N17*(1+P18) -> -89.7728 | Q17: =O17*(1+Q18) -> -133.85882 | R17: =P17*(1+R18) -> -93.363712 | S17: =Q17*(1+S18) -> -139.21317 | T17: =R17*(1+T18) -> -97.09826 | ... W17: =U17*(1+W18) -> -150.57296 | AC17: 53 | AD17: -102 | AE17: -398 | AF17: =L17+M17 -> -206.76 | AG17: =N17+O17 -> -215.0304 | AH17: =P17+Q17 -> -223.63162 | AI17: =R17+S17 -> -232.57688 | AJ17: =T17+U17 -> -241.87996 | AK17: =V17+W17 -> -251.55515
B18: Fx growth (%) | C18: =IFERROR(C17/#REF!-1, "-") -> - | D18: =IFERROR(D17/#REF!-1, "-") -> - | E18: =IFERROR(E17/#REF!-1, "-") -> - | F18: =F17/C21 -> 0.023538961 | G18: =G17/D21 -> 0.028985507 | H18: =H17/F21 -> 0.024691358 | I18: =I17/G21 -> -0.13307618 | J18: =J17/H21 -> -0.15270936 | K18: =K17/I21 -> -0.10429448 | L18: =L17/J21 -> -0.048852266 | M18: 0.04 | N18: 0.04 | O18: 0.04 | P18: 0.04 | Q18: 0.04 | R18: 0.04 | S18: 0.04 | T18: 0.04 | U18: 0.04 | V18: 0.04 | W18: 0.04 | AC18: =AC17/E21 -> 0.025728155 | AD18: =AD17/AC21 -> -0.040865385 | AE18: =AE17/AD21 -> -0.13405187 | AF18: =AF17/AE17-1 -> -0.48050251 | AG18: =AG17/AF17-1 -> 0.04 | AH18: =AH17/AG17-1 -> 0.04 | AI18: =AI17/AH17-1 -> 0.04 | AJ18: =AJ17/AI17-1 -> 0.04 | AK18: =AK17/AJ17-1 -> 0.04
B19: Scope | F19: 0 | G19: =AC19-F19 -> 0 | H19: 48 | I19: =AD19-H19 -> 26 | J19: 89 | K19: =AE19-J19 -> 37 | L19: 5 | M19: =K19*(1+M20) -> 38.48 | N19: =L19*(1+N20) -> 5.2 | O19: =M19*(1+O20) -> 40.0192 | P19: =N19*(1+P20) -> 5.408 | Q19: =O19*(1+Q20) -> 41.619968 | R19: =P19*(1+R20) -> 5.62432 | S19: =Q19*(1+S20) -> 43.284767 | T19: =R19*(1+T20) -> 5.8492928 | ... W19: =U19*(1+W20) -> 46.816804 | AC19: 0 | AD19: 74 | AE19: 126 | AF19: =L19+M19 -> 43.48 | AG19: =N19+O19 -> 45.2192 | AH19: =P19+Q19 -> 47.027968 | AI19: =R19+S19 -> 48.909087 | AJ19: =T19+U19 -> 50.86545 | AK19: =V19+W19 -> 52.900068
B20: Scope growth (%) | C20: =IFERROR(C19/#REF!-1, "-") -> - | D20: =IFERROR(D19/#REF!-1, "-") -> - | E20: =IFERROR(E19/#REF!-1, "-") -> - | F20: =F19/C21 -> 0 | G20: =G19/D21 -> 0 | H20: =H19/F21 -> 0.032921811 | I20: =I19/G21 -> 0.025072324 | J20: =J19/H21 -> 0.048713738 | K20: =K19/I21 -> 0.032427695 | L20: =L19/J21 -> 0.0029429076 | M20: 0.04 | N20: 0.04 | O20: 0.04 | P20: 0.04 | Q20: 0.04 | R20: 0.04 | S20: 0.04 | T20: 0.04 | U20: 0.04 | V20: 0.04 | W20: 0.04 | AC20: =AC19/E21 -> 0 | AD20: =AD19/AC21 -> 0.029647436 | AE20: =AE19/AD21 -> 0.042438531 | AF20: =IFERROR(AF19/AE19-1, "-") -> -0.65492063 | AG20: =IFERROR(AG19/AF19-1, "-") -> 0.04 | AH20: =IFERROR(AH19/AG19-1, "-") -> 0.04 | AI20: =IFERROR(AI19/AH19-1, "-") -> 0.04 | AJ20: =IFERROR(AJ19/AI19-1, "-") -> 0.04 | AK20: =IFERROR(AK19/AJ19-1, "-") -> 0.04
B21: Total Sales - Asia/Row | C21: 1232 | D21: =E21-C21 -> 828 | E21: 2060 | F21: =C21+F15+F17+F19-1 -> 1458 | G21: =D21+G15+G17+G19 -> 1037 | H21: =F21+H15+H17+H19 -> 1827 | I21: =G21+I15+I17+I19 -> 1141 | J21: =H21+J15+J17+J19 -> 1699 | K21: =I21+K15+K17+K19 -> 1152 | L21: =J21+L15+L17+L19 -> 1523 | M21: =K21+M15+M17+M19 -> 1163.44 | N21: =L21+N15+N17+N19 -> 1339.96 | O21: =M21+O15+O17+O19 -> 1175.3376 | ... W21: =U21+W15+W17+W19 -> 1227.8812 | AC21: =E21+AC15+AC17+AC19 -> 2496 | AD21: =AC21+AD15+AD17+AD19 -> 2969 | AE21: =AD21+AE15+AE17+AE19 -> 2852 | AF21: =AE21+AF15+AF17+AF19 -> 2687.44 | AG21: =AF21+AG15+AG17+AG19 -> 2516.2976 | AH21: =AG21+AH15+AH17+AH19 -> 2338.3095 | AI21: =AH21+AI15+AI17+AI19 -> 2153.2019 | AJ21: =AI21+AJ15+AJ17+AJ19 -> 1960.69 | AK21: =AJ21+AK15+AK17+AK19 -> 1760.4776
B22: Growth (%) | C22: =IFERROR(C21/#REF!-1, "-") -> - | D22: =IFERROR(D21/#REF!-1, "-") -> - | E22: =IFERROR(E21/#REF!-1, "-") -> - | F22: =IFERROR(F21/C21-1, "-") -> 0.18344156 | G22: =IFERROR(G21/D21-1, "-") -> 0.25241546 | H22: =IFERROR(H21/F21-1, "-") -> 0.25308642 | I22: =IFERROR(I21/G21-1, "-") -> 0.1002893 | J22: =IFERROR(J21/H21-1, "-") -> -0.070060208 | K22: =IFERROR(K21/I21-1, "-") -> 0.0096406661 | L22: =IFERROR(L21/J21-1, "-") -> -0.10359035 | M22: =IFERROR(M21/K21-1, "-") -> 0.0099305556 | N22: =IFERROR(N21/L21-1, "-") -> -0.12018385 | O22: =IFERROR(O21/M21-1, "-") -> 0.010226226 | ... W22: =IFERROR(W21/U21-1, "-") -> 0.011465351 | AC22: =IFERROR(AC21/E21-1, "-") -> 0.21165049 | AD22: =IFERROR(AD21/AC21-1, "-") -> 0.18950321 | AE22: =IFERROR(AE21/AD21-1, "-") -> -0.039407208 | AF22: =IFERROR(AF21/AE21-1, "-") -> -0.05769986 | AG22: =IFERROR(AG21/AF21-1, "-") -> -0.063682315 | AH22: =IFERROR(AH21/AG21-1, "-") -> -0.07073412 | AI22: =IFERROR(AI21/AH21-1, "-") -> -0.079163011 | AJ22: =IFERROR(AJ21/AI21-1, "-") -> -0.08940728 | AK22: =IFERROR(AK21/AJ21-1, "-") -> -0.10211324
B24: Europe
B25: Organic | F25: 211 | G25: =AC25-F25 -> 131 | H25: 79 | I25: =AD25-H25 -> 56 | J25: -67 | K25: =AE25-J25 -> -17 | L25: -30 | M25: =K25*(1+M26) -> -17.68 | N25: =L25*(1+N26) -> -31.2 | O25: =M25*(1+O26) -> -18.3872 | P25: =N25*(1+P26) -> -32.448 | Q25: =O25*(1+Q26) -> -19.122688 | R25: =P25*(1+R26) -> -33.74592 | S25: =Q25*(1+S26) -> -19.887596 | T25: =R25*(1+T26) -> -35.095757 | ... W25: =U25*(1+W26) -> -21.510423 | AC25: 342 | AD25: 135 | AE25: -84 | AF25: =L25+M25 -> -47.68 | AG25: =N25+O25 -> -49.5872 | AH25: =P25+Q25 -> -51.570688 | AI25: =R25+S25 -> -53.633516 | AJ25: =T25+U25 -> -55.778856 | AK25: =V25+W25 -> -58.01001
B26: Organic growth (%) | C26: =IFERROR(C25/#REF!-1, "-") -> - | D26: =IFERROR(D25/#REF!-1, "-") -> - | E26: =IFERROR(E25/#REF!-1, "-") -> - | F26: =F25/C31 -> 0.23950057 | G26: =G25/D31 -> 0.20061256 | H26: =H25/F31 -> 0.071043165 | I26: =I25/G31 -> 0.069565217 | J26: =J25/H31 -> -0.054604727 | K26: =K25/I31 -> -0.020481928 | L26: =L25/J31 -> -0.026086957 | M26: 0.04 | N26: 0.04 | O26: 0.04 | P26: 0.04 | Q26: 0.04 | R26: 0.04 | S26: 0.04 | T26: 0.04 | U26: 0.04 | V26: 0.04 | W26: 0.04 | AC26: =AC25/E31 -> 0.22294654 | AD26: =AD25/AC31 -> 0.070385819 | AE26: =AE25/AD31 -> -0.040836169 | AF26: =AF25/AE25-1 -> -0.43238095 | AG26: =AG25/AF25-1 -> 0.04 | AH26: =AH25/AG25-1 -> 0.04 | AI26: =AI25/AH25-1 -> 0.04 | AJ26: =AJ25/AI25-1 -> 0.04 | AK26: =AK25/AJ25-1 -> 0.04
