Workbook

Sheet Company
B2: Founded | C2: 1724
B3: Business Model | C3: The Rémy Cointreau Group is one of the major operators in the global Wine & Spirits market with a portfolio of exceptional brands, which include Rémy Martin and LOUIS XIII cognacs and Cointreau liqueur. The brands are mostly distributed by a network of subsidiaries established in the Group’s various strategic markets. Rémy Cointreau is listed on Euronext Paris. The free float represents approximately 40%. The Rémy Cointreau Group is controlled by the majority shareholder, the Andromède family holding company
B4: Revenue Streams | C4: Cognac
C5: Liqueur & Spirits
C6: Partner Brands
B7: Geographies market wise
B8: Biggest SKUs
B9: Highest Priced Products
C12: Rémy Cointreau has a portfolio of exceptional spirits. Each of these brands embodies unique expertise and heritage, but all share the same culture of excellence.
B14: The House of Rémy Martin - Cognac & House of Brillet | C14: The parent company for the Group’s two brands of cognac — Rémy Martin and LOUIS XIII — Rémy Martin manages all the pooled resources that they are able to call on.
B15: Liqueur & Spirits | C15: The Liqueurs & Spirits division gathers together eight brands with very distinct personalities and brand positions: the liqueur Cointreau, the Greek spirit Metaxa, Mount Gay rum, the French brandy St-Rémy, the single malts Bruichladdich, Port Charlotte and Octomore, the American single malt Westland, the French organic single malt Domaine des Hautes Glaces, and The Botanist gin.
C16: Cointreau - Orange Liqueur- Used in Cosmopolitan
C17: Metaxa - | D17: The Original Greek Spirit
C18: Mount Gay Rum - originated in Barbados
C19: St-Remy- St-Rémy is the world’s number-one French brandy. St-Rémy is bottled in the Loire Valley and shipped around the world!
C20: Bruichladdich – Port Charlotte – Octomore - Unpeated, peated and heavily peated whiskies from Islay
C21: The Botanist - Islya Dry Gin
C22: Hautes Glaces - Whisky from French Alps
C23: Westland Distillery - American single malt
C24: Telmont - Champagne
C25: Belle de brillet - Pear liquer, pineau and cognac
B26: Partner Brands

Sheet Revenue Model
B2: In Euro millions | C2: H1'20 | D2: H2'20 | E2: FY20 | F2: H1'21 | G2: H2'21 | H2: FY21 | I2: H1'22 | J2: H2'22 | K2: FY22 | L2: H1'23 | M2: H2'23 | N2: FY23 | O2: H1'24 | P2: H2'24 | Q2: FY24 | R2: H1'25 | S2: H2'25 | T2: FY25 | U2: H1'26 | V2: H2'26 | W2: FY26 | X2: H1'27 | Y2: H2'27 | Z2: FY27 | AA2: H1'28 | AB2: H2'28 | AC2: FY28 | AD2: H1'29 | AE2: H2'29 | AF2: FY29 | AG2: H1'30 | AH2: H2'30 | AI2: FY30
B4: Cognac
B5: Organic | C5: 367.2 | D5: 349.5 | E5: 716.6 | F5: 310.9 | G5: 451.9 | H5: 762.8 | I5: 473.9 | J5: 454.3 | K5: 928.2 | L5: 568.7 | M5: 451.6 | N5: 1020.3 | O5: 445.8 | P5: 378.1 | Q5: 823.9 | R5: 343 | S5: 265 | T5: 608 | U5: 315.4 | V5: =S16*(1+V7) -> 302.736 | W5: =U5+V5 -> 618.136 | X5: =U16*(1+X7) -> 312.208 | Y5: =V16*(1+Y7) -> 314.84544 | Z5: =X5+Y5 -> 627.05344 | AA5: =X16*(1+AA7) -> 324.69632 | AB5: =Y16*(1+AB7) -> 327.43926 | AC5: =AA5+AB5 -> 652.13558 | AD5: =AA16*(1+AD7) -> 337.68417 | AE5: =AB16*(1+AE7) -> 340.53683 | AF5: =AD5+AE5 -> 678.221 | AG5: =AD16*(1+AG7) -> 351.19154 | AH5: =AE16*(1+AH7) -> 354.1583 | AI5: =AG5+AH5 -> 705.34984
U6: =U10+U8 -> -26.2955
B7: Organic growth (%) | F7: =F5/C16-1 -> -0.18097998 | G7: =G5/D16-1 -> 0.26973869 | H7: =H5/E16-1 -> 0.037258635 | I7: =I5/F16-1 -> 0.55173543 | J7: =J5/G16-1 -> 0.057495345 | K7: =K5/H16-1 -> 0.26285714 | L7: =L5/I16-1 -> 0.22406371 | M7: =M5/J16-1 -> -0.066363448 | ... U7: =U5/R16-1 -> -0.076427526 | V7: 0.12 | W7: =W5/T16-1 -> 0.010521497 | X7: 0.04 | Y7: 0.04 | Z7: =Z5/W16-1 -> 0.04 | AA7: 0.04 | AB7: 0.04 | AC7: =AC5/Z16-1 -> 0.04 | AD7: 0.04 | AE7: 0.04 | AF7: =AF5/AC16-1 -> 0.04 | AG7: 0.04 | AH7: 0.04 | AI7: =AI5/AF16-1 -> 0.04
B8: Volume | U8: =U9*R16 -> 2.3905
B9: Volume growth (%) | T9: -0.156 | U9: 0.007
B10: Price Mix | U10: =U11*R16 -> -28.686
B11: Price Mix(%) | T11: -0.063 | U11: -0.084
B12: Fx | C12: 12.4 | D12: 6.4 | E12: 18.8 | F12: -5.6 | G12: -22.5 | H12: -28.2 | I12: -9.3 | J12: 29.4 | K12: 20.1 | L12: 69.4 | M12: 10.3 | N12: 79.7 | O12: -29.7 | P12: -15.5 | Q12: -45.3 | R12: -1.6 | S12: 5.3 | T12: 3.7 | U12: -15.2 | V12: =V13*S16 -> 0 | W12: =U12+V12 -> -15.2 | X12: =X13*U16 -> 0 | Y12: =Y13*V16 -> 0 | Z12: =X12+Y12 -> 0 | AA12: =AA13*X16 -> 0 | AB12: =AB13*Y16 -> 0 | AC12: =AA12+AB12 -> 0 | AD12: =AD13*AA16 -> 0 | AE12: =AE13*AB16 -> 0 | AF12: =AD12+AE12 -> 0 | AG12: =AG13*AD16 -> 0 | AH12: =AH13*AE16 -> 0 | AI12: =AG12+AH12 -> 0
B13: Fx growth (%) | F13: =F12/C16 -> -0.014752371 | G13: =G12/D16 -> -0.063220006 | H13: =H12/E16 -> -0.038346478 | I13: =I12/F16 -> -0.030451866 | J13: =J12/G16 -> 0.068435754 | K13: =K12/H16 -> 0.027346939 | L13: =L12/I16 -> 0.14937581 | M13: =M12/J16 -> 0.021294191 | ... U13: =U12/R16 -> -0.044509517 | V13: 0 | W13: =W12/T16 -> -0.024848782 | X13: 0 | Y13: 0 | Z13: =Z12/W16 -> 0 | AA13: 0 | AB13: 0 | AC13: =AC12/Z16 -> 0 | AD13: 0 | AE13: 0 | AF13: =AF12/AC16 -> 0 | AG13: 0 | AH13: 0 | AI13: =AI12/AF16 -> 0
B14: Scope | C14: 0 | D14: 0 | E14: 0 | F14: 0.1 | G14: 0.2 | H14: 0.4 | I14: 0 | J14: 0 | K14: 0 | L14: 0 | M14: 0 | N14: 0 | O14: 0 | P14: 0 | Q14: 0 | R14: 0 | S14: 0 | T14: 0 | U14: 0 | V14: =V15*S16 -> 0 | W14: =U14+V14 -> 0 | X14: =X15*U16 -> 0 | Y14: =Y15*V16 -> 0 | Z14: =X14+Y14 -> 0 | AA14: =AA15*X16 -> 0 | AB14: =AB15*Y16 -> 0 | AC14: =AA14+AB14 -> 0 | AD14: =AD15*AA16 -> 0 | AE14: =AE15*AB16 -> 0 | AF14: =AD14+AE14 -> 0 | AG14: =AG15*AD16 -> 0 | AH14: =AH15*AE16 -> 0 | AI14: =AG14+AH14 -> 0
B15: Scope growth (%) | F15: =F14/C126 -> #DIV/0! | G15: =G14/D126 -> #DIV/0! | H15: =H14/E126 -> #DIV/0! | I15: =I14/F126 -> #DIV/0! | J15: =J14/G126 -> #DIV/0! | K15: =K14/H126 -> #DIV/0! | L15: =L14/I126 -> #DIV/0! | M15: =M14/J126 -> #DIV/0! | ... U15: =U14/R126 -> #DIV/0! | V15: 0 | W15: =W14/T126 -> #DIV/0! | X15: 0 | Y15: 0 | Z15: =Z14/W126 -> #DIV/0! | AA15: 0 | AB15: 0 | AC15: =AC14/Z126 -> #DIV/0! | AD15: 0 | AE15: 0 | AF15: =AF14/AC126 -> #DIV/0! | AG15: 0 | AH15: 0 | AI15: =AI14/AF126 -> #DIV/0!
B16: Total Sales - Cognac | C16: =C5+C12+C14 -> 379.6 | D16: =D5+D12+D14 -> 355.9 | E16: =E5+E12+E14 -> 735.4 | F16: =F5+F12+F14 -> 305.4 | G16: =G5+G12+G14 -> 429.6 | H16: =H5+H12+H14 -> 735 | I16: =I5+I12+I14 -> 464.6 | J16: =J5+J12+J14 -> 483.7 | ... Q16: =Q5+Q12+Q14 -> 778.6 | R16: =R5+R12+R14+0.1 -> 341.5 | S16: =S5+S12+S14 -> 270.3 | T16: =T5+T12+T14 -> 611.7 | U16: =U5+U12+U14 -> 300.2 | V16: =V5+V12+V14 -> 302.736 | W16: =W5+W12+W14 -> 602.936 | X16: =X5+X12+X14 -> 312.208 | Y16: =Y5+Y12+Y14 -> 314.84544 | Z16: =Z5+Z12+Z14 -> 627.05344 | ... AI16: =AI5+AI12+AI14 -> 705.34984
B17: Growth (%) | F17: =IFERROR(F16/C16-1, "-") -> -0.19546891 | G17: =IFERROR(G16/D16-1, "-") -> 0.20708064 | H17: =IFERROR(H16/E16-1, "-") -> -0.00054392168 | I17: =IFERROR(I16/F16-1, "-") -> 0.52128356 | J17: =IFERROR(J16/G16-1, "-") -> 0.1259311 | K17: =IFERROR(K16/H16-1, "-") -> 0.29020408 | L17: =IFERROR(L16/I16-1, "-") -> 0.37343952 | M17: =IFERROR(M16/J16-1, "-") -> -0.045069258 | ... AI17: =IFERROR(AI16/AF16-1, "-") -> 0.04
B19: Liquers & Spirits
B20: Organic | C20: 128 | D20: 128.5 | E20: 256.4 | F20: 113.4 | G20: 140 | H20: 253.4 | I20: 164.7 | J20: 162.5 | K20: 327.1 | L20: 198.1 | M20: 197.6 | N20: 395.7 | O20: 214.6 | P20: 185 | Q20: 399.6 | R20: 181.8 | S20: 168.8 | T20: 350.7 | U20: 189.2 | V20: =S31*(1+V22) -> 172.508 | W20: =U20+V20 -> 361.708 | X20: =U31*(1+X22) -> 190.008 | Y20: =V31*(1+Y22) -> 179.40832 | Z20: =X20+Y20 -> 369.41632 | AA20: =X31*(1+AA22) -> 197.60832 | AB20: =Y31*(1+AB22) -> 186.58465 | AC20: =AA20+AB20 -> 384.19297 | AD20: =AA31*(1+AD22) -> 205.51265 | AE20: =AB31*(1+AE22) -> 194.04804 | AF20: =AD20+AE20 -> 399.56069 | AG20: =AD31*(1+AG22) -> 221.95367 | AH20: =AE31*(1+AH22) -> 213.45284 | AI20: =AG20+AH20 -> 435.40651
U21: =U23+U25 -> 7.6314
B22: Organic growth (%) | F22: =F20/C31-1 -> -0.13567073 | G22: =G20/D31-1 -> 0.071155318 | H22: =H20/E31-1 -> -0.032085561 | I22: =I20/F31-1 -> 0.47053571 | J22: =J20/G31-1 -> 0.19222304 | K22: =K20/H31-1 -> 0.31735803 | L22: =L20/I31-1 -> 0.20719074 | M22: =M20/J31-1 -> 0.16853933 | ... U22: =U20/R31-1 -> 0.04127683 | V22: 0.01 | W22: =W20/T31-1 -> 0.02583097 | X22: 0.04 | Y22: 0.04 | Z22: =Z20/W20-1 -> 0.021310892 | AA22: 0.04 | AB22: 0.04 | AC22: =AC20/Z20-1 -> 0.04 | AD22: 0.04 | AE22: 0.04 | AF22: =AF20/AC20-1 -> 0.04 | AG22: 0.08 | AH22: 0.1 | AI22: =AI20/AF20-1 -> 0.08971307
B23: Volume | U23: =U24*R31 -> 9.4484
B24: Volume growth (%) | U24: 0.052
B25: Price Mix | U25: =U26*R31 -> -1.817
B26: Price Mix(%) | U26: -0.01
B27: Fx | C27: 3.2 | D27: 2.2 | E27: 5.4 | F27: -1.8 | G27: -6.2 | H27: -8 | I27: -2.5 | J27: 6.6 | K27: 4.1 | L27: 16.4 | M27: 6.9 | N27: 23.2 | O27: -7.9 | P27: -3.8 | Q27: -11.7 | R27: -0.1 | S27: 2 | T27: 1.9 | U27: -6.5 | V27: =V28*S31 -> 0 | W27: =U27+V27 -> -6.5 | X27: =X28*U31 -> 0 | Y27: =Y28*V31 -> 0 | Z27: =X27+Y27 -> 0 | AA27: =AA28*X31 -> 0 | AB27: =AB28*Y31 -> 0 | AC27: =AA27+AB27 -> 0 | AD27: =AD28*AA31 -> 0 | AE27: =AE28*AB31 -> 0 | AF27: =AD27+AE27 -> 0 | AG27: =AG28*AD31 -> 0 | AH27: =AH28*AE31 -> 0 | AI27: =AG27+AH27 -> 0
B28: Fx growth (%) | F28: =F27/C31 -> -0.013719512 | G28: =G27/D31 -> -0.047436878 | H28: =H27/E31 -> -0.030557678 | I28: =I27/F31 -> -0.022321429 | J28: =J27/G31 -> 0.048422597 | K28: =K27/H31 -> 0.016512284 | L28: =L27/I31 -> 0.099939062 | M28: =M27/J31 -> 0.040804258 | ... U28: =U27/R31 -> -0.035773253 | V28: 0 | W28: =W27/T31 -> -0.018434487 | X28: 0 | Y28: 0 | Z28: =Z27/W31 -> 0 | AA28: 0 | AB28: 0 | AC28: =AC27/Z31 -> 0 | AD28: 0 | AE28: 0 | AF28: =AF27/AC31 -> 0 | AG28: 0 | AH28: 0 | AI28: =AI27/AF31 -> 0
B29: Scope | C29: 0 | D29: 0 | E29: 0 | F29: 0.4 | G29: 2.5 | H29: 2.9 | I29: 1.9 | J29: 0 | K29: 0 | L29: 0 | M29: 0 | N29: 0 | O29: 0 | P29: 0 | Q29: 0 | R29: 0 | S29: 0 | T29: 0 | U29: 0 | V29: =V30*S31 -> 0 | W29: =U29+V29 -> 0 | X29: =X30*U31 -> 0 | Y29: =Y30*V31 -> 0 | Z29: =X29+Y29 -> 0 | AA29: =AA30*X31 -> 0 | AB29: =AB30*Y31 -> 0 | AC29: =AA29+AB29 -> 0 | AD29: =AD30*AA31 -> 0 | AE29: =AE30*AB31 -> 0 | AF29: =AD29+AE29 -> 0 | AG29: =AG30*AD31 -> 0 | AH29: =AH30*AE31 -> 0 | AI29: =AG29+AH29 -> 0
B30: Scope growth (%) | F30: =F29/C136 -> #DIV/0! | G30: =G29/D136 -> #DIV/0! | H30: =H29/E136 -> #DIV/0! | I30: =I29/F136 -> #DIV/0! | J30: =J29/G136 -> #DIV/0! | K30: =K29/H136 -> #DIV/0! | L30: =L29/I136 -> #DIV/0! | M30: =M29/J136 -> #DIV/0! | ... U30: =U29/R136 -> #DIV/0! | V30: 0 | W30: =W29/T136 -> #DIV/0! | X30: 0 | Y30: 0 | Z30: =Z29/W136 -> #DIV/0! | AA30: 0 | AB30: 0 | AC30: =AC29/Z136 -> #DIV/0! | AD30: 0 | AE30: 0 | AF30: =AF29/AC136 -> #DIV/0! | AG30: 0 | AH30: 0 | AI30: =AI29/AF136 -> #DIV/0!
B31: Total Sales - Liquers & Spirits | C31: =C20+C27+C29 -> 131.2 | D31: =D20+D27+D29 -> 130.7 | E31: =E20+E27+E29 -> 261.8 | F31: =F20+F27+F29 -> 112 | G31: =G20+G27+G29 -> 136.3 | H31: =H20+H27+H29 -> 248.3 | I31: =I20+I27+I29 -> 164.1 | J31: =J20+J27+J29 -> 169.1 | ... AI31: =AI20+AI27+AI29 -> 435.40651
B32: Growth (%) | F32: =IFERROR(F31/C31-1, "-") -> -0.14634146 | G32: =IFERROR(G31/D31-1, "-") -> 0.042846213 | H32: =IFERROR(H31/E31-1, "-") -> -0.051566081 | I32: =IFERROR(I31/F31-1, "-") -> 0.46517857 | J32: =IFERROR(J31/G31-1, "-") -> 0.24064563 | K32: =IFERROR(K31/H31-1, "-") -> 0.33387032 | L32: =IFERROR(L31/I31-1, "-") -> 0.3071298 | M32: =IFERROR(M31/J31-1, "-") -> 0.20934358 | ... AI32: =IFERROR(AI31/AF31-1, "-") -> 0.08971307
B34: Subtotal
B35: Cognac | C35: =C16 -> 379.6 | D35: =D16 -> 355.9 | E35: =E16 -> 735.4 | F35: =F16 -> 305.4 | G35: =G16 -> 429.6 | H35: =H16 -> 735 | I35: =I16 -> 464.6 | J35: =J16 -> 483.7 | ... S35: =S16 -> 270.3 | T35: =T16+0.1 -> 611.8 | U35: =U16 -> 300.2 | V35: =V16 -> 302.736 | W35: =W16 -> 602.936 | X35: =X16 -> 312.208 | Y35: =Y16 -> 314.84544 | Z35: =Z16 -> 627.05344 | AA35: =AA16 -> 324.69632 | AB35: =AB16 -> 327.43926 | ... AI35: =AI16 -> 705.34984
B36: Liquers & Spirits | C36: =C31 -> 131.2 | D36: =D31 -> 130.7 | E36: =E31 -> 261.8 | F36: =F31 -> 112 | G36: =G31 -> 136.3 | H36: =H31 -> 248.3 | I36: =I31 -> 164.1 | J36: =J31 -> 169.1 | ... AI36: =AI31 -> 435.40651
B37: Total Sales - Subtotal | C37: =C35+C36 -> 510.8 | D37: =D35+D36 -> 486.6 | E37: =E35+E36 -> 997.2 | F37: =F35+F36 -> 417.4 | G37: =G35+G36 -> 565.9 | H37: =H35+H36 -> 983.3 | I37: =I35+I36 -> 628.7 | J37: =J35+J36 -> 652.8 | ... AI37: =AI35+AI36 -> 1140.7563
B38: Growth (%) | F38: =IFERROR(F37/C37-1, "-") -> -0.18285043 | G38: =IFERROR(G37/D37-1, "-") -> 0.16296753 | H38: =IFERROR(H37/E37-1, "-") -> -0.013939029 | I38: =IFERROR(I37/F37-1, "-") -> 0.50622904 | J38: =IFERROR(J37/G37-1, "-") -> 0.1535607 | K38: =IFERROR(K37/H37-1, "-") -> 0.30123055 | L38: =IFERROR(L37/I37-1, "-") -> 0.3561317 | M38: =IFERROR(M37/J37-1, "-") -> 0.020833333 | ... AI38: =IFERROR(AI37/AF37-1, "-") -> 0.058429881
B40: Partner Brands
B41: Organic | C41: 13 | D41: 14.3 | E41: 27.3 | F41: 13.4 | G41: 13.7 | H41: 27.1 | I41: 16.5 | J41: 14.5 | K41: 31 | L41: 14.5 | M41: 15.2 | N41: 29.7 | O41: 14.1 | P41: 13.7 | Q41: 27.8 | R41: 10.5 | S41: 9.7 | T41: 20.1 | U41: 6.7 | V41: =S52*(1+V43) -> 10.976 | W41: =U41+V41 -> 17.676 | X41: =U52*(1+X43) -> 7.236 | Y41: =V52*(1+Y43) -> 12.0736 | Z41: =X41+Y41 -> 19.3096 | AA41: =X52*(1+AA43) -> 7.81488 | AB41: =Y52*(1+AB43) -> 13.28096 | AC41: =AA41+AB41 -> 21.09584 | AD41: =AA52*(1+AD43) -> 8.4400704 | AE41: =AB52*(1+AE43) -> 14.609056 | AF41: =AD41+AE41 -> 23.049126 | AG41: =AD52*(1+AG43) -> 9.115276 | AH41: =AE52*(1+AH43) -> 16.069962 | AI41: =AG41+AH41 -> 25.185238
B43: Organic growth (%) | F43: =F41/C52-1 -> 0.022900763 | G43: =G41/D52-1 -> -0.048611111 | H43: =H41/E52-1 -> -0.014545455 | I43: =I41/F52-1 -> 0.2406015 | J43: =J41/G52-1 -> 0.066176471 | K43: =K41/H52-1 -> 0.15241636 | L43: =L41/I52-1 -> -0.12650602 | M43: =M41/J52-1 -> 0.034013605 | ... U43: =U41/R52-1 -> -0.36190476 | V43: 0.12 | W43: =W41/T41-1 -> -0.12059701 | X43: 0.08 | Y43: 0.1 | Z43: =Z41/W41-1 -> 0.092419099 | AA43: 0.08 | AB43: 0.1 | AC43: =AC41/Z41-1 -> 0.092505282 | AD43: 0.08 | AE43: 0.1 | AF43: =AF41/AC41-1 -> 0.09259107 | AG43: 0.08 | AH43: 0.1 | AI43: =AI41/AF41-1 -> 0.092676451
B44: Volume | U44: =U45*R52 -> 0
B45: Volume growth (%) | T45: -0.156
B46: Price Mix | U46: =U47*R52 -> 0
...

Sheet Financial Statements
B1: In Euro Millions
B3: Income Statement | C3: H1'20 | D3: H2'20 | E3: FY20 | F3: H1'21 | G3: H2'21 | H3: FY21 | I3: H1'22 | J3: H2'22 | K3: FY22 | L3: H1'23 | M3: H2'23 | N3: FY23 | O3: H1'24 | P3: H2'24 | Q3: FY24 | R3: H1'25 | S3: ='Revenue Model'!S2 -> H2'25 | T3: ='Revenue Model'!T2 -> FY25 | U3: H1'26 | V3: ='Revenue Model'!V2 -> H2'26 | W3: ='Revenue Model'!W2 -> FY26 | X3: ='Revenue Model'!X2 -> H1'27 | Y3: ='Revenue Model'!Y2 -> H2'27 | Z3: ='Revenue Model'!Z2 -> FY27 | AA3: ='Revenue Model'!AA2 -> H1'28 | AB3: ='Revenue Model'!AB2 -> H2'28 | AC3: ='Revenue Model'!AC2 -> FY28 | ... AI3: ='Revenue Model'!AI2 -> FY30
B4: Sales | C4: 523.9 | D4: =E4-C4 -> 500.9 | E4: 1024.8 | F4: 430.8 | G4: =H4-F4 -> 579.4 | H4: 1010.2 | I4: 645.3 | J4: =K4-I4 -> 667.6 | K4: 1312.9 | L4: 867.1 | M4: =N4-L4 -> 681.4 | N4: 1548.5 | O4: 636.7 | P4: =Q4-O4 -> 557.5 | Q4: ='Revenue Model'!Q58 -> 1194.2 | R4: ='Revenue Model'!R58 -> 533.7 | S4: =T4-R4 -> 450.9 | T4: ='Revenue Model'!T58 -> 984.6 | U4: ='Revenue Model'!U58 -> 489.6 | V4: ='Revenue Model'!V58 -> 486.22 | W4: ='Revenue Model'!W58 -> 975.82 | X4: ='Revenue Model'!X58 -> 509.452 | Y4: ='Revenue Model'!Y58 -> 506.32736 | Z4: ='Revenue Model'!Z58 -> 1015.7794 | AA4: ='Revenue Model'!AA58 -> 530.11952 | ... AI4: ='Revenue Model'!AI58 -> 1165.9416
B5: Cost of Sales | C5: 175.6 | D5: =E5-C5 -> 172.3 | E5: 347.9 | F5: 152.2 | G5: =H5-F5 -> 177.9 | H5: 330.1 | I5: 199.4 | J5: =K5-I5 -> 212.4 | K5: 411.8 | L5: 243.4 | M5: =N5-L5 -> 201.3 | N5: 444.7 | O5: 176.8 | P5: =Q5-O5 -> 167.2 | Q5: 344 | R5: 146.8 | S5: =T5-R5 -> 143 | T5: 289.8 | U5: 156.6 | V5: =V4-V6 -> 170.177 | W5: =U5+V5 -> 326.777 | X5: =X4-X6 -> 178.3082 | Y5: =Y4-Y6 -> 177.21458 | Z5: =X5+Y5 -> 355.52278 | AA5: =AA4-AA6 -> 185.54183 | AB5: =AB4-AB6 -> 184.5567 | AC5: =AA5+AB5 -> 370.09854 | AD5: =AD4-AD6 -> 193.07291 | AE5: =AE4-AE6 -> 192.21787 | AF5: =AD5+AE5 -> 385.29079 | AG5: =AG4-AG6 -> 203.79117 | AH5: =AH4-AH6 -> 204.28839 | AI5: =AG5+AH5 -> 408.07956
B6: Gross Profit | C6: =C4-C5 -> 348.3 | D6: =D4-D5 -> 328.6 | E6: =E4-E5 -> 676.9 | F6: =F4-F5 -> 278.6 | G6: =G4-G5 -> 401.5 | H6: =H4-H5 -> 680.1 | I6: =I4-I5 -> 445.9 | J6: =J4-J5 -> 455.2 | ... T6: =T4-T5 -> 694.8 | U6: =U4-U5+0.1 -> 333.1 | V6: =V4*V7 -> 316.043 | W6: =W4-W5 -> 649.043 | X6: =X4*X7 -> 331.1438 | Y6: =Y4*Y7 -> 329.11278 | Z6: =Z4-Z5 -> 660.25658 | AA6: =AA4*AA7 -> 344.57769 | AB6: =AB4*AB7 -> 342.74817 | AC6: =AC4-AC5 -> 687.32585 | AD6: =AD4*AD7 -> 358.56398 | AE6: =AE4*AE7 -> 356.97605 | AF6: =AF4-AF5 -> 715.54003 | AG6: =AG4*AG7 -> 378.46931 | AH6: =AH4*AH7 -> 379.39272 | AI6: =AI4-AI5 -> 757.86203
B7: Gross Margin (%) | C7: =C6/C4 -> 0.66482153 | D7: =D6/D4 -> 0.65601917 | E7: =E6/E4 -> 0.66051913 | F7: =F6/F4 -> 0.64670381 | G7: =G6/G4 -> 0.69295823 | H7: =H6/H4 -> 0.67323302 | I7: =I6/I4 -> 0.69099644 | J7: =J6/J4 -> 0.68184542 | ... U7: =U6/U4 -> 0.68035131 | V7: 0.65 | W7: =W6/W4 -> 0.66512574 | X7: 0.65 | Y7: 0.65 | Z7: =Z6/Z4 -> 0.65 | AA7: 0.65 | AB7: 0.65 | AC7: =AC6/AC4 -> 0.65 | AD7: 0.65 | AE7: 0.65 | AF7: =AF6/AF4 -> 0.65 | AG7: 0.65 | AH7: 0.65 | AI7: =AI6/AI4 -> 0.65
B8: Distribution & Administrative Expenses | C8: =159.2+50.8 -> 210 | D8: =E8-C8 -> 251.8 | E8: =355+106.8 -> 461.8 | F8: =128.6+43.8 -> 172.4 | G8: =H8-F8 -> 271.7 | H8: =341.6+102.5 -> 444.1 | I8: =172.1+60.9 -> 233 | J8: =K8-I8 -> 333.7 | K8: =566.7 -> 566.7 | L8: =230.8+73.6 -> 304.4 | M8: =N8-L8 -> 369.8 | N8: =674.2 -> 674.2 | O8: =290.8 -> 290.8 | P8: =Q8-O8 -> 255 | Q8: =545.8 -> 545.8 | R8: =239.6 -> 239.6 | S8: =T8-R8 -> 238.2 | T8: 477.8 | U8: 231.2 | V8: =V9*V4 -> 194.488 | W8: =U8+V8 -> 425.688 | X8: =X9*X4 -> 203.7808 | Y8: =Y9*Y4 -> 202.53094 | Z8: =X8+Y8 -> 406.31174 | AA8: =AA9*AA4 -> 212.04781 | AB8: =AB9*AB4 -> 210.92195 | AC8: =AA8+AB8 -> 422.96976 | AD8: =AD9*AD4 -> 220.65476 | AE8: =AE9*AE4 -> 219.67757 | AF8: =AD8+AE8 -> 440.33233 | AG8: =AG9*AG4 -> 232.90419 | AH8: =AH9*AH4 -> 233.47244 | AI8: =AG8+AH8 -> 466.37663
B9: SG&A Margin (%) | C9: =C8/C4 -> 0.40083985 | D9: =D8/D4 -> 0.50269515 | E9: =E8/E4 -> 0.45062451 | F9: =F8/F4 -> 0.4001857 | G9: =G8/G4 -> 0.46893338 | H9: =H8/H4 -> 0.43961592 | I9: =I8/I4 -> 0.36107237 | J9: =J8/J4 -> 0.49985021 | ... U9: =U8/U4 -> 0.47222222 | V9: 0.4 | W9: =W8/W4 -> 0.43623619 | X9: 0.4 | Y9: 0.4 | Z9: =Z8/Z4 -> 0.4 | AA9: 0.4 | AB9: 0.4 | AC9: =AC8/AC4 -> 0.4 | AD9: 0.4 | AE9: 0.4 | AF9: =AF8/AF4 -> 0.4 | AG9: 0.4 | AH9: 0.4 | AI9: =AI8/AI4 -> 0.4
B10: Misc. | U10: 6.9 | W10: =U10+V10 -> 6.9
B11: Current Operating Profit | C11: =C6-C8 -> 138.3 | D11: =D6-D8 -> 76.8 | E11: =E6-E8 -> 215.1 | F11: =F6-F8 -> 106.2 | G11: =G6-G8 -> 129.8 | H11: =H6-H8 -> 236 | I11: =I6-I8 -> 212.9 | J11: =J6-J8 -> 121.5 | ... T11: =T6-T8 -> 217 | U11: =U6-U8+U10-0.1 -> 108.7 | V11: =V6-V8 -> 121.555 | W11: =W6-W8+W10 -> 230.255 | X11: =X6-X8 -> 127.363 | Y11: =Y6-Y8 -> 126.58184 | Z11: =Z6-Z8 -> 253.94484 | AA11: =AA6-AA8 -> 132.52988 | AB11: =AB6-AB8 -> 131.82622 | AC11: =AC6-AC8 -> 264.3561 | AD11: =AD6-AD8 -> 137.90922 | AE11: =AE6-AE8 -> 137.29848 | ... AI11: =AI6-AI8 -> 291.4854
B12: COP Margin (%) | C12: =C11/C4 -> 0.26398168 | D12: =D11/D4 -> 0.15332402 | E12: =E11/E4 -> 0.20989461 | F12: =F11/F4 -> 0.24651811 | G12: =G11/G4 -> 0.22402485 | H12: =H11/H4 -> 0.23361711 | I12: =I11/I4 -> 0.32992407 | J12: =J11/J4 -> 0.18199521 | ... AI12: =AI11/AI4 -> 0.25
B13: Other non-current income/expense | C13: 0.6 | D13: =E13-C13 -> 19.1 | E13: 19.7 | F13: 0.2 | G13: =H13-F13 -> 0 | H13: 0.2 | I13: 13.6 | J13: =K13-I13 -> 0.5 | K13: 14.1 | L13: 4 | M13: =N13-L13 -> -0.9 | N13: 3.1 | O13: 0 | P13: =Q13-O13 -> 12.8 | Q13: 12.8 | R13: -0.2 | S13: =T13-R13 -> 6.2 | T13: 6 | U13: -0.7 | V13: 0 | W13: =U13+V13 -> -0.7 | X13: 0 | Y13: 0 | Z13: =X13+Y13 -> 0 | AA13: 0 | AB13: 0 | AC13: =AA13+AB13 -> 0 | AD13: 0 | AE13: 0 | AF13: =AD13+AE13 -> 0 | AG13: 0 | AH13: 0 | AI13: =AG13+AH13 -> 0
B14: EBIT | C14: =C11-C13 -> 137.7 | D14: =D11-D13 -> 57.7 | E14: =E11-E13 -> 195.4 | F14: =F11-F13 -> 106 | G14: =G11-G13 -> 129.8 | H14: =H11-H13 -> 235.8 | I14: =I11-I13 -> 199.3 | J14: =J11-J13 -> 121 | ... U14: =U11-U13 -> 109.4 | V14: =V6-V8-V13 -> 121.555 | W14: =W6-W8-W13 -> 224.055 | X14: =X6-X8-X13 -> 127.363 | Y14: =Y6-Y8-Y13 -> 126.58184 | Z14: =Z6-Z8-Z13 -> 253.94484 | AA14: =AA6-AA8-AA13 -> 132.52988 | AB14: =AB6-AB8-AB13 -> 131.82622 | AC14: =AC6-AC8-AC13 -> 264.3561 | ... AI14: =AI6-AI8-AI13 -> 291.4854
B15: EBIT Margin (%) | C15: =C14/C4 -> 0.26283642 | D15: =D14/D4 -> 0.11519265 | E15: =E14/E4 -> 0.19067135 | F15: =F14/F4 -> 0.24605385 | G15: =G14/G4 -> 0.22402485 | H15: =H14/H4 -> 0.23341912 | I15: =I14/I4 -> 0.3088486 | J15: =J14/J4 -> 0.18124626 | ... AI15: =AI14/AI4 -> 0.25
B16: D&A | C16: 15.4 | D16: =E16-C16 -> 18 | E16: 33.4 | F16: 16.4 | G16: =H16-F16 -> 17.6 | H16: 34 | I16: 18 | J16: =K16-I16 -> 22 | K16: 40 | L16: 19.1 | M16: =N16-L16 -> 21.1 | N16: 40.2 | O16: 21.6 | P16: =Q16-O16 -> 23.5 | Q16: 45.1 | R16: 22.9 | S16: =T16-R16 -> 23.9 | T16: 46.8 | U16: 23.2 | V16: =Schedules!V11+Schedules!V25+Schedules!V39 -> 16.038 | W16: =U16+V16 -> 39.238 | X16: =Schedules!X11+Schedules!X25+Schedules!X39 -> 16.52422 | Y16: =Schedules!Y11+Schedules!Y25+Schedules!Y39 -> 17.033672 | Z16: =Schedules!Z11+Schedules!Z25+Schedules!Z39 -> 33.557892 | AA16: =Schedules!AA11+Schedules!AA25+Schedules!AA39 -> 17.539999 | AB16: =Schedules!AB11+Schedules!AB25+Schedules!AB39 -> 18.070119 | AC16: =Schedules!AC11+Schedules!AC25+Schedules!AC39 -> 35.610118 | AD16: =Schedules!AD11+Schedules!AD25+Schedules!AD39 -> 18.597424 | AE16: =Schedules!AE11+Schedules!AE25+Schedules!AE39 -> 19.149061 | ... AI16: =Schedules!AI11+Schedules!AI25+Schedules!AI39 -> 39.97877
B17: SBP | Q17: 6.2 | R17: 4.1 | S17: =T17-R17 -> 0 | T17: 4.1 | U17: 0.8 | W17: =U17+V17 -> 0.8
B18: Dividends received from associates | Q18: 0.6 | S18: =T18-R18 -> 0 | T18: 0 | U18: 0.5 | W18: =U18+V18 -> 0.5
B19: EBITDA | C19: =C14+C16 -> 153.1 | D19: =D14+D16 -> 75.7 | E19: =E14+E16 -> 228.8 | F19: =F14+F16 -> 122.4 | G19: =G14+G16 -> 147.4 | H19: =H14+H16 -> 269.8 | I19: =I14+I16 -> 217.3 | J19: =J14+J16 -> 143 | ... P19: =P14+P16 -> 146 | Q19: =Q11+Q16+Q17+Q18 -> 356.3 | R19: =R11+R16+R17+R18 -> 174.3 | S19: =S11+S16+S17+S18 -> 93.6 | T19: =T11+T16+T17+T18-0.1 -> 267.8 | U19: =U11+U16+U17+U18 -> 133.2 | V19: =V6-V8 -> 121.555 | W19: =W6-W8 -> 223.355 | X19: =X6-X8 -> 127.363 | Y19: =Y6-Y8 -> 126.58184 | Z19: =Z6-Z8 -> 253.94484 | AA19: =AA6-AA8 -> 132.52988 | AB19: =AB6-AB8 -> 131.82622 | AC19: =AC6-AC8 -> 264.3561 | ... AI19: =AI6-AI8 -> 291.4854 | AL19: Higher EBITDA Margins
B20: EBITDA Margin (%) | C20: =C19/C4 -> 0.29223134 | D20: =D19/D4 -> 0.15112797 | E20: =E19/E4 -> 0.22326308 | F20: =F19/F4 -> 0.28412256 | G20: =G19/G4 -> 0.2544011 | H20: =H19/H4 -> 0.26707583 | I20: =I19/I4 -> 0.3367426 | J20: =J19/J4 -> 0.21420012 | ... AI20: =AI19/AI4 -> 0.25
B21: Net borrowing cost | C21: 6.3 | D21: =E21-C21 -> 6.4 | E21: 12.7 | F21: 6.1 | G21: =H21-F21 -> 5.9 | H21: 12 | I21: 5.5 | J21: =K21-I21 -> 4.9 | K21: 10.4 | L21: 4.5 | M21: =N21-L21 -> 7.2 | N21: 11.7 | O21: 11.7 | P21: =Q21-O21 -> 20 | Q21: 31.7 | R21: 16.7 | S21: =T21-R21 -> 17 | T21: 33.7 | U21: 16 | V21: =Schedules!V71 -> 17.319 | W21: =U21+V21 -> 33.319 | X21: =Schedules!X71 -> 16.719 | Y21: =Schedules!Y71 -> 16.419 | Z21: =X21+Y21 -> 33.138 | AA21: =Schedules!AA71 -> 15.819 | AB21: =Schedules!AB71 -> 15.519 | AC21: =AA21+AB21 -> 31.338 | AD21: =Schedules!AD71 -> 14.919 | AE21: =Schedules!AE71 -> 14.619 | AF21: =AD21+AE21 -> 29.538 | AG21: =Schedules!AG71 -> 14.019 | AH21: =Schedules!AH71 -> 13.719 | AI21: =AG21+AH21 -> 27.738
B22: Other financial income/expenses | C22: 8 | D22: =E22-C22 -> 7.3 | E22: 15.3 | F22: 1.9 | G22: =H22-F22 -> 0.7 | H22: 2.6 | I22: 1.9 | J22: =K22-I22 -> 0.9 | K22: 2.8 | L22: 0.7 | M22: =N22-L22 -> 5.2 | N22: 5.9 | O22: 4 | P22: =Q22-O22 -> 2.8 | Q22: 6.8 | R22: 4.4 | S22: =T22-R22 -> 4.5 | T22: 8.9 | U22: 6 | V22: 0 | W22: =U22+V22 -> 6 | X22: 0 | Y22: 0 | Z22: =X22+Y22 -> 0 | AA22: 0 | AB22: 0 | AC22: =AA22+AB22 -> 0 | AD22: 0 | AE22: 0 | AF22: =AD22+AE22 -> 0 | AG22: 0 | AH22: 0 | AI22: =AG22+AH22 -> 0
B23: PBT | C23: =C14-C21-C22 -> 123.4 | D23: =D14-D21-D22 -> 44 | E23: =E14-E21-E22 -> 167.4 | F23: =F14-F21-F22 -> 98 | G23: =G14-G21-G22 -> 123.2 | H23: =H14-H21-H22 -> 221.2 | I23: =I14-I21-I22 -> 191.9 | J23: =J14-J21-J22 -> 115.2 | ... AI23: =AI14-AI21-AI22 -> 263.7474
B24: PBT Margin (%) | C24: =C23/C4 -> 0.23554113 | D24: =D23/D4 -> 0.087841885 | E24: =E23/E4 -> 0.16334895 | F24: =F23/F4 -> 0.22748375 | G24: =G23/G4 -> 0.21263376 | H24: =H23/H4 -> 0.21896654 | I24: =I23/I4 -> 0.29738106 | J24: =J23/J4 -> 0.17255842 | ... AI24: =AI23/AI4 -> 0.22620979
B25: Income Tax | C25: 39.1 | D25: =E25-C25 -> 21.8 | E25: 60.9 | F25: 33.1 | G25: =H25-F25 -> 44.5 | H25: 77.6 | I25: 58.1 | J25: =K25-I25 -> 37.5 | K25: 95.6 | L25: 86.9 | M25: =N25-L25 -> 29.4 | N25: 116.3 | O25: 40.8 | P25: =Q25-O25 -> 28.6 | Q25: 69.4 | R25: 34.8 | S25: =T25-R25 -> 13.4 | T25: 48.2 | U25: 24.5 | V25: =V26*V23 -> 27.10136 | W25: =U25+V25 -> 51.60136 | X25: =X26*X23 -> 28.76744 | Y25: =Y26*Y23 -> 28.642338 | Z25: =X25+Y25 -> 57.409778 | AA25: =AA26*AA23 -> 30.344829 | AB25: =AB26*AB23 -> 30.239877 | AC25: =AA25+AB25 -> 60.584705 | AD25: =AD26*AD23 -> 31.977458 | AE25: =AE26*AE23 -> 31.896665 | AF25: =AD25+AE25 -> 63.874123 | AG25: =AG26*AG23 -> 34.201991 | AH25: =AH26*AH23 -> 34.372332 | AI25: =AG25+AH25 -> 68.574323
B26: Tax Rate (%) | C26: =C25/C23 -> 0.31685575 | D26: =D25/D23 -> 0.49545455 | E26: =E25/E23 -> 0.36379928 | F26: =F25/F23 -> 0.3377551 | G26: =G25/G23 -> 0.3612013 | H26: =H25/H23 -> 0.35081374 | I26: =I25/I23 -> 0.30276186 | J26: =J25/J23 -> 0.32552083 | ... U26: =U25/U23 -> 0.28032037 | V26: 0.26 | W26: =W25/W23 -> 0.27932487 | X26: 0.26 | Y26: 0.26 | Z26: =Z25/Z23 -> 0.26 | AA26: 0.26 | AB26: 0.26 | AC26: =AC25/AC23 -> 0.26 | AD26: 0.26 | AE26: 0.26 | AF26: =AF25/AF23 -> 0.26 | AG26: 0.26 | AH26: 0.26 | AI26: =AI25/AI23 -> 0.26
B27: Profit of associates | C27: 0 | D27: =E27-C27 -> 0.3 | E27: 0.3 | F27: 0 | G27: =H27-F27 -> 0.6 | H27: 0.6 | I27: 0.2 | J27: =K27-I27 -> 0.6 | K27: 0.8 | L27: 0.3 | M27: =N27-L27 -> 0.6 | N27: 0.9 | O27: 0.2 | P27: =Q27-O27 -> 0.4 | Q27: 0.6 | R27: 0.1 | S27: =T27-R27 -> 0.4 | T27: 0.5 | U27: 0.1 | V27: =U27 -> 0.1 | W27: =U27+V27 -> 0.2 | Y27: =X27 -> 0 | Z27: =X27+Y27 -> 0 | AB27: =AA27 -> 0 | AC27: =AA27+AB27 -> 0 | AE27: =AD27 -> 0 | AF27: =AD27+AE27 -> 0 | AH27: =AG27 -> 0 | AI27: =AG27+AH27 -> 0
B28: Net profit/loss | C28: =C23-C25+C27 -> 84.3 | D28: =D23-D25+D27 -> 22.5 | E28: =E23-E25+E27 -> 106.8 | F28: =F23-F25+F27 -> 64.9 | G28: =G23-G25+G27 -> 79.3 | H28: =H23-H25+H27 -> 144.2 | I28: =I23-I25+I27 -> 134 | J28: =J23-J25+J27 -> 78.3 | ... T28: =T23-T25+T27 -> 120.7 | U28: =U23-U25+U27+0.1 -> 63.1 | V28: =V23-V25+V27 -> 77.23464 | W28: =W23-W25+W27 -> 133.33464 | X28: =X23-X25+X27 -> 81.87656 | Y28: =Y23-Y25+Y27 -> 81.520502 | Z28: =Z23-Z25+Z27 -> 163.39706 | AA28: =AA23-AA25+AA27 -> 86.366051 | AB28: =AB23-AB25+AB27 -> 86.067341 | AC28: =AC23-AC25+AC27 -> 172.43339 | ... AI28: =AI23-AI25+AI27 -> 195.17307
B29: Net Profit Margin (%) | C29: =C28/C4 -> 0.16090857 | D29: =D28/D4 -> 0.044919146 | E29: =E28/E4 -> 0.10421546 | F29: =F28/F4 -> 0.15064995 | G29: =G28/G4 -> 0.13686572 | H29: =H28/H4 -> 0.14274401 | I29: =I28/I4 -> 0.20765535 | J29: =J28/J4 -> 0.1172858 | ... AI29: =AI28/AI4 -> 0.16739524
B30: Non-controling interests | C30: 0 | D30: =E30-C30 -> 0.1 | E30: 0.1 | F30: 0.1 | G30: =H30-F30 -> -0.1 | H30: 0 | I30: 0 | J30: =K30-I30 -> 0.2 | K30: 0.2 | L30: 0.1 | M30: =N30-L30 -> 0.2 | N30: 0.3 | O30: 0.2 | P30: =Q30-O30 -> 0.2 | Q30: 0.4 | R30: 0.2 | S30: =T30-R30 -> 0.3 | T30: 0.5 | W30: =U30+V30 -> 0 | Z30: =X30+Y30 -> 0 | AC30: =AA30+AB30 -> 0 | AF30: =AD30+AE30 -> 0 | AI30: =AG30+AH30 -> 0
B31: Net Profit before discounted | C31: =C28+C30 -> 84.3 | D31: =D28+D30 -> 22.6 | E31: =E28+E30 -> 106.9 | F31: =F28+F30 -> 65 | G31: =G28+G30 -> 79.2 | H31: =H28+H30 -> 144.2 | I31: =I28+I30 -> 134 | J31: =J28+J30 -> 78.5 | ... AI31: =AI28+AI30 -> 195.17307
B32: Net profit/loss from discontinued | C32: 6.3 | D32: =E32-C32 -> 0.1 | E32: 6.4 | F32: 0 | G32: =H32-F32 -> 0 | H32: 0 | I32: 0 | J32: =K32-I32 -> 0 | K32: 0 | L32: 0 | M32: =N32-L32 -> 0 | N32: 0 | O32: 0 | P32: =Q32-O32 -> 0 | Q32: 0 | R32: 0 | S32: =T32-R32 -> 0 | T32: 0 | U32: -0.1 | W32: =U32+V32 -> -0.1 | Z32: =X32+Y32 -> 0 | AC32: =AA32+AB32 -> 0 | AF32: =AD32+AE32 -> 0 | AI32: =AG32+AH32 -> 0
B33: Net Profit attributable to parents | C33: =C28+C32 -> 90.6 | D33: =D28+D32 -> 22.6 | E33: =E28+E32 -> 113.2 | F33: =F28+F32 -> 64.9 | G33: =G28+G32 -> 79.3 | H33: =H28+H32 -> 144.2 | I33: =I28+I32 -> 134 | J33: =J28+J32 -> 78.3 | ... AI33: =AI28+AI32 -> 195.17307
B35: EPS - continuing operations
B36: Basic | C36: =C33/C44*1000 -> 1.8191565 | D36: =D33/D44*1000 -> 0.4537541 | E36: =E33/E44*1000 -> 2.272786 | F36: =F33/F44*1000 -> 1.3007355 | G36: =G33/G44*1000 -> 1.583767 | H36: =H33/H44*1000 -> 2.8799395 | I36: =I33/I44*1000 -> 2.669389 | J36: =J33/J44*1000 -> 1.5523699 | ... AI36: =AI33/AI44*1000 -> 3.7960128
B37: Diluted | C37: =C33/C45*1000 -> 1.7266072 | D37: =D33/D45*1000 -> 0.43128959 | E37: =E33/E45*1000 -> 2.1602647 | F37: =F33/F45*1000 -> 1.2364702 | G37: =G33/G45*1000 -> 1.5062831 | H37: =H33/H45*1000 -> 2.7390419 | I37: =I33/I45*1000 -> 2.5977944 | J37: =J33/J45*1000 -> 1.5137133 | ... AI37: =AI33/AI45*1000 -> 3.7675913
B39: EPS
B40: Basic | C40: =C31/C44*1000 -> 1.6926589 | D40: =D31/D44*1000 -> 0.4537541 | E40: =E33/E44*1000 -> 2.272786 | F40: =F31/F44*1000 -> 1.3027397 | G40: =G31/G44*1000 -> 1.5817698 | H40: =H31/H44*1000 -> 2.8799395 | I40: =I31/I44*1000 -> 2.669389 | J40: =J31/J44*1000 -> 1.5563351 | K40: =K31/K44*1000 -> 4.2130089 | L40: =L31/L44*1000 -> 4.3932397 | M40: =M31/M44*1000 -> 1.3840602 | ... AI40: =AI31/AI44*1000 -> 3.7960128
B41: Diluted | C41: =C31/C45*1000 -> 1.6065451 | D41: =D31/D45*1000 -> 0.43128959 | E41: =E33/E45*1000 -> 2.1602647 | F41: =F31/F45*1000 -> 1.2383754 | G41: =G31/G45*1000 -> 1.5043836 | H41: =H31/H45*1000 -> 2.7390419 | I41: =I31/I45*1000 -> 2.5977944 | J41: =J31/J45*1000 -> 1.5175798 | K41: =K31/K45*1000 -> 4.1080981 | L41: =L31/L45*1000 -> 4.3151737 | M41: =M31/M45*1000 -> 1.3604365 | ... AI41: =AI31/AI45*1000 -> 3.7675913
B43: No. of shares
B44: Basic | C44: 49803.302 | D44: =E44 -> 49806.712 | E44: 49806.712 | F44: 49894.848 | G44: =H44 -> 50070.497 | H44: 50070.497 | I44: 50198.754 | J44: =K44 -> 50439.01 | K44: 50439.01 | L44: 50896.381 | M44: =N44 -> 50720.336 | N44: 50720.336 | O44: 50508.715 | P44: =Q44 -> 50719.758 | Q44: 50719.758 | R44: 50967.846 | S44: =T44 -> 51415.283 | T44: 51415.283 | U44: 51902.383 | V44: =S44 -> 51415.283 | W44: =T44 -> 51415.283 | X44: =U44 -> 51902.383 | Y44: =V44 -> 51415.283 | Z44: =W44 -> 51415.283 | AA44: =X44 -> 51902.383 | AB44: =Y44 -> 51415.283 | AC44: =Z44 -> 51415.283 | ... AI44: =AF44 -> 51415.283
...

Sheet Schedules
B2: Schedules | C2: ='Financial Statements'!C47 -> H1'20 | D2: ='Financial Statements'!D47 -> H2'20 | E2: ='Financial Statements'!E47 -> FY20 | F2: ='Financial Statements'!F47 -> H1'21 | G2: ='Financial Statements'!G47 -> H2'21 | H2: ='Financial Statements'!H47 -> FY21 | I2: ='Financial Statements'!I47 -> H1'22 | J2: ='Financial Statements'!J47 -> H2'22 | ... R2: ='Financial Statements'!R47 -> H1'25 | S2: H2'25 | T2: FY25 | U2: ='Financial Statements'!U47 -> H1'26 | V2: ='Financial Statements'!V47 -> H2'26 | W2: ='Financial Statements'!W47 -> FY26 | X2: ='Financial Statements'!X47 -> H1'27 | Y2: ='Financial Statements'!Y47 -> H2'27 | Z2: ='Financial Statements'!Z47 -> FY27 | AA2: ='Financial Statements'!AA47 -> H1'28 | AB2: ='Financial Statements'!AB47 -> H2'28 | ... AI2: ='Financial Statements'!AI47 -> FY30
B3: PP&E
B4: Opening Value | P4: =O9 -> 735.1 | Q4: =P4 -> 735.1 | R4: =Q9 -> 764.9 | S4: =R9 -> 778.8 | T4: =S4 -> 778.8 | U4: =T9 -> 807.2 | V4: =U9 -> 801.9 | W4: =T9 -> 807.2 | X4: =W9 -> 826.211 | Y4: =X9 -> 851.6836 | Z4: =W9 -> 826.211 | AA4: =Z9 -> 876.99997 | AB4: =AA9 -> 903.50594 | AC4: =Z9 -> 876.99997 | AD4: =AC9 -> 929.87119 | AE4: =AD9 -> 957.45303 | AF4: =AC9 -> 929.87119 | AG4: =AF9 -> 984.91273 | AH4: =AG9 -> 1014.0258 | AI4: =AF9 -> 984.91273
B5: Acquisitions | O5: =-'Financial Statements'!O109 -> 45.8 | R5: 16.6 | U5: 11.4 | V5: =V6*'Financial Statements'!V4 -> 24.311 | W5: =SUM(U5:V5) -> 35.711 | X5: =X6*'Financial Statements'!X4 -> 25.4726 | Y5: =Y6*'Financial Statements'!Y4 -> 25.316368 | Z5: =SUM(X5:Y5) -> 50.788968 | AA5: =AA6*'Financial Statements'!AA4 -> 26.505976 | AB5: =AB6*'Financial Statements'!AB4 -> 26.365244 | AC5: =SUM(AA5:AB5) -> 52.87122 | AD5: =AD6*'Financial Statements'!AD4 -> 27.581845 | AE5: =AE6*'Financial Statements'!AE4 -> 27.459696 | AF5: =SUM(AD5:AE5) -> 55.041541 | AG5: =AG6*'Financial Statements'!AG4 -> 29.113024 | AH5: =AH6*'Financial Statements'!AH4 -> 29.184055 | AI5: =SUM(AG5:AH5) -> 58.297079
B6: Capex/sales Ratio | O6: =O5/'Financial Statements'!O4 -> 0.071933407 | P6: =P5/'Financial Statements'!P4 -> 0 | Q6: =Q5/'Financial Statements'!Q4 -> 0 | R6: =R5/'Financial Statements'!R4 -> 0.031103616 | S6: =S5/'Financial Statements'!S4 -> 0 | T6: =T5/'Financial Statements'!T4 -> 0 | U6: =U5/'Financial Statements'!U4 -> 0.023284314 | V6: 0.05 | W6: =W5/'Financial Statements'!W4 -> 0.036595889 | X6: 0.05 | Y6: 0.05 | Z6: =Z5/'Financial Statements'!Z4 -> 0.05 | AA6: 0.05 | AB6: 0.05 | AC6: =AC5/'Financial Statements'!AC4 -> 0.05 | AD6: 0.05 | AE6: 0.05 | AF6: =AF5/'Financial Statements'!AF4 -> 0.05 | AG6: 0.05 | AH6: 0.05 | AI6: =AI5/'Financial Statements'!AI4 -> 0.05 | AK6: =+S5-S11 -> 0
B7: Disposals | O7: =O4+O5-O11-O15 -> -406 | R7: -0.2 | U7: -2.1 | W7: =SUM(U7:V7) -> -2.1 | Z7: =SUM(X7:Y7) -> 0 | AC7: =SUM(AA7:AB7) -> 0 | AF7: =SUM(AD7:AE7) -> 0 | AI7: =SUM(AG7:AH7) -> 0
B8: Other adjustments | R8: =0.1-2.6 -> -2.5 | U8: =-0.1-14.4 -> -14.5 | W8: =SUM(U8:V8) -> -14.5
B9: Gross Value | O9: 735.1 | P9: 764.9 | Q9: =P9 -> 764.9 | R9: =R4+R5+R7+R8 -> 778.8 | S9: 807.2 | T9: =S9 -> 807.2 | U9: =U4+U5+U7+U8-0.1 -> 801.9 | V9: =V4+V5+V7+V8 -> 826.211 | W9: =W4+W5+W7+W8-0.1 -> 826.211 | X9: =X4+X5+X7+X8 -> 851.6836 | Y9: =Y4+Y5+Y7+Y8 -> 876.99997 | Z9: =Z4+Z5+Z7+Z8 -> 876.99997 | AA9: =AA4+AA5+AA7+AA8 -> 903.50594 | AB9: =AB4+AB5+AB7+AB8 -> 929.87119 | AC9: =AC4+AC5+AC7+AC8 -> 929.87119 | AD9: =AD4+AD5+AD7+AD8 -> 957.45303 | AE9: =AE4+AE5+AE7+AE8 -> 984.91273 | ... AI9: =AI4+AI5+AI7+AI8 -> 1043.2098
B10: Accumulated depreciation - Opening | P10: 304.9 | Q10: =P10 -> 304.9 | R10: =Q14 -> 314.3 | S10: 304.9 | T10: =S10 -> 304.9 | U10: =T14 -> 342.8 | V10: =U14 -> 351.7 | W10: =T14 -> 342.8 | X10: =W14 -> 367.738 | Y10: =X14 -> 384.26222 | Z10: =W14 -> 367.738 | AA10: =Z14 -> 401.29589 | AB10: =AA14 -> 418.83589 | AC10: =Z14 -> 401.29589 | AD10: =AC14 -> 436.90601 | AE10: =AD14 -> 455.50343 | AF10: =AC14 -> 436.90601 | AG10: =AF14 -> 474.65249 | AH10: =AG14 -> 494.35075 | AI10: =AF14 -> 474.65249
B11: Depeciation charge for the year | O11: ='Financial Statements'!O16 -> 21.6 | Q11: ='Financial Statements'!Q16 -> 45.1 | R11: 15.4 | T11: ='Financial Statements'!T16 -> 46.8 | U11: 16.2 | V11: =V12*V4 -> 16.038 | W11: =SUM(U11:V11) -> 32.238 | X11: =X12*X4 -> 16.52422 | Y11: =Y12*Y4 -> 17.033672 | Z11: =SUM(X11:Y11) -> 33.557892 | AA11: =AA12*AA4 -> 17.539999 | AB11: =AB12*AB4 -> 18.070119 | AC11: =SUM(AA11:AB11) -> 35.610118 | AD11: =AD12*AD4 -> 18.597424 | AE11: =AE12*AE4 -> 19.149061 | AF11: =SUM(AD11:AE11) -> 37.746484 | AG11: =AG12*AG4 -> 19.698255 | AH11: =AH12*AH4 -> 20.280515 | AI11: =SUM(AG11:AH11) -> 39.97877
B12: Depreciation rate (%) | O12: =O11/O4 -> #DIV/0! | P12: =P11/P4 -> 0 | Q12: =Q11/Q4 -> 0.061352197 | R12: =R11/R4 -> 0.020133351 | S12: =S11/S4 -> 0 | T12: =T11/T4 -> 0.06009245 | U12: =U11/U4 -> 0.020069376 | V12: 0.02 | W12: =W11/W4 -> 0.039938057 | X12: 0.02 | Y12: 0.02 | Z12: =Z11/Z4 -> 0.040616612 | AA12: 0.02 | AB12: 0.02 | AC12: =AC11/AC4 -> 0.040604469 | AD12: 0.02 | AE12: 0.02 | AF12: =AF11/AF4 -> 0.04059324 | AG12: 0.02 | AH12: 0.02 | AI12: =AI11/AI4 -> 0.04059118
B13: Other adjustments | R13: =-1.1+0-0.2 -> -1.3 | U13: -7.3 | W13: =SUM(U13:V13) -> -7.3
B14: Accumulated depreciation and impairments | O14: 304.9 | P14: 314.3 | Q14: =P14 -> 314.3 | R14: =R10+R11+R13 -> 328.4 | S14: 342.8 | T14: =S14 -> 342.8 | U14: =U10+U11+U13 -> 351.7 | V14: =V10+V11+V13 -> 367.738 | W14: =W10+W11+W13 -> 367.738 | X14: =X10+X11+X13 -> 384.26222 | Y14: =Y10+Y11+Y13 -> 401.29589 | Z14: =Z10+Z11+Z13 -> 401.29589 | AA14: =AA10+AA11+AA13 -> 418.83589 | AB14: =AB10+AB11+AB13 -> 436.90601 | ... AI14: =AI10+AI11+AI13 -> 514.63126
B15: Net Value | O15: =O9-O14 -> 430.2 | P15: ='Financial Statements'!P51 -> 450.6 | Q15: =Q9-Q14 -> 450.6 | R15: =R9-R14 -> 450.4 | S15: ='Financial Statements'!S51 -> 464.4 | T15: 464.4 | U15: =U9-U14 -> 450.2 | V15: =V9-V14 -> 458.473 | W15: =W9-W14 -> 458.473 | X15: =X9-X14 -> 467.42138 | Y15: =Y9-Y14 -> 475.70408 | Z15: =Z9-Z14 -> 475.70408 | AA15: =AA9-AA14 -> 484.67005 | AB15: =AB9-AB14 -> 492.96518 | ... AI15: =AI9-AI14 -> 528.57854
B17: Goodwill
B18: Opening Value | P18: =O23 -> 647.4 | Q18: =P18 -> 647.4 | R18: =Q23 -> 648.7 | S18: =R23 -> 648.8 | T18: =S18 -> 648.8 | U18: =T23 -> 648.7 | V18: =U23 -> 647.3 | W18: =T23 -> 648.7 | X18: =W23 -> 647.3 | Y18: =X23 -> 647.3 | Z18: =W23 -> 647.3 | AA18: =Z23 -> 647.3 | AB18: =AA23 -> 647.3 | AC18: =Z23 -> 647.3 | AD18: =AC23 -> 647.3 | AE18: =AD23 -> 647.3 | AF18: =AC23 -> 647.3 | AG18: =AF23 -> 647.3 | AH18: =AG23 -> 647.3 | AI18: =AF23 -> 647.3
B19: Acquisitions | O19: =-'Financial Statements'!O123 -> -306.7 | R19: 1.7 | V19: =V20*'Financial Statements'!V21 -> 0 | W19: =SUM(U19:V19) -> 0 | X19: =X20*'Financial Statements'!X21 -> 0 | Y19: =Y20*'Financial Statements'!Y21 -> 0 | Z19: =SUM(X19:Y19) -> 0 | AA19: =AA20*'Financial Statements'!AA21 -> 0 | AB19: =AB20*'Financial Statements'!AB21 -> 0 | AC19: =SUM(AA19:AB19) -> 0 | AD19: =AD20*'Financial Statements'!AD21 -> 0 | AE19: =AE20*'Financial Statements'!AE21 -> 0 | AF19: =SUM(AD19:AE19) -> 0 | AG19: =AG20*'Financial Statements'!AG21 -> 0 | AH19: =AH20*'Financial Statements'!AH21 -> 0 | AI19: =SUM(AG19:AH19) -> 0
B20: Capex/sales Ratio | O20: =O19/'Financial Statements'!O21 -> -26.213675 | P20: =P19/'Financial Statements'!P21 -> 0 | Q20: =Q19/'Financial Statements'!Q21 -> 0 | R20: =R19/'Financial Statements'!R21 -> 0.10179641 | S20: =S19/'Financial Statements'!S21 -> 0 | T20: =T19/'Financial Statements'!T21 -> 0 | U20: =U19/'Financial Statements'!U21 -> 0 | W20: =W19/'Financial Statements'!W21 -> 0 | Z20: =Z19/'Financial Statements'!Z21 -> 0 | AC20: =AC19/'Financial Statements'!AC21 -> 0 | AF20: =AF19/'Financial Statements'!AF21 -> 0 | AI20: =AI19/'Financial Statements'!AI21 -> 0
B21: Disposals | O21: =O18+O19-O25-O29 -> -812.4 | R21: 0 | W21: =SUM(U21:V21) -> 0 | Z21: =SUM(X21:Y21) -> 0 | AC21: =SUM(AA21:AB21) -> 0 | AF21: =SUM(AD21:AE21) -> 0 | AI21: =SUM(AG21:AH21) -> 0
B22: Other adjustments | R22: =-0.1-1.4 -> -1.5 | U22: =-0.1-1.4 -> -1.5 | W22: =SUM(U22:V22) -> -1.5
B23: Gross Value | O23: 647.4 | P23: 648.7 | Q23: =P23 -> 648.7 | R23: =R18+R19+R21+R22-0.1 -> 648.8 | S23: 648.7 | T23: =S23 -> 648.7 | U23: =U18+U19+U21+U22+0.1 -> 647.3 | V23: =V18+V19+V21+V22 -> 647.3 | W23: =W18+W19+W21+W22+0.1 -> 647.3 | X23: =X18+X19+X21+X22 -> 647.3 | Y23: =Y18+Y19+Y21+Y22 -> 647.3 | Z23: =Z18+Z19+Z21+Z22 -> 647.3 | AA23: =AA18+AA19+AA21+AA22 -> 647.3 | AB23: =AB18+AB19+AB21+AB22 -> 647.3 | AC23: =AC18+AC19+AC21+AC22 -> 647.3 | AD23: =AD18+AD19+AD21+AD22 -> 647.3 | AE23: =AE18+AE19+AE21+AE22 -> 647.3 | ... AI23: =AI18+AI19+AI21+AI22 -> 647.3
B24: Accumulated amortization - Opening | P24: =O28 -> 141.7 | Q24: =P24 -> 141.7 | R24: =Q28 -> 143.9 | S24: =R28 -> 145.1 | T24: =S24 -> 145.1 | U24: 149.5 | V24: =U28 -> 148.2 | W24: 149.5 | X24: =W24+X25 -> 149.5 | Y24: =X24+Y25 -> 149.5 | Z24: =Y24 -> 149.5 | AA24: =Z24+AA25 -> 149.5 | AB24: =AA24+AB25 -> 149.5 | AC24: =AB24 -> 149.5 | AD24: =AC24+AD25 -> 149.5 | AE24: =AD24+AE25 -> 149.5 | AF24: =AE24 -> 149.5 | AG24: =AF24+AG25 -> 149.5 | AH24: =AG24+AH25 -> 149.5 | AI24: =AH24 -> 149.5
B25: Depeciation charge for the year | O25: ='Financial Statements'!O32 -> 0 | Q25: ='Financial Statements'!Q32 -> 0 | R25: 3.1 | T25: ='Financial Statements'!T32 -> 0 | U25: -1.3 | V25: =V26*V18 -> 0 | W25: =SUM(U25:V25) -> -1.3 | X25: =X26*X18 -> 0 | Y25: =Y26*Y18 -> 0 | Z25: =SUM(X25:Y25) -> 0 | AA25: =AA26*AA18 -> 0 | AB25: =AB26*AB18 -> 0 | AC25: =SUM(AA25:AB25) -> 0 | AD25: =AD26*AD18 -> 0 | AE25: =AE26*AE18 -> 0 | AF25: =SUM(AD25:AE25) -> 0 | AG25: =AG26*AG18 -> 0 | AH25: =AH26*AH18 -> 0 | AI25: =SUM(AG25:AH25) -> 0
B26: Depreciation rate (%) | O26: =O25/O18 -> #DIV/0! | P26: =P25/P18 -> 0 | Q26: =Q25/Q18 -> 0 | R26: =R25/R18 -> 0.0047787883 | S26: =S25/S18 -> 0 | T26: =T25/T18 -> 0 | U26: =U25/U18 -> -0.002004008 | W26: =W25/W18 -> -0.002004008 | Z26: =Z25/Z18 -> 0 | AC26: =AC25/AC18 -> 0 | AF26: =AF25/AF18 -> 0 | AI26: =AI25/AI18 -> 0
B27: Other adjustments | R27: -1.9
B28: Accumulated amortization | O28: 141.7 | P28: 143.9 | Q28: =P28 -> 143.9 | R28: =R24+R25+R27 -> 145.1 | S28: 143.9 | T28: =S28 -> 143.9 | U28: =U24+U25+U27 -> 148.2 | V28: =U28 -> 148.2 | W28: =W24+W25 -> 148.2 | X28: =W28 -> 148.2 | Y28: =X28 -> 148.2 | Z28: =W28 -> 148.2 | AA28: =Z28 -> 148.2 | AB28: =AA28 -> 148.2 | AC28: =Z28 -> 148.2 | AD28: =AC28 -> 148.2 | AE28: =AD28 -> 148.2 | AF28: =AC28 -> 148.2 | AG28: =AF28 -> 148.2 | AH28: =AG28 -> 148.2 | AI28: =AF28 -> 148.2
B29: Net Value | O29: =O23-O28 -> 505.7 | P29: =P23-P28 -> 504.8 | Q29: =Q23-Q28 -> 504.8 | R29: =R23-R28 -> 503.7 | S29: 503.5 | T29: =T23-T28 -> 504.8 | U29: =U23-U28-0.1 -> 499 | V29: =V23-V28 -> 499.1 | W29: =W23-W28 -> 499.1 | X29: =X23-X28+0.1 -> 499.2 | Y29: =Y23-Y28+0.1 -> 499.2 | Z29: =Z23-Z28+0.1 -> 499.2 | AA29: =AA23-AA28+0.1 -> 499.2 | AB29: =AB23-AB28+0.1 -> 499.2 | AC29: =AC23-AC28+0.1 -> 499.2 | AD29: =AD23-AD28+0.1 -> 499.2 | AE29: =AE23-AE28+0.1 -> 499.2 | ... AI29: =AI23-AI28+0.1 -> 499.2
B31: Right-of-use assets – IFRS 16
B32: Opening Value | P32: =O37 -> 64 | Q32: =P32 -> 64 | R32: =Q37 -> 58.1 | S32: =R37 -> 52.9 | T32: =S32 -> 52.9 | U32: 58.8 | V32: =U37 -> 52.4 | W32: 58.8 | X32: =W37 -> 52.4 | Y32: =X37 -> 52.4 | Z32: =W37 -> 52.4 | AA32: =Z37 -> 52.4 | AB32: =AA37 -> 52.4 | AC32: =Z37 -> 52.4 | AD32: =AC37 -> 52.4 | AE32: =AD37 -> 52.4 | AF32: =AC37 -> 52.4 | AG32: =AF37 -> 52.4 | AH32: =AG37 -> 52.4 | AI32: =AF37 -> 52.4
B33: Acquisitions | O33: =-'Financial Statements'!O137 -> 0 | R33: 0.2 | V33: =V34*'Financial Statements'!V35 -> 0 | W33: =SUM(U33:V33) -> 0 | X33: =X34*'Financial Statements'!X35 -> 0 | Y33: =Y34*'Financial Statements'!Y35 -> 0 | Z33: =SUM(X33:Y33) -> 0 | AA33: =AA34*'Financial Statements'!AA35 -> 0 | AB33: =AB34*'Financial Statements'!AB35 -> 0 | AC33: =SUM(AA33:AB33) -> 0 | AD33: =AD34*'Financial Statements'!AD35 -> 0 | AE33: =AE34*'Financial Statements'!AE35 -> 0 | AF33: =SUM(AD33:AE33) -> 0 | AG33: =AG34*'Financial Statements'!AG35 -> 0 | AH33: =AH34*'Financial Statements'!AH35 -> 0 | AI33: =SUM(AG33:AH33) -> 0
B34: Capex/sales Ratio | O34: =O33/'Financial Statements'!O35 -> #DIV/0! | P34: =P33/'Financial Statements'!P35 -> #DIV/0! | Q34: =Q33/'Financial Statements'!Q35 -> #DIV/0! | R34: =R33/'Financial Statements'!R35 -> #DIV/0! | S34: =S33/'Financial Statements'!S35 -> #DIV/0! | T34: =T33/'Financial Statements'!T35 -> #DIV/0! | U34: =U33/'Financial Statements'!U35 -> #DIV/0! | W34: =W33/'Financial Statements'!W35 -> #DIV/0! | Z34: =Z33/'Financial Statements'!Z35 -> #DIV/0! | AC34: =AC33/'Financial Statements'!AC35 -> #DIV/0! | AF34: =AF33/'Financial Statements'!AF35 -> #DIV/0! | AI34: =AI33/'Financial Statements'!AI35 -> #DIV/0!
B35: Disposals | R35: 0 | W35: =SUM(U35:V35) -> 0 | Z35: =SUM(X35:Y35) -> 0 | AC35: =SUM(AA35:AB35) -> 0 | AF35: =SUM(AD35:AE35) -> 0 | AI35: =SUM(AG35:AH35) -> 0
B36: Other adjustments | R36: =-4.6-0.7 -> -5.3 | U36: =-3.6-2.8 -> -6.4 | W36: =SUM(U36:V36) -> -6.4
B37: Gross Value | O37: 64 | P37: 58.1 | Q37: =P37 -> 58.1 | R37: =R32+R33+R35+R36-0.1 -> 52.9 | S37: 58.1 | T37: =S37 -> 58.1 | U37: =U32+U33+U35+U36 -> 52.4 | V37: =V32+V33+V35+V36 -> 52.4 | W37: =W32+W33+W35+W36 -> 52.4 | X37: =X32+X33+X35+X36 -> 52.4 | Y37: =Y32+Y33+Y35+Y36 -> 52.4 | Z37: =Z32+Z33+Z35+Z36 -> 52.4 | AA37: =AA32+AA33+AA35+AA36 -> 52.4 | AB37: =AB32+AB33+AB35+AB36 -> 52.4 | ... AI37: =AI32+AI33+AI35+AI36 -> 52.4
B38: Accumulated amortization - Opening | Q38: =P38 -> 0 | R38: =Q42 -> 21.7 | T38: =S38 -> 0 | U38: 26.5 | V38: =U42 -> 25.7 | W38: =U38 -> 26.5 | X38: =W42 -> 25.7 | Y38: =X42 -> 25.7 | Z38: =X38 -> 25.7 | AA38: =Z42 -> 25.7 | AB38: =AA42 -> 25.7 | AC38: =AA38 -> 25.7 | AD38: =AC42 -> 25.7 | AE38: =AD42 -> 25.7 | AF38: =AD38 -> 25.7 | AG38: =AF42 -> 25.7 | AH38: =AG42 -> 25.7 | AI38: =AG38 -> 25.7
B39: Depeciation charge for the year | O39: ='Financial Statements'!O46 -> 0 | Q39: ='Financial Statements'!Q46 -> 0 | R39: 4.4 | T39: ='Financial Statements'!T46 -> 0 | U39: 4 | V39: =V40*V32 -> 0 | W39: =SUM(U39:V39) -> 4 | X39: =X40*X32 -> 0 | Y39: =Y40*Y32 -> 0 | Z39: =SUM(X39:Y39) -> 0 | AA39: =AA40*AA32 -> 0 | AB39: =AB40*AB32 -> 0 | AC39: =SUM(AA39:AB39) -> 0 | AD39: =AD40*AD32 -> 0 | AE39: =AE40*AE32 -> 0 | AF39: =SUM(AD39:AE39) -> 0 | AG39: =AG40*AG32 -> 0 | AH39: =AH40*AH32 -> 0 | AI39: =SUM(AG39:AH39) -> 0
B40: Depreciation rate (%) | O40: =O39/O32 -> #DIV/0! | P40: =P39/P32 -> 0 | Q40: =Q39/Q32 -> 0 | R40: =R39/R32 -> 0.075731497 | S40: =S39/S32 -> 0 | T40: =T39/T32 -> 0 | U40: =U39/U32 -> 0.068027211 | V40: 0 | W40: =W39/W32 -> 0.068027211 | X40: 0 | Y40: 0 | Z40: =Z39/Z32 -> 0 | AA40: 0 | AB40: 0 | AC40: =AC39/AC32 -> 0 | AD40: 0 | AE40: 0 | AF40: =AF39/AF32 -> 0 | AG40: 0 | AH40: 0 | AI40: =AI39/AI32 -> 0
B41: Other adjustments | R41: 4.8 | U41: -4.8 | W41: =SUM(U41:V41) -> -4.8
B42: Accumulated amortization | O42: 30.8 | P42: 21.7 | Q42: =P42 -> 21.7 | R42: =R38-R41+R39 -> 21.3 | S42: 21.7 | T42: =S42 -> 21.7 | U42: =U38+U41+U39 -> 25.7 | V42: =V38+V41+V39 -> 25.7 | W42: =W38+W41+W39 -> 25.7 | X42: =X38+X39 -> 25.7 | Y42: =Y38+Y39 -> 25.7 | Z42: =Z38+Z39 -> 25.7 | AA42: =AA38+AA39 -> 25.7 | AB42: =AB38+AB39 -> 25.7 | AC42: =AC38+AC39 -> 25.7 | AD42: =AD38+AD39 -> 25.7 | AE42: =AE38+AE39 -> 25.7 | ... AI42: =AI38+AI39 -> 25.7
B43: Net Value | O43: =O37-O42 -> 33.2 | P43: =P37-P42 -> 36.4 | Q43: =Q37-Q42 -> 36.4 | R43: =R37-R42 -> 31.6 | S43: =S37-S42 -> 36.4 | T43: =T37-T42 -> 36.4 | U43: =U37-U42-0.1 -> 26.6 | V43: =V37-V42 -> 26.7 | W43: =W37-W42 -> 26.7 | X43: =X37-X42 -> 26.7 | Y43: =Y37-Y42 -> 26.7 | Z43: =Z37-Z42 -> 26.7 | AA43: =AA37-AA42 -> 26.7 | AB43: =AB37-AB42 -> 26.7 | AC43: =AC37-AC42 -> 26.7 | ... AI43: =AI37-AI42 -> 26.7
...

Sheet Ratio Analysis
B2: Income Statement | C2: ='Financial Statements'!C3 -> H1'20 | D2: ='Financial Statements'!D3 -> H2'20 | E2: ='Financial Statements'!E3 -> FY20 | F2: ='Financial Statements'!F3 -> H1'21 | G2: ='Financial Statements'!G3 -> H2'21 | H2: ='Financial Statements'!H3 -> FY21 | I2: ='Financial Statements'!I3 -> H1'22 | J2: ='Financial Statements'!J3 -> H2'22 | ... AI2: ='Financial Statements'!AI3 -> FY30
B4: Actvity Ratios (Utilising resources)
B6: DIO | C6: =Schedules!C60 -> 1322.4772 | D6: =Schedules!D60 -> 1448.5995 | E6: =Schedules!E60 -> 1434.8589 | F6: =Schedules!F60 -> 1653.0519 | G6: =Schedules!G60 -> 1531.0919 | H6: =Schedules!H60 -> 1650.2954 | I6: =Schedules!I60 -> 1384.4007 | J6: =Schedules!J60 -> 1388.0826 | ... AI6: =Schedules!AI60 -> 2600
B7: DSO | C7: =Schedules!C61 -> 87.186104 | D7: =Schedules!D61 -> 72.849271 | E7: =Schedules!E61 -> 71.214286 | F7: =Schedules!F61 -> 114.59204 | G7: =Schedules!G61 -> 49.798498 | H7: =Schedules!H61 -> 57.123837 | I7: =Schedules!I61 -> 80.997985 | J7: =Schedules!J61 -> 69.325944 | ... AI7: =Schedules!AI61 -> 125
B8: DPO | C8: =Schedules!C62 -> 494.70444 | D8: =Schedules!D62 -> 567.58677 | E8: =Schedules!E62 -> 562.20293 | F8: =Schedules!F62 -> 597.98127 | G8: =Schedules!G62 -> 601.25492 | H8: =Schedules!H62 -> 648.06574 | I8: =Schedules!I62 -> 549.97116 | J8: =Schedules!J62 -> 587.1104 | ... AI8: =Schedules!AI62 -> 605
B9: Cash Conversion Cycle | C9: =C6+C7-C8 -> 914.95888 | D9: =D6+D7-D8 -> 953.86204 | E9: =E6+E7-E8 -> 943.87022 | F9: =F6+F7-F8 -> 1169.6627 | G9: =G6+G7-G8 -> 979.63549 | H9: =H6+H7-H8 -> 1059.3535 | I9: =I6+I7-I8 -> 915.42752 | J9: =J6+J7-J8 -> 870.29817 | ... AI9: =AI6+AI7-AI8 -> 2120
B10: Fixed Assets Turnover | C10: ='Financial Statements'!C4/('Financial Statements'!C50+'Financial Statements'!C51) -> 1.7527601 | D10: ='Financial Statements'!D4/('Financial Statements'!D50+'Financial Statements'!D51) -> 1.5137504 | E10: ='Financial Statements'!E4/('Financial Statements'!E50+'Financial Statements'!E51) -> 3.0970082 | F10: ='Financial Statements'!F4/('Financial Statements'!F50+'Financial Statements'!F51) -> 1.3214724 | G10: ='Financial Statements'!G4/('Financial Statements'!G50+'Financial Statements'!G51) -> 1.6367232 | H10: ='Financial Statements'!H4/('Financial Statements'!H50+'Financial Statements'!H51) -> 2.8536723 | I10: ='Financial Statements'!I4/('Financial Statements'!I50+'Financial Statements'!I51) -> 1.8228814 | J10: ='Financial Statements'!J4/('Financial Statements'!J50+'Financial Statements'!J51) -> 1.7017589 | ... AI10: ='Financial Statements'!AI4/('Financial Statements'!AI50+'Financial Statements'!AI51) -> 2.10012
B11: Working Capital Turnover | C11: ='Financial Statements'!C4/('Financial Statements'!C62-'Financial Statements'!C86) -> 0.49677603 | D11: ='Financial Statements'!D4/('Financial Statements'!D62-'Financial Statements'!D86) -> 0.49761574 | E11: ='Financial Statements'!E4/('Financial Statements'!E62-'Financial Statements'!E86) -> 1.0179795 | F11: ='Financial Statements'!F4/('Financial Statements'!F62-'Financial Statements'!F86) -> 0.38228769 | G11: ='Financial Statements'!G4/('Financial Statements'!G62-'Financial Statements'!G86) -> 0.50762222 | H11: ='Financial Statements'!H4/('Financial Statements'!H62-'Financial Statements'!H86) -> 0.88505344 | I11: ='Financial Statements'!I4/('Financial Statements'!I62-'Financial Statements'!I86) -> 0.60591549 | J11: ='Financial Statements'!J4/('Financial Statements'!J62-'Financial Statements'!J86) -> 0.59137213 | ... AI11: ='Financial Statements'!AI4/('Financial Statements'!AI62-'Financial Statements'!AI86) -> 0.54210799
B12: Total Assets Turnover | C12: ='Financial Statements'!C4/'Financial Statements'!C63 -> 0.20296761 | D12: ='Financial Statements'!D4/'Financial Statements'!D63 -> 0.1796113 | E12: ='Financial Statements'!E4/'Financial Statements'!E63 -> 0.36748306 | F12: ='Financial Statements'!F4/'Financial Statements'!F63 -> 0.16466002 | G12: ='Financial Statements'!G4/'Financial Statements'!G63 -> 0.20833483 | H12: ='Financial Statements'!H4/'Financial Statements'!H63 -> 0.36323757 | I12: ='Financial Statements'!I4/'Financial Statements'!I63 -> 0.22766723 | J12: ='Financial Statements'!J4/'Financial Statements'!J63 -> 0.22413967 | ... AI12: ='Financial Statements'!AI4/'Financial Statements'!AI63 -> 0.27976066
B13: Equity Turnover | C13: ='Financial Statements'!C4/'Financial Statements'!C72 -> 0.37870464 | D13: ='Financial Statements'!D4/'Financial Statements'!D72 -> 0.35694435 | E13: ='Financial Statements'!E4/'Financial Statements'!E72 -> 0.73027863 | F13: ='Financial Statements'!F4/'Financial Statements'!F72 -> 0.29392099 | G13: ='Financial Statements'!G4/'Financial Statements'!G72 -> 0.37399948 | H13: ='Financial Statements'!H4/'Financial Statements'!H72 -> 0.65207849 | I13: ='Financial Statements'!I4/'Financial Statements'!I72 -> 0.40700095 | J13: ='Financial Statements'!J4/'Financial Statements'!J72 -> 0.40175724 | ... AI13: ='Financial Statements'!AI4/'Financial Statements'!AI72 -> 0.42951818
T14: ='Financial Statements'!T57/'Financial Statements'!T4 -> 2.1385334
B16: Liquidity Ratios
B18: Current Ratio | C18: ='Financial Statements'!C62/'Financial Statements'!C86 -> 2.7748233 | D18: ='Financial Statements'!D62/'Financial Statements'!D86 -> 2.1960551 | E18: ='Financial Statements'!E62/'Financial Statements'!E86 -> 2.1963161 | F18: ='Financial Statements'!F62/'Financial Statements'!F86 -> 2.80304 | G18: ='Financial Statements'!G62/'Financial Statements'!G86 -> 2.5857183 | H18: ='Financial Statements'!H62/'Financial Statements'!H86 -> 2.5857183 | I18: ='Financial Statements'!I62/'Financial Statements'!I86 -> 2.2675553 | J18: ='Financial Statements'!J62/'Financial Statements'!J86 -> 2.3017758 | ... AI18: ='Financial Statements'!AI62/'Financial Statements'!AI86 -> 3.3296595
B19: Quick Ratio | C19: =('Financial Statements'!C62-'Financial Statements'!C61)/'Financial Statements'!C86 -> 2.5627735 | D19: =('Financial Statements'!D62-'Financial Statements'!D61)/'Financial Statements'!D86 -> 1.8759506 | E19: =('Financial Statements'!E62-'Financial Statements'!E61)/'Financial Statements'!E86 -> 1.8761735 | F19: =('Financial Statements'!F62-'Financial Statements'!F61)/'Financial Statements'!F86 -> 2.65968 | G19: =('Financial Statements'!G62-'Financial Statements'!G61)/'Financial Statements'!G86 -> 2.306474 | H19: =('Financial Statements'!H62-'Financial Statements'!H61)/'Financial Statements'!H86 -> 2.306474 | I19: =('Financial Statements'!I62-'Financial Statements'!I61)/'Financial Statements'!I86 -> 2.1494882 | J19: =('Financial Statements'!J62-'Financial Statements'!J61)/'Financial Statements'!J86 -> 2.1676661 | ... AI19: =('Financial Statements'!AI62-'Financial Statements'!AI61)/'Financial Statements'!AI86 -> 3.6007822
B20: Cash ratio | C20: ='Financial Statements'!C61/'Financial Statements'!C86 -> 0.21204981 | D20: ='Financial Statements'!D61/'Financial Statements'!D86 -> 0.32010456 | E20: ='Financial Statements'!E61/'Financial Statements'!E86 -> 0.3201426 | F20: ='Financial Statements'!F61/'Financial Statements'!F86 -> 0.14336 | G20: ='Financial Statements'!G61/'Financial Statements'!G86 -> 0.27924423 | H20: ='Financial Statements'!H61/'Financial Statements'!H86 -> 0.27924423 | I20: ='Financial Statements'!I61/'Financial Statements'!I86 -> 0.11806713 | J20: ='Financial Statements'!J61/'Financial Statements'!J86 -> 0.13410978 | ... AI20: ='Financial Statements'!AI61/'Financial Statements'!AI86 -> -0.27112273
B21: Defensive Interval | C21: =('Financial Statements'!C61+'Financial Statements'!C58)/('Financial Statements'!C8/182.5) -> 326.41429 | D21: =('Financial Statements'!D61+'Financial Statements'!D58)/('Financial Statements'!D8/182.5) -> 339.7776 | E21: =('Financial Statements'!E61+'Financial Statements'!E58)/('Financial Statements'!E8/365) -> 370.5327 | F21: =('Financial Statements'!F61+'Financial Statements'!F58)/('Financial Statements'!F8/182.5) -> 381.19635 | G21: =('Financial Statements'!G61+'Financial Statements'!G58)/('Financial Statements'!G8/182.5) -> 241.20629 | H21: =('Financial Statements'!H61+'Financial Statements'!H58)/('Financial Statements'!H8/365) -> 295.13961 | I21: =('Financial Statements'!I61+'Financial Statements'!I58)/('Financial Statements'!I8/182.5) -> 302.02575 | J21: =('Financial Statements'!J61+'Financial Statements'!J58)/('Financial Statements'!J8/182.5) -> 202.29772 | K21: =('Financial Statements'!K61+'Financial Statements'!K58)/('Financial Statements'!K8/365) -> 238.2451 | L21: =('Financial Statements'!L61+'Financial Statements'!L58)/('Financial Statements'!L8/182.5) -> 290.29731 | M21: =('Financial Statements'!M61+'Financial Statements'!M58)/('Financial Statements'!M8/182.5) -> 168.97783 | N21: =('Financial Statements'!N61+'Financial Statements'!N58)/('Financial Statements'!N8/365) -> 185.36933 | O21: =('Financial Statements'!O61+'Financial Statements'!O58)/('Financial Statements'!O8/182.5) -> 402.78026 | P21: =('Financial Statements'!P61+'Financial Statements'!P58)/('Financial Statements'!P8/182.5) -> 237.03529 | Q21: =('Financial Statements'!Q61+'Financial Statements'!Q58)/('Financial Statements'!Q8/365) -> 221.48772 | R21: =('Financial Statements'!R61+'Financial Statements'!R58)/('Financial Statements'!R8/182.5) -> 271.46494 | S21: =('Financial Statements'!S61+'Financial Statements'!S58)/('Financial Statements'!S8/182.5) -> 207.32368 | T21: =('Financial Statements'!T61+'Financial Statements'!T58)/('Financial Statements'!T8/365) -> 206.7162 | U21: =('Financial Statements'!U61+'Financial Statements'!U58)/('Financial Statements'!U8/182.5) -> 256.62089 | V21: =('Financial Statements'!V61+'Financial Statements'!V58)/('Financial Statements'!V8/182.5) -> 179.64162 | W21: =('Financial Statements'!W61+'Financial Statements'!W58)/('Financial Statements'!W8/365) -> 164.23479 | X21: =('Financial Statements'!X61+'Financial Statements'!X58)/('Financial Statements'!X8/182.5) -> 82.761183 | Y21: =('Financial Statements'!Y61+'Financial Statements'!Y58)/('Financial Statements'!Y8/182.5) -> 101.39211 | Z21: =('Financial Statements'!Z61+'Financial Statements'!Z58)/('Financial Statements'!Z8/365) -> 101.08022 | AA21: =('Financial Statements'!AA61+'Financial Statements'!AA58)/('Financial Statements'!AA8/182.5) -> 28.371327 | AB21: =('Financial Statements'!AB61+'Financial Statements'!AB58)/('Financial Statements'!AB8/182.5) -> 91.750558 | AC21: =('Financial Statements'!AC61+'Financial Statements'!AC58)/('Financial Statements'!AC8/365) -> 91.506336 | AD21: =('Financial Statements'!AD61+'Financial Statements'!AD58)/('Financial Statements'!AD8/182.5) -> 54.107325 | AE21: =('Financial Statements'!AE61+'Financial Statements'!AE58)/('Financial Statements'!AE8/182.5) -> 118.40855 | AF21: =('Financial Statements'!AF61+'Financial Statements'!AF58)/('Financial Statements'!AF8/365) -> 118.14577 | AG21: =('Financial Statements'!AG61+'Financial Statements'!AG58)/('Financial Statements'!AG8/182.5) -> 57.033357 | AH21: =('Financial Statements'!AH61+'Financial Statements'!AH58)/('Financial Statements'!AH8/182.5) -> 116.46436 | AI21: =('Financial Statements'!AI61+'Financial Statements'!AI58)/('Financial Statements'!AI8/365) -> 116.60626
B23: Solvency Ratios
B25: Debt to Equity | C25: =('Financial Statements'!C74+'Financial Statements'!C80)/'Financial Statements'!C72 -> 0.4227989 | D25: =('Financial Statements'!D74+'Financial Statements'!D80)/'Financial Statements'!D72 -> 0.5132901 | E25: =('Financial Statements'!E74+'Financial Statements'!E80)/'Financial Statements'!E72 -> 0.5132901 | F25: =('Financial Statements'!F74+'Financial Statements'!F80)/'Financial Statements'!F72 -> 0.35266426 | G25: =('Financial Statements'!G74+'Financial Statements'!G80)/'Financial Statements'!G72 -> 0.33262329 | H25: =('Financial Statements'!H74+'Financial Statements'!H80)/'Financial Statements'!H72 -> 0.33262329 | I25: =('Financial Statements'!I74+'Financial Statements'!I80)/'Financial Statements'!I72 -> 0.25152949 | J25: =('Financial Statements'!J74+'Financial Statements'!J80)/'Financial Statements'!J72 -> 0.28260215 | ... AI25: =('Financial Statements'!AI74+'Financial Statements'!AI80)/'Financial Statements'!AI72 -> 0.23108941
